INFO:werkzeug: * Running on http://0.0.0.0:5000/ (Press CTRL+C to quit)
INFO:werkzeug: * Running on http://0.0.0.0:5000/ (Press CTRL+C to quit)
INFO:werkzeug:127.0.0.1 - - [04/May/2021 13:33:18] "[37mGET / HTTP/1.1[0m" 200 -
INFO:werkzeug:127.0.0.1 - - [04/May/2021 13:33:18] "[33mGET /favicon.ico HTTP/1.1[0m" 404 -
INFO:werkzeug:127.0.0.1 - - [04/May/2021 13:33:23] "[37mGET /3 HTTP/1.1[0m" 200 -
ERROR:app:Exception on /$%refresh_data [GET]
Traceback (most recent call last):
  File "C:\venvs\smartOrderService\lib\site-packages\flask\app.py", line 2447, in wsgi_app
    response = self.full_dispatch_request()
  File "C:\venvs\smartOrderService\lib\site-packages\flask\app.py", line 1953, in full_dispatch_request
    return self.finalize_request(rv)
  File "C:\venvs\smartOrderService\lib\site-packages\flask\app.py", line 1968, in finalize_request
    response = self.make_response(rv)
  File "C:\venvs\smartOrderService\lib\site-packages\flask\app.py", line 2097, in make_response
    raise TypeError(
TypeError: The view function did not return a valid response. The function either returned None or ended without a return statement.
INFO:werkzeug:127.0.0.1 - - [04/May/2021 13:34:10] "[35m[1mGET /$%refresh_data HTTP/1.1[0m" 500 -
INFO:werkzeug: * Running on http://0.0.0.0:5000/ (Press CTRL+C to quit)
INFO:werkzeug:127.0.0.1 - - [04/May/2021 13:35:15] "[33mGET /refresh_data HTTP/1.1[0m" 404 -
INFO:werkzeug:127.0.0.1 - - [04/May/2021 13:35:45] "[33mGET /refresh_data HTTP/1.1[0m" 404 -
INFO:werkzeug:127.0.0.1 - - [04/May/2021 13:35:47] "[33mGET /refresh_data HTTP/1.1[0m" 404 -
INFO:werkzeug:127.0.0.1 - - [04/May/2021 13:35:47] "[33mGET /refresh_data HTTP/1.1[0m" 404 -
INFO:werkzeug:127.0.0.1 - - [04/May/2021 13:35:47] "[33mGET /refresh_data HTTP/1.1[0m" 404 -
INFO:werkzeug:127.0.0.1 - - [04/May/2021 13:35:47] "[33mGET /refresh_data HTTP/1.1[0m" 404 -
INFO:werkzeug:127.0.0.1 - - [04/May/2021 13:35:47] "[33mGET /refresh_data HTTP/1.1[0m" 404 -
INFO:werkzeug:127.0.0.1 - - [04/May/2021 13:35:47] "[33mGET /refresh_data HTTP/1.1[0m" 404 -
INFO:werkzeug:127.0.0.1 - - [04/May/2021 13:35:48] "[33mGET /refresh_data HTTP/1.1[0m" 404 -
INFO:werkzeug:127.0.0.1 - - [04/May/2021 13:35:48] "[33mGET /refresh_data HTTP/1.1[0m" 404 -
INFO:werkzeug:127.0.0.1 - - [04/May/2021 13:35:50] "[37mGET / HTTP/1.1[0m" 200 -
INFO:werkzeug: * Running on http://0.0.0.0:5000/ (Press CTRL+C to quit)
INFO:werkzeug:127.0.0.1 - - [04/May/2021 13:36:04] "[33mGET /refresh_dat HTTP/1.1[0m" 404 -
INFO:werkzeug:127.0.0.1 - - [04/May/2021 13:36:07] "[33mGET /refresh_data HTTP/1.1[0m" 404 -
INFO:werkzeug:127.0.0.1 - - [04/May/2021 13:36:08] "[33mGET /refresh_data HTTP/1.1[0m" 404 -
INFO:werkzeug:127.0.0.1 - - [04/May/2021 13:36:09] "[33mGET /refresh_data HTTP/1.1[0m" 404 -
INFO:werkzeug:127.0.0.1 - - [04/May/2021 13:36:09] "[33mGET /refresh_data HTTP/1.1[0m" 404 -
INFO:werkzeug:127.0.0.1 - - [04/May/2021 13:36:09] "[33mGET /refresh_data HTTP/1.1[0m" 404 -
INFO:werkzeug:127.0.0.1 - - [04/May/2021 13:36:10] "[33mGET /refresh_data HTTP/1.1[0m" 404 -
INFO:werkzeug:127.0.0.1 - - [04/May/2021 13:36:10] "[33mGET /refresh_data HTTP/1.1[0m" 404 -
INFO:werkzeug: * Running on http://0.0.0.0:5000/ (Press CTRL+C to quit)
INFO:werkzeug:127.0.0.1 - - [04/May/2021 13:38:17] "[33mGET /refresh_data HTTP/1.1[0m" 404 -
INFO:werkzeug:127.0.0.1 - - [04/May/2021 13:38:19] "[33mGET /refresh_data HTTP/1.1[0m" 404 -
INFO:werkzeug:127.0.0.1 - - [04/May/2021 13:38:19] "[33mGET /refresh_data HTTP/1.1[0m" 404 -
INFO:werkzeug:127.0.0.1 - - [04/May/2021 13:38:20] "[33mGET /refresh_data HTTP/1.1[0m" 404 -
INFO:werkzeug:127.0.0.1 - - [04/May/2021 13:38:20] "[33mGET /refresh_data HTTP/1.1[0m" 404 -
INFO:werkzeug:127.0.0.1 - - [04/May/2021 13:38:20] "[33mGET /refresh_data HTTP/1.1[0m" 404 -
INFO:werkzeug:127.0.0.1 - - [04/May/2021 13:38:20] "[33mGET /refresh_data HTTP/1.1[0m" 404 -
INFO:werkzeug:127.0.0.1 - - [04/May/2021 13:38:21] "[33mGET /refresh_data HTTP/1.1[0m" 404 -
INFO:werkzeug:127.0.0.1 - - [04/May/2021 13:38:21] "[33mGET /refresh_data HTTP/1.1[0m" 404 -
INFO:werkzeug:127.0.0.1 - - [04/May/2021 13:38:21] "[33mGET /refresh_data HTTP/1.1[0m" 404 -
INFO:werkzeug:127.0.0.1 - - [04/May/2021 13:38:21] "[33mGET /refresh_data HTTP/1.1[0m" 404 -
INFO:werkzeug:127.0.0.1 - - [04/May/2021 13:38:21] "[33mGET /refresh_data HTTP/1.1[0m" 404 -
INFO:werkzeug:127.0.0.1 - - [04/May/2021 13:40:19] "[37mGET /home HTTP/1.1[0m" 200 -
INFO:werkzeug: * Running on http://0.0.0.0:5000/ (Press CTRL+C to quit)
INFO:werkzeug:127.0.0.1 - - [04/May/2021 13:40:51] "[33mGET /refresh_data HTTP/1.1[0m" 404 -
INFO:werkzeug:127.0.0.1 - - [04/May/2021 13:41:12] "[33mGET /refresh_data HTTP/1.1[0m" 404 -
INFO:werkzeug:127.0.0.1 - - [04/May/2021 13:41:13] "[33mGET /refresh_data HTTP/1.1[0m" 404 -
INFO:werkzeug:127.0.0.1 - - [04/May/2021 13:41:14] "[33mGET /refresh_data HTTP/1.1[0m" 404 -
INFO:werkzeug: * Running on http://0.0.0.0:5000/ (Press CTRL+C to quit)
INFO:werkzeug:127.0.0.1 - - [04/May/2021 13:41:47] "[37mGET / HTTP/1.1[0m" 200 -
INFO:werkzeug:127.0.0.1 - - [04/May/2021 13:41:53] "[33mGET /refresh_data HTTP/1.1[0m" 404 -
INFO:werkzeug: * Running on http://0.0.0.0:5000/ (Press CTRL+C to quit)
INFO:werkzeug:127.0.0.1 - - [04/May/2021 13:42:14] "[33mGET /refresh_data HTTP/1.1[0m" 404 -
INFO:werkzeug:127.0.0.1 - - [04/May/2021 13:42:15] "[33mGET /refresh_data HTTP/1.1[0m" 404 -
INFO:werkzeug:127.0.0.1 - - [04/May/2021 13:42:15] "[33mGET /refresh_data HTTP/1.1[0m" 404 -
INFO:werkzeug:127.0.0.1 - - [04/May/2021 13:42:17] "[37mGET / HTTP/1.1[0m" 200 -
INFO:werkzeug:127.0.0.1 - - [04/May/2021 13:42:19] "[33mGET /refresh_data HTTP/1.1[0m" 404 -
INFO:werkzeug:127.0.0.1 - - [04/May/2021 13:42:19] "[33mGET /refresh_data HTTP/1.1[0m" 404 -
INFO:werkzeug:127.0.0.1 - - [04/May/2021 13:42:20] "[33mGET /refresh_data HTTP/1.1[0m" 404 -
INFO:werkzeug:127.0.0.1 - - [04/May/2021 13:42:20] "[33mGET /refresh_data HTTP/1.1[0m" 404 -
INFO:werkzeug:127.0.0.1 - - [04/May/2021 13:42:20] "[33mGET /refresh_data HTTP/1.1[0m" 404 -
INFO:werkzeug:127.0.0.1 - - [04/May/2021 13:42:20] "[33mGET /refresh_data HTTP/1.1[0m" 404 -
INFO:werkzeug:127.0.0.1 - - [04/May/2021 13:42:21] "[33mGET /refresh_data HTTP/1.1[0m" 404 -
INFO:werkzeug: * Running on http://0.0.0.0:5000/ (Press CTRL+C to quit)
INFO:werkzeug:127.0.0.1 - - [05/May/2021 02:30:59] "[37mGET / HTTP/1.1[0m" 200 -
INFO:werkzeug:127.0.0.1 - - [05/May/2021 02:30:59] "[33mGET /favicon.ico HTTP/1.1[0m" 404 -
ERROR:app:Exception on /555 [GET]
Traceback (most recent call last):
  File "C:\venvs\smartOrderService\lib\site-packages\flask\app.py", line 2447, in wsgi_app
    response = self.full_dispatch_request()
  File "C:\venvs\smartOrderService\lib\site-packages\flask\app.py", line 1952, in full_dispatch_request
    rv = self.handle_user_exception(e)
  File "C:\venvs\smartOrderService\lib\site-packages\flask_cors\extension.py", line 165, in wrapped_function
    return cors_after_request(app.make_response(f(*args, **kwargs)))
  File "C:\venvs\smartOrderService\lib\site-packages\flask\app.py", line 1821, in handle_user_exception
    reraise(exc_type, exc_value, tb)
  File "C:\venvs\smartOrderService\lib\site-packages\flask\_compat.py", line 39, in reraise
    raise value
  File "C:\venvs\smartOrderService\lib\site-packages\flask\app.py", line 1950, in full_dispatch_request
    rv = self.dispatch_request()
  File "C:\venvs\smartOrderService\lib\site-packages\flask\app.py", line 1936, in dispatch_request
    return self.view_functions[rule.endpoint](**req.view_args)
  File "C:/flaskProjects/smartOrderService_recommendingMenu/app.py", line 57, in recommend
    result = compute_recommending_menu.user_recommend(user_id, each_menu_recommend_data, each_user_pearson_data, conn)
  File "C:\flaskProjects\smartOrderService_recommendingMenu\compute_recommending_menu.py", line 93, in user_recommend
    cur_user_pearson_datas = each_user_pearson_data[user_id]['Pearson Data']
IndexError: list index out of range
INFO:werkzeug:127.0.0.1 - - [05/May/2021 02:31:02] "[35m[1mGET /555 HTTP/1.1[0m" 500 -
ERROR:app:Exception on /555 [GET]
Traceback (most recent call last):
  File "C:\venvs\smartOrderService\lib\site-packages\flask\app.py", line 2447, in wsgi_app
    response = self.full_dispatch_request()
  File "C:\venvs\smartOrderService\lib\site-packages\flask\app.py", line 1952, in full_dispatch_request
    rv = self.handle_user_exception(e)
  File "C:\venvs\smartOrderService\lib\site-packages\flask_cors\extension.py", line 165, in wrapped_function
    return cors_after_request(app.make_response(f(*args, **kwargs)))
  File "C:\venvs\smartOrderService\lib\site-packages\flask\app.py", line 1821, in handle_user_exception
    reraise(exc_type, exc_value, tb)
  File "C:\venvs\smartOrderService\lib\site-packages\flask\_compat.py", line 39, in reraise
    raise value
  File "C:\venvs\smartOrderService\lib\site-packages\flask\app.py", line 1950, in full_dispatch_request
    rv = self.dispatch_request()
  File "C:\venvs\smartOrderService\lib\site-packages\flask\app.py", line 1936, in dispatch_request
    return self.view_functions[rule.endpoint](**req.view_args)
  File "C:/flaskProjects/smartOrderService_recommendingMenu/app.py", line 57, in recommend
    result = compute_recommending_menu.user_recommend(user_id, each_menu_recommend_data, each_user_pearson_data, conn)
  File "C:\flaskProjects\smartOrderService_recommendingMenu\compute_recommending_menu.py", line 93, in user_recommend
    cur_user_pearson_datas = each_user_pearson_data[user_id]['Pearson Data']
IndexError: list index out of range
INFO:werkzeug:127.0.0.1 - - [05/May/2021 02:31:59] "[35m[1mGET /555 HTTP/1.1[0m" 500 -
INFO:werkzeug:127.0.0.1 - - [05/May/2021 02:32:02] "[37mGET / HTTP/1.1[0m" 200 -
INFO:werkzeug: * Running on http://0.0.0.0:5000/ (Press CTRL+C to quit)
INFO:werkzeug:127.0.0.1 - - [05/May/2021 02:32:42] "[37mGET / HTTP/1.1[0m" 200 -
ERROR:app:Exception on /555 [GET]
Traceback (most recent call last):
  File "C:\venvs\smartOrderService\lib\site-packages\flask\app.py", line 2447, in wsgi_app
    response = self.full_dispatch_request()
  File "C:\venvs\smartOrderService\lib\site-packages\flask\app.py", line 1952, in full_dispatch_request
    rv = self.handle_user_exception(e)
  File "C:\venvs\smartOrderService\lib\site-packages\flask_cors\extension.py", line 165, in wrapped_function
    return cors_after_request(app.make_response(f(*args, **kwargs)))
  File "C:\venvs\smartOrderService\lib\site-packages\flask\app.py", line 1821, in handle_user_exception
    reraise(exc_type, exc_value, tb)
  File "C:\venvs\smartOrderService\lib\site-packages\flask\_compat.py", line 39, in reraise
    raise value
  File "C:\venvs\smartOrderService\lib\site-packages\flask\app.py", line 1950, in full_dispatch_request
    rv = self.dispatch_request()
  File "C:\venvs\smartOrderService\lib\site-packages\flask\app.py", line 1936, in dispatch_request
    return self.view_functions[rule.endpoint](**req.view_args)
  File "C:/flaskProjects/smartOrderService_recommendingMenu/app.py", line 57, in recommend
    result = compute_recommending_menu.user_recommend(user_id, each_menu_recommend_data, each_user_pearson_data, conn)
  File "C:\flaskProjects\smartOrderService_recommendingMenu\compute_recommending_menu.py", line 93, in user_recommend
    cur_user_pearson_datas = each_user_pearson_data[user_id]['Pearson Data']
IndexError: list index out of range
INFO:werkzeug:127.0.0.1 - - [05/May/2021 02:32:44] "[35m[1mGET /555 HTTP/1.1[0m" 500 -
ERROR:app:Exception on /555 [GET]
Traceback (most recent call last):
  File "C:\venvs\smartOrderService\lib\site-packages\flask\app.py", line 2447, in wsgi_app
    response = self.full_dispatch_request()
  File "C:\venvs\smartOrderService\lib\site-packages\flask\app.py", line 1952, in full_dispatch_request
    rv = self.handle_user_exception(e)
  File "C:\venvs\smartOrderService\lib\site-packages\flask_cors\extension.py", line 165, in wrapped_function
    return cors_after_request(app.make_response(f(*args, **kwargs)))
  File "C:\venvs\smartOrderService\lib\site-packages\flask\app.py", line 1821, in handle_user_exception
    reraise(exc_type, exc_value, tb)
  File "C:\venvs\smartOrderService\lib\site-packages\flask\_compat.py", line 39, in reraise
    raise value
  File "C:\venvs\smartOrderService\lib\site-packages\flask\app.py", line 1950, in full_dispatch_request
    rv = self.dispatch_request()
  File "C:\venvs\smartOrderService\lib\site-packages\flask\app.py", line 1936, in dispatch_request
    return self.view_functions[rule.endpoint](**req.view_args)
  File "C:/flaskProjects/smartOrderService_recommendingMenu/app.py", line 57, in recommend
    result = compute_recommending_menu.user_recommend(user_id, each_menu_recommend_data, each_user_pearson_data, conn)
  File "C:\flaskProjects\smartOrderService_recommendingMenu\compute_recommending_menu.py", line 93, in user_recommend
    cur_user_pearson_datas = each_user_pearson_data[user_id]['Pearson Data']
IndexError: list index out of range
INFO:werkzeug:127.0.0.1 - - [05/May/2021 02:32:53] "[35m[1mGET /555 HTTP/1.1[0m" 500 -
INFO:werkzeug: * Running on http://0.0.0.0:5000/ (Press CTRL+C to quit)
ERROR:app:Exception on /555 [GET]
Traceback (most recent call last):
  File "C:\venvs\smartOrderService\lib\site-packages\flask\app.py", line 2447, in wsgi_app
    response = self.full_dispatch_request()
  File "C:\venvs\smartOrderService\lib\site-packages\flask\app.py", line 1952, in full_dispatch_request
    rv = self.handle_user_exception(e)
  File "C:\venvs\smartOrderService\lib\site-packages\flask_cors\extension.py", line 165, in wrapped_function
    return cors_after_request(app.make_response(f(*args, **kwargs)))
  File "C:\venvs\smartOrderService\lib\site-packages\flask\app.py", line 1821, in handle_user_exception
    reraise(exc_type, exc_value, tb)
  File "C:\venvs\smartOrderService\lib\site-packages\flask\_compat.py", line 39, in reraise
    raise value
  File "C:\venvs\smartOrderService\lib\site-packages\flask\app.py", line 1950, in full_dispatch_request
    rv = self.dispatch_request()
  File "C:\venvs\smartOrderService\lib\site-packages\flask\app.py", line 1936, in dispatch_request
    return self.view_functions[rule.endpoint](**req.view_args)
  File "C:/flaskProjects/smartOrderService_recommendingMenu/app.py", line 57, in recommend
    result = compute_recommending_menu.user_recommend(user_id, each_menu_recommend_data, each_user_pearson_data, conn)
  File "C:\flaskProjects\smartOrderService_recommendingMenu\compute_recommending_menu.py", line 93, in user_recommend
    cur_user_pearson_datas = each_user_pearson_data[user_id]['Pearson Data']
IndexError: list index out of range
INFO:werkzeug:127.0.0.1 - - [05/May/2021 02:33:45] "[35m[1mGET /555 HTTP/1.1[0m" 500 -
ERROR:app:Exception on /555 [GET]
Traceback (most recent call last):
  File "C:\venvs\smartOrderService\lib\site-packages\flask\app.py", line 2447, in wsgi_app
    response = self.full_dispatch_request()
  File "C:\venvs\smartOrderService\lib\site-packages\flask\app.py", line 1952, in full_dispatch_request
    rv = self.handle_user_exception(e)
  File "C:\venvs\smartOrderService\lib\site-packages\flask_cors\extension.py", line 165, in wrapped_function
    return cors_after_request(app.make_response(f(*args, **kwargs)))
  File "C:\venvs\smartOrderService\lib\site-packages\flask\app.py", line 1821, in handle_user_exception
    reraise(exc_type, exc_value, tb)
  File "C:\venvs\smartOrderService\lib\site-packages\flask\_compat.py", line 39, in reraise
    raise value
  File "C:\venvs\smartOrderService\lib\site-packages\flask\app.py", line 1950, in full_dispatch_request
    rv = self.dispatch_request()
  File "C:\venvs\smartOrderService\lib\site-packages\flask\app.py", line 1936, in dispatch_request
    return self.view_functions[rule.endpoint](**req.view_args)
  File "C:/flaskProjects/smartOrderService_recommendingMenu/app.py", line 57, in recommend
    result = compute_recommending_menu.user_recommend(user_id, each_menu_recommend_data, each_user_pearson_data, conn)
  File "C:\flaskProjects\smartOrderService_recommendingMenu\compute_recommending_menu.py", line 93, in user_recommend
    cur_user_pearson_datas = each_user_pearson_data[user_id]['Pearson Data']
IndexError: list index out of range
INFO:werkzeug:127.0.0.1 - - [05/May/2021 02:33:47] "[35m[1mGET /555 HTTP/1.1[0m" 500 -
ERROR:app:Exception on /555 [GET]
Traceback (most recent call last):
  File "C:\venvs\smartOrderService\lib\site-packages\flask\app.py", line 2447, in wsgi_app
    response = self.full_dispatch_request()
  File "C:\venvs\smartOrderService\lib\site-packages\flask\app.py", line 1952, in full_dispatch_request
    rv = self.handle_user_exception(e)
  File "C:\venvs\smartOrderService\lib\site-packages\flask_cors\extension.py", line 165, in wrapped_function
    return cors_after_request(app.make_response(f(*args, **kwargs)))
  File "C:\venvs\smartOrderService\lib\site-packages\flask\app.py", line 1821, in handle_user_exception
    reraise(exc_type, exc_value, tb)
  File "C:\venvs\smartOrderService\lib\site-packages\flask\_compat.py", line 39, in reraise
    raise value
  File "C:\venvs\smartOrderService\lib\site-packages\flask\app.py", line 1950, in full_dispatch_request
    rv = self.dispatch_request()
  File "C:\venvs\smartOrderService\lib\site-packages\flask\app.py", line 1936, in dispatch_request
    return self.view_functions[rule.endpoint](**req.view_args)
  File "C:/flaskProjects/smartOrderService_recommendingMenu/app.py", line 57, in recommend
    result = compute_recommending_menu.user_recommend(user_id, each_menu_recommend_data, each_user_pearson_data, conn)
  File "C:\flaskProjects\smartOrderService_recommendingMenu\compute_recommending_menu.py", line 93, in user_recommend
    cur_user_pearson_datas = each_user_pearson_data[user_id]['Pearson Data']
IndexError: list index out of range
INFO:werkzeug:127.0.0.1 - - [05/May/2021 02:33:47] "[35m[1mGET /555 HTTP/1.1[0m" 500 -
ERROR:app:Exception on /555 [GET]
Traceback (most recent call last):
  File "C:\venvs\smartOrderService\lib\site-packages\flask\app.py", line 2447, in wsgi_app
    response = self.full_dispatch_request()
  File "C:\venvs\smartOrderService\lib\site-packages\flask\app.py", line 1952, in full_dispatch_request
    rv = self.handle_user_exception(e)
  File "C:\venvs\smartOrderService\lib\site-packages\flask_cors\extension.py", line 165, in wrapped_function
    return cors_after_request(app.make_response(f(*args, **kwargs)))
  File "C:\venvs\smartOrderService\lib\site-packages\flask\app.py", line 1821, in handle_user_exception
    reraise(exc_type, exc_value, tb)
  File "C:\venvs\smartOrderService\lib\site-packages\flask\_compat.py", line 39, in reraise
    raise value
  File "C:\venvs\smartOrderService\lib\site-packages\flask\app.py", line 1950, in full_dispatch_request
    rv = self.dispatch_request()
  File "C:\venvs\smartOrderService\lib\site-packages\flask\app.py", line 1936, in dispatch_request
    return self.view_functions[rule.endpoint](**req.view_args)
  File "C:/flaskProjects/smartOrderService_recommendingMenu/app.py", line 57, in recommend
    result = compute_recommending_menu.user_recommend(user_id, each_menu_recommend_data, each_user_pearson_data, conn)
  File "C:\flaskProjects\smartOrderService_recommendingMenu\compute_recommending_menu.py", line 93, in user_recommend
    cur_user_pearson_datas = each_user_pearson_data[user_id]['Pearson Data']
IndexError: list index out of range
INFO:werkzeug:127.0.0.1 - - [05/May/2021 02:33:48] "[35m[1mGET /555 HTTP/1.1[0m" 500 -
ERROR:app:Exception on /555 [GET]
Traceback (most recent call last):
  File "C:\venvs\smartOrderService\lib\site-packages\flask\app.py", line 2447, in wsgi_app
    response = self.full_dispatch_request()
  File "C:\venvs\smartOrderService\lib\site-packages\flask\app.py", line 1952, in full_dispatch_request
    rv = self.handle_user_exception(e)
  File "C:\venvs\smartOrderService\lib\site-packages\flask_cors\extension.py", line 165, in wrapped_function
    return cors_after_request(app.make_response(f(*args, **kwargs)))
  File "C:\venvs\smartOrderService\lib\site-packages\flask\app.py", line 1821, in handle_user_exception
    reraise(exc_type, exc_value, tb)
  File "C:\venvs\smartOrderService\lib\site-packages\flask\_compat.py", line 39, in reraise
    raise value
  File "C:\venvs\smartOrderService\lib\site-packages\flask\app.py", line 1950, in full_dispatch_request
    rv = self.dispatch_request()
  File "C:\venvs\smartOrderService\lib\site-packages\flask\app.py", line 1936, in dispatch_request
    return self.view_functions[rule.endpoint](**req.view_args)
  File "C:/flaskProjects/smartOrderService_recommendingMenu/app.py", line 57, in recommend
    result = compute_recommending_menu.user_recommend(user_id, each_menu_recommend_data, each_user_pearson_data, conn)
  File "C:\flaskProjects\smartOrderService_recommendingMenu\compute_recommending_menu.py", line 93, in user_recommend
    cur_user_pearson_datas = each_user_pearson_data[user_id]['Pearson Data']
IndexError: list index out of range
INFO:werkzeug:127.0.0.1 - - [05/May/2021 02:33:48] "[35m[1mGET /555 HTTP/1.1[0m" 500 -
ERROR:app:Exception on /555 [GET]
Traceback (most recent call last):
  File "C:\venvs\smartOrderService\lib\site-packages\flask\app.py", line 2447, in wsgi_app
    response = self.full_dispatch_request()
  File "C:\venvs\smartOrderService\lib\site-packages\flask\app.py", line 1952, in full_dispatch_request
    rv = self.handle_user_exception(e)
  File "C:\venvs\smartOrderService\lib\site-packages\flask_cors\extension.py", line 165, in wrapped_function
    return cors_after_request(app.make_response(f(*args, **kwargs)))
  File "C:\venvs\smartOrderService\lib\site-packages\flask\app.py", line 1821, in handle_user_exception
    reraise(exc_type, exc_value, tb)
  File "C:\venvs\smartOrderService\lib\site-packages\flask\_compat.py", line 39, in reraise
    raise value
  File "C:\venvs\smartOrderService\lib\site-packages\flask\app.py", line 1950, in full_dispatch_request
    rv = self.dispatch_request()
  File "C:\venvs\smartOrderService\lib\site-packages\flask\app.py", line 1936, in dispatch_request
    return self.view_functions[rule.endpoint](**req.view_args)
  File "C:/flaskProjects/smartOrderService_recommendingMenu/app.py", line 57, in recommend
    result = compute_recommending_menu.user_recommend(user_id, each_menu_recommend_data, each_user_pearson_data, conn)
  File "C:\flaskProjects\smartOrderService_recommendingMenu\compute_recommending_menu.py", line 93, in user_recommend
    cur_user_pearson_datas = each_user_pearson_data[user_id]['Pearson Data']
IndexError: list index out of range
INFO:werkzeug:127.0.0.1 - - [05/May/2021 02:33:49] "[35m[1mGET /555 HTTP/1.1[0m" 500 -
INFO:werkzeug: * Running on http://0.0.0.0:5000/ (Press CTRL+C to quit)
ERROR:app:Exception on /55 [GET]
Traceback (most recent call last):
  File "C:\venvs\smartOrderService\lib\site-packages\flask\app.py", line 2447, in wsgi_app
    response = self.full_dispatch_request()
  File "C:\venvs\smartOrderService\lib\site-packages\flask\app.py", line 1952, in full_dispatch_request
    rv = self.handle_user_exception(e)
  File "C:\venvs\smartOrderService\lib\site-packages\flask_cors\extension.py", line 165, in wrapped_function
    return cors_after_request(app.make_response(f(*args, **kwargs)))
  File "C:\venvs\smartOrderService\lib\site-packages\flask\app.py", line 1821, in handle_user_exception
    reraise(exc_type, exc_value, tb)
  File "C:\venvs\smartOrderService\lib\site-packages\flask\_compat.py", line 39, in reraise
    raise value
  File "C:\venvs\smartOrderService\lib\site-packages\flask\app.py", line 1950, in full_dispatch_request
    rv = self.dispatch_request()
  File "C:\venvs\smartOrderService\lib\site-packages\flask\app.py", line 1936, in dispatch_request
    return self.view_functions[rule.endpoint](**req.view_args)
  File "C:/flaskProjects/smartOrderService_recommendingMenu/app.py", line 57, in recommend
    result = compute_recommending_menu.user_recommend(user_id, each_menu_recommend_data, each_user_pearson_data, conn)
  File "C:\flaskProjects\smartOrderService_recommendingMenu\compute_recommending_menu.py", line 93, in user_recommend
    cur_user_pearson_datas = each_user_pearson_data[user_id-1]['Pearson Data']
IndexError: list index out of range
INFO:werkzeug:127.0.0.1 - - [05/May/2021 02:35:09] "[35m[1mGET /55 HTTP/1.1[0m" 500 -
ERROR:app:Exception on /1 [GET]
Traceback (most recent call last):
  File "C:\venvs\smartOrderService\lib\site-packages\flask\app.py", line 2447, in wsgi_app
    response = self.full_dispatch_request()
  File "C:\venvs\smartOrderService\lib\site-packages\flask\app.py", line 1952, in full_dispatch_request
    rv = self.handle_user_exception(e)
  File "C:\venvs\smartOrderService\lib\site-packages\flask_cors\extension.py", line 165, in wrapped_function
    return cors_after_request(app.make_response(f(*args, **kwargs)))
  File "C:\venvs\smartOrderService\lib\site-packages\flask\app.py", line 1821, in handle_user_exception
    reraise(exc_type, exc_value, tb)
  File "C:\venvs\smartOrderService\lib\site-packages\flask\_compat.py", line 39, in reraise
    raise value
  File "C:\venvs\smartOrderService\lib\site-packages\flask\app.py", line 1950, in full_dispatch_request
    rv = self.dispatch_request()
  File "C:\venvs\smartOrderService\lib\site-packages\flask\app.py", line 1936, in dispatch_request
    return self.view_functions[rule.endpoint](**req.view_args)
  File "C:/flaskProjects/smartOrderService_recommendingMenu/app.py", line 57, in recommend
    result = compute_recommending_menu.user_recommend(user_id, each_menu_recommend_data, each_user_pearson_data, conn)
  File "C:\flaskProjects\smartOrderService_recommendingMenu\compute_recommending_menu.py", line 93, in user_recommend
    cur_user_pearson_datas = each_user_pearson_data[user_id-1]['Pearson Data']
IndexError: list index out of range
INFO:werkzeug:127.0.0.1 - - [05/May/2021 02:35:13] "[35m[1mGET /1 HTTP/1.1[0m" 500 -
ERROR:app:Exception on /1 [GET]
Traceback (most recent call last):
  File "C:\venvs\smartOrderService\lib\site-packages\flask\app.py", line 2447, in wsgi_app
    response = self.full_dispatch_request()
  File "C:\venvs\smartOrderService\lib\site-packages\flask\app.py", line 1952, in full_dispatch_request
    rv = self.handle_user_exception(e)
  File "C:\venvs\smartOrderService\lib\site-packages\flask_cors\extension.py", line 165, in wrapped_function
    return cors_after_request(app.make_response(f(*args, **kwargs)))
  File "C:\venvs\smartOrderService\lib\site-packages\flask\app.py", line 1821, in handle_user_exception
    reraise(exc_type, exc_value, tb)
  File "C:\venvs\smartOrderService\lib\site-packages\flask\_compat.py", line 39, in reraise
    raise value
  File "C:\venvs\smartOrderService\lib\site-packages\flask\app.py", line 1950, in full_dispatch_request
    rv = self.dispatch_request()
  File "C:\venvs\smartOrderService\lib\site-packages\flask\app.py", line 1936, in dispatch_request
    return self.view_functions[rule.endpoint](**req.view_args)
  File "C:/flaskProjects/smartOrderService_recommendingMenu/app.py", line 57, in recommend
    result = compute_recommending_menu.user_recommend(user_id, each_menu_recommend_data, each_user_pearson_data, conn)
  File "C:\flaskProjects\smartOrderService_recommendingMenu\compute_recommending_menu.py", line 93, in user_recommend
    cur_user_pearson_datas = each_user_pearson_data[user_id-1]['Pearson Data']
IndexError: list index out of range
INFO:werkzeug:127.0.0.1 - - [05/May/2021 02:35:15] "[35m[1mGET /1 HTTP/1.1[0m" 500 -
ERROR:app:Exception on /1 [GET]
Traceback (most recent call last):
  File "C:\venvs\smartOrderService\lib\site-packages\flask\app.py", line 2447, in wsgi_app
    response = self.full_dispatch_request()
  File "C:\venvs\smartOrderService\lib\site-packages\flask\app.py", line 1952, in full_dispatch_request
    rv = self.handle_user_exception(e)
  File "C:\venvs\smartOrderService\lib\site-packages\flask_cors\extension.py", line 165, in wrapped_function
    return cors_after_request(app.make_response(f(*args, **kwargs)))
  File "C:\venvs\smartOrderService\lib\site-packages\flask\app.py", line 1821, in handle_user_exception
    reraise(exc_type, exc_value, tb)
  File "C:\venvs\smartOrderService\lib\site-packages\flask\_compat.py", line 39, in reraise
    raise value
  File "C:\venvs\smartOrderService\lib\site-packages\flask\app.py", line 1950, in full_dispatch_request
    rv = self.dispatch_request()
  File "C:\venvs\smartOrderService\lib\site-packages\flask\app.py", line 1936, in dispatch_request
    return self.view_functions[rule.endpoint](**req.view_args)
  File "C:/flaskProjects/smartOrderService_recommendingMenu/app.py", line 57, in recommend
    result = compute_recommending_menu.user_recommend(user_id, each_menu_recommend_data, each_user_pearson_data, conn)
  File "C:\flaskProjects\smartOrderService_recommendingMenu\compute_recommending_menu.py", line 93, in user_recommend
    cur_user_pearson_datas = each_user_pearson_data[user_id-1]['Pearson Data']
IndexError: list index out of range
INFO:werkzeug:127.0.0.1 - - [05/May/2021 02:35:15] "[35m[1mGET /1 HTTP/1.1[0m" 500 -
ERROR:app:Exception on /1 [GET]
Traceback (most recent call last):
  File "C:\venvs\smartOrderService\lib\site-packages\flask\app.py", line 2447, in wsgi_app
    response = self.full_dispatch_request()
  File "C:\venvs\smartOrderService\lib\site-packages\flask\app.py", line 1952, in full_dispatch_request
    rv = self.handle_user_exception(e)
  File "C:\venvs\smartOrderService\lib\site-packages\flask_cors\extension.py", line 165, in wrapped_function
    return cors_after_request(app.make_response(f(*args, **kwargs)))
  File "C:\venvs\smartOrderService\lib\site-packages\flask\app.py", line 1821, in handle_user_exception
    reraise(exc_type, exc_value, tb)
  File "C:\venvs\smartOrderService\lib\site-packages\flask\_compat.py", line 39, in reraise
    raise value
  File "C:\venvs\smartOrderService\lib\site-packages\flask\app.py", line 1950, in full_dispatch_request
    rv = self.dispatch_request()
  File "C:\venvs\smartOrderService\lib\site-packages\flask\app.py", line 1936, in dispatch_request
    return self.view_functions[rule.endpoint](**req.view_args)
  File "C:/flaskProjects/smartOrderService_recommendingMenu/app.py", line 57, in recommend
    result = compute_recommending_menu.user_recommend(user_id, each_menu_recommend_data, each_user_pearson_data, conn)
  File "C:\flaskProjects\smartOrderService_recommendingMenu\compute_recommending_menu.py", line 93, in user_recommend
    cur_user_pearson_datas = each_user_pearson_data[user_id-1]['Pearson Data']
IndexError: list index out of range
INFO:werkzeug:127.0.0.1 - - [05/May/2021 02:35:15] "[35m[1mGET /1 HTTP/1.1[0m" 500 -
ERROR:app:Exception on /1 [GET]
Traceback (most recent call last):
  File "C:\venvs\smartOrderService\lib\site-packages\flask\app.py", line 2447, in wsgi_app
    response = self.full_dispatch_request()
  File "C:\venvs\smartOrderService\lib\site-packages\flask\app.py", line 1952, in full_dispatch_request
    rv = self.handle_user_exception(e)
  File "C:\venvs\smartOrderService\lib\site-packages\flask_cors\extension.py", line 165, in wrapped_function
    return cors_after_request(app.make_response(f(*args, **kwargs)))
  File "C:\venvs\smartOrderService\lib\site-packages\flask\app.py", line 1821, in handle_user_exception
    reraise(exc_type, exc_value, tb)
  File "C:\venvs\smartOrderService\lib\site-packages\flask\_compat.py", line 39, in reraise
    raise value
  File "C:\venvs\smartOrderService\lib\site-packages\flask\app.py", line 1950, in full_dispatch_request
    rv = self.dispatch_request()
  File "C:\venvs\smartOrderService\lib\site-packages\flask\app.py", line 1936, in dispatch_request
    return self.view_functions[rule.endpoint](**req.view_args)
  File "C:/flaskProjects/smartOrderService_recommendingMenu/app.py", line 57, in recommend
    result = compute_recommending_menu.user_recommend(user_id, each_menu_recommend_data, each_user_pearson_data, conn)
  File "C:\flaskProjects\smartOrderService_recommendingMenu\compute_recommending_menu.py", line 93, in user_recommend
    cur_user_pearson_datas = each_user_pearson_data[user_id-1]['Pearson Data']
IndexError: list index out of range
INFO:werkzeug:127.0.0.1 - - [05/May/2021 02:35:15] "[35m[1mGET /1 HTTP/1.1[0m" 500 -
ERROR:app:Exception on /556 [GET]
Traceback (most recent call last):
  File "C:\venvs\smartOrderService\lib\site-packages\flask\app.py", line 2447, in wsgi_app
    response = self.full_dispatch_request()
  File "C:\venvs\smartOrderService\lib\site-packages\flask\app.py", line 1952, in full_dispatch_request
    rv = self.handle_user_exception(e)
  File "C:\venvs\smartOrderService\lib\site-packages\flask_cors\extension.py", line 165, in wrapped_function
    return cors_after_request(app.make_response(f(*args, **kwargs)))
  File "C:\venvs\smartOrderService\lib\site-packages\flask\app.py", line 1821, in handle_user_exception
    reraise(exc_type, exc_value, tb)
  File "C:\venvs\smartOrderService\lib\site-packages\flask\_compat.py", line 39, in reraise
    raise value
  File "C:\venvs\smartOrderService\lib\site-packages\flask\app.py", line 1950, in full_dispatch_request
    rv = self.dispatch_request()
  File "C:\venvs\smartOrderService\lib\site-packages\flask\app.py", line 1936, in dispatch_request
    return self.view_functions[rule.endpoint](**req.view_args)
  File "C:/flaskProjects/smartOrderService_recommendingMenu/app.py", line 57, in recommend
    result = compute_recommending_menu.user_recommend(user_id, each_menu_recommend_data, each_user_pearson_data, conn)
  File "C:\flaskProjects\smartOrderService_recommendingMenu\compute_recommending_menu.py", line 93, in user_recommend
    cur_user_pearson_datas = each_user_pearson_data[user_id-1]['Pearson Data']
IndexError: list index out of range
INFO:werkzeug:127.0.0.1 - - [05/May/2021 02:35:20] "[35m[1mGET /556 HTTP/1.1[0m" 500 -
INFO:werkzeug: * Running on http://0.0.0.0:5000/ (Press CTRL+C to quit)
ERROR:app:Exception on /556 [GET]
Traceback (most recent call last):
  File "C:\venvs\smartOrderService\lib\site-packages\flask\app.py", line 2447, in wsgi_app
    response = self.full_dispatch_request()
  File "C:\venvs\smartOrderService\lib\site-packages\flask\app.py", line 1952, in full_dispatch_request
    rv = self.handle_user_exception(e)
  File "C:\venvs\smartOrderService\lib\site-packages\flask_cors\extension.py", line 165, in wrapped_function
    return cors_after_request(app.make_response(f(*args, **kwargs)))
  File "C:\venvs\smartOrderService\lib\site-packages\flask\app.py", line 1821, in handle_user_exception
    reraise(exc_type, exc_value, tb)
  File "C:\venvs\smartOrderService\lib\site-packages\flask\_compat.py", line 39, in reraise
    raise value
  File "C:\venvs\smartOrderService\lib\site-packages\flask\app.py", line 1950, in full_dispatch_request
    rv = self.dispatch_request()
  File "C:\venvs\smartOrderService\lib\site-packages\flask\app.py", line 1936, in dispatch_request
    return self.view_functions[rule.endpoint](**req.view_args)
  File "C:/flaskProjects/smartOrderService_recommendingMenu/app.py", line 57, in recommend
    result = compute_recommending_menu.user_recommend(user_id, each_menu_recommend_data, each_user_pearson_data, conn)
  File "C:\flaskProjects\smartOrderService_recommendingMenu\compute_recommending_menu.py", line 93, in user_recommend
    result_list = []
IndexError: list index out of range
INFO:werkzeug:127.0.0.1 - - [05/May/2021 03:03:55] "[35m[1mGET /556 HTTP/1.1[0m" 500 -
ERROR:app:Exception on /556 [GET]
Traceback (most recent call last):
  File "C:\venvs\smartOrderService\lib\site-packages\flask\app.py", line 2447, in wsgi_app
    response = self.full_dispatch_request()
  File "C:\venvs\smartOrderService\lib\site-packages\flask\app.py", line 1952, in full_dispatch_request
    rv = self.handle_user_exception(e)
  File "C:\venvs\smartOrderService\lib\site-packages\flask_cors\extension.py", line 165, in wrapped_function
    return cors_after_request(app.make_response(f(*args, **kwargs)))
  File "C:\venvs\smartOrderService\lib\site-packages\flask\app.py", line 1821, in handle_user_exception
    reraise(exc_type, exc_value, tb)
  File "C:\venvs\smartOrderService\lib\site-packages\flask\_compat.py", line 39, in reraise
    raise value
  File "C:\venvs\smartOrderService\lib\site-packages\flask\app.py", line 1950, in full_dispatch_request
    rv = self.dispatch_request()
  File "C:\venvs\smartOrderService\lib\site-packages\flask\app.py", line 1936, in dispatch_request
    return self.view_functions[rule.endpoint](**req.view_args)
  File "C:/flaskProjects/smartOrderService_recommendingMenu/app.py", line 57, in recommend
    result = compute_recommending_menu.user_recommend(user_id, each_menu_recommend_data, each_user_pearson_data, conn)
  File "C:\flaskProjects\smartOrderService_recommendingMenu\compute_recommending_menu.py", line 93, in user_recommend
    result_list = []
IndexError: list index out of range
INFO:werkzeug:127.0.0.1 - - [05/May/2021 03:03:57] "[35m[1mGET /556 HTTP/1.1[0m" 500 -
ERROR:app:Exception on /556 [GET]
Traceback (most recent call last):
  File "C:\venvs\smartOrderService\lib\site-packages\flask\app.py", line 2447, in wsgi_app
    response = self.full_dispatch_request()
  File "C:\venvs\smartOrderService\lib\site-packages\flask\app.py", line 1952, in full_dispatch_request
    rv = self.handle_user_exception(e)
  File "C:\venvs\smartOrderService\lib\site-packages\flask_cors\extension.py", line 165, in wrapped_function
    return cors_after_request(app.make_response(f(*args, **kwargs)))
  File "C:\venvs\smartOrderService\lib\site-packages\flask\app.py", line 1821, in handle_user_exception
    reraise(exc_type, exc_value, tb)
  File "C:\venvs\smartOrderService\lib\site-packages\flask\_compat.py", line 39, in reraise
    raise value
  File "C:\venvs\smartOrderService\lib\site-packages\flask\app.py", line 1950, in full_dispatch_request
    rv = self.dispatch_request()
  File "C:\venvs\smartOrderService\lib\site-packages\flask\app.py", line 1936, in dispatch_request
    return self.view_functions[rule.endpoint](**req.view_args)
  File "C:/flaskProjects/smartOrderService_recommendingMenu/app.py", line 57, in recommend
    result = compute_recommending_menu.user_recommend(user_id, each_menu_recommend_data, each_user_pearson_data, conn)
  File "C:\flaskProjects\smartOrderService_recommendingMenu\compute_recommending_menu.py", line 93, in user_recommend
    result_list = []
IndexError: list index out of range
INFO:werkzeug:127.0.0.1 - - [05/May/2021 03:04:00] "[35m[1mGET /556 HTTP/1.1[0m" 500 -
ERROR:app:Exception on /556 [GET]
Traceback (most recent call last):
  File "C:\venvs\smartOrderService\lib\site-packages\flask\app.py", line 2447, in wsgi_app
    response = self.full_dispatch_request()
  File "C:\venvs\smartOrderService\lib\site-packages\flask\app.py", line 1952, in full_dispatch_request
    rv = self.handle_user_exception(e)
  File "C:\venvs\smartOrderService\lib\site-packages\flask_cors\extension.py", line 165, in wrapped_function
    return cors_after_request(app.make_response(f(*args, **kwargs)))
  File "C:\venvs\smartOrderService\lib\site-packages\flask\app.py", line 1821, in handle_user_exception
    reraise(exc_type, exc_value, tb)
  File "C:\venvs\smartOrderService\lib\site-packages\flask\_compat.py", line 39, in reraise
    raise value
  File "C:\venvs\smartOrderService\lib\site-packages\flask\app.py", line 1950, in full_dispatch_request
    rv = self.dispatch_request()
  File "C:\venvs\smartOrderService\lib\site-packages\flask\app.py", line 1936, in dispatch_request
    return self.view_functions[rule.endpoint](**req.view_args)
  File "C:/flaskProjects/smartOrderService_recommendingMenu/app.py", line 57, in recommend
    result = compute_recommending_menu.user_recommend(user_id, each_menu_recommend_data, each_user_pearson_data, conn)
  File "C:\flaskProjects\smartOrderService_recommendingMenu\compute_recommending_menu.py", line 93, in user_recommend
    result_list = []
IndexError: list index out of range
INFO:werkzeug:127.0.0.1 - - [05/May/2021 03:04:00] "[35m[1mGET /556 HTTP/1.1[0m" 500 -
ERROR:app:Exception on /556 [GET]
Traceback (most recent call last):
  File "C:\venvs\smartOrderService\lib\site-packages\flask\app.py", line 2447, in wsgi_app
    response = self.full_dispatch_request()
  File "C:\venvs\smartOrderService\lib\site-packages\flask\app.py", line 1952, in full_dispatch_request
    rv = self.handle_user_exception(e)
  File "C:\venvs\smartOrderService\lib\site-packages\flask_cors\extension.py", line 165, in wrapped_function
    return cors_after_request(app.make_response(f(*args, **kwargs)))
  File "C:\venvs\smartOrderService\lib\site-packages\flask\app.py", line 1821, in handle_user_exception
    reraise(exc_type, exc_value, tb)
  File "C:\venvs\smartOrderService\lib\site-packages\flask\_compat.py", line 39, in reraise
    raise value
  File "C:\venvs\smartOrderService\lib\site-packages\flask\app.py", line 1950, in full_dispatch_request
    rv = self.dispatch_request()
  File "C:\venvs\smartOrderService\lib\site-packages\flask\app.py", line 1936, in dispatch_request
    return self.view_functions[rule.endpoint](**req.view_args)
  File "C:/flaskProjects/smartOrderService_recommendingMenu/app.py", line 57, in recommend
    result = compute_recommending_menu.user_recommend(user_id, each_menu_recommend_data, each_user_pearson_data, conn)
  File "C:\flaskProjects\smartOrderService_recommendingMenu\compute_recommending_menu.py", line 93, in user_recommend
    result_list = []
IndexError: list index out of range
INFO:werkzeug:127.0.0.1 - - [05/May/2021 03:04:01] "[35m[1mGET /556 HTTP/1.1[0m" 500 -
ERROR:app:Exception on /556 [GET]
Traceback (most recent call last):
  File "C:\venvs\smartOrderService\lib\site-packages\flask\app.py", line 2447, in wsgi_app
    response = self.full_dispatch_request()
  File "C:\venvs\smartOrderService\lib\site-packages\flask\app.py", line 1952, in full_dispatch_request
    rv = self.handle_user_exception(e)
  File "C:\venvs\smartOrderService\lib\site-packages\flask_cors\extension.py", line 165, in wrapped_function
    return cors_after_request(app.make_response(f(*args, **kwargs)))
  File "C:\venvs\smartOrderService\lib\site-packages\flask\app.py", line 1821, in handle_user_exception
    reraise(exc_type, exc_value, tb)
  File "C:\venvs\smartOrderService\lib\site-packages\flask\_compat.py", line 39, in reraise
    raise value
  File "C:\venvs\smartOrderService\lib\site-packages\flask\app.py", line 1950, in full_dispatch_request
    rv = self.dispatch_request()
  File "C:\venvs\smartOrderService\lib\site-packages\flask\app.py", line 1936, in dispatch_request
    return self.view_functions[rule.endpoint](**req.view_args)
  File "C:/flaskProjects/smartOrderService_recommendingMenu/app.py", line 57, in recommend
    result = compute_recommending_menu.user_recommend(user_id, each_menu_recommend_data, each_user_pearson_data, conn)
  File "C:\flaskProjects\smartOrderService_recommendingMenu\compute_recommending_menu.py", line 93, in user_recommend
    result_list = []
IndexError: list index out of range
INFO:werkzeug:127.0.0.1 - - [05/May/2021 03:04:01] "[35m[1mGET /556 HTTP/1.1[0m" 500 -
ERROR:app:Exception on /556 [GET]
Traceback (most recent call last):
  File "C:\venvs\smartOrderService\lib\site-packages\flask\app.py", line 2447, in wsgi_app
    response = self.full_dispatch_request()
  File "C:\venvs\smartOrderService\lib\site-packages\flask\app.py", line 1952, in full_dispatch_request
    rv = self.handle_user_exception(e)
  File "C:\venvs\smartOrderService\lib\site-packages\flask_cors\extension.py", line 165, in wrapped_function
    return cors_after_request(app.make_response(f(*args, **kwargs)))
  File "C:\venvs\smartOrderService\lib\site-packages\flask\app.py", line 1821, in handle_user_exception
    reraise(exc_type, exc_value, tb)
  File "C:\venvs\smartOrderService\lib\site-packages\flask\_compat.py", line 39, in reraise
    raise value
  File "C:\venvs\smartOrderService\lib\site-packages\flask\app.py", line 1950, in full_dispatch_request
    rv = self.dispatch_request()
  File "C:\venvs\smartOrderService\lib\site-packages\flask\app.py", line 1936, in dispatch_request
    return self.view_functions[rule.endpoint](**req.view_args)
  File "C:/flaskProjects/smartOrderService_recommendingMenu/app.py", line 57, in recommend
    result = compute_recommending_menu.user_recommend(user_id, each_menu_recommend_data, each_user_pearson_data, conn)
  File "C:\flaskProjects\smartOrderService_recommendingMenu\compute_recommending_menu.py", line 93, in user_recommend
    result_list = []
IndexError: list index out of range
INFO:werkzeug:127.0.0.1 - - [05/May/2021 03:04:01] "[35m[1mGET /556 HTTP/1.1[0m" 500 -
ERROR:app:Exception on /1 [GET]
Traceback (most recent call last):
  File "C:\venvs\smartOrderService\lib\site-packages\flask\app.py", line 2447, in wsgi_app
    response = self.full_dispatch_request()
  File "C:\venvs\smartOrderService\lib\site-packages\flask\app.py", line 1952, in full_dispatch_request
    rv = self.handle_user_exception(e)
  File "C:\venvs\smartOrderService\lib\site-packages\flask_cors\extension.py", line 165, in wrapped_function
    return cors_after_request(app.make_response(f(*args, **kwargs)))
  File "C:\venvs\smartOrderService\lib\site-packages\flask\app.py", line 1821, in handle_user_exception
    reraise(exc_type, exc_value, tb)
  File "C:\venvs\smartOrderService\lib\site-packages\flask\_compat.py", line 39, in reraise
    raise value
  File "C:\venvs\smartOrderService\lib\site-packages\flask\app.py", line 1950, in full_dispatch_request
    rv = self.dispatch_request()
  File "C:\venvs\smartOrderService\lib\site-packages\flask\app.py", line 1936, in dispatch_request
    return self.view_functions[rule.endpoint](**req.view_args)
  File "C:/flaskProjects/smartOrderService_recommendingMenu/app.py", line 57, in recommend
    result = compute_recommending_menu.user_recommend(user_id, each_menu_recommend_data, each_user_pearson_data, conn)
  File "C:\flaskProjects\smartOrderService_recommendingMenu\compute_recommending_menu.py", line 93, in user_recommend
    result_list = []
IndexError: list index out of range
INFO:werkzeug:127.0.0.1 - - [05/May/2021 03:04:25] "[35m[1mGET /1 HTTP/1.1[0m" 500 -
ERROR:app:Exception on /555 [GET]
Traceback (most recent call last):
  File "C:\venvs\smartOrderService\lib\site-packages\flask\app.py", line 2447, in wsgi_app
    response = self.full_dispatch_request()
  File "C:\venvs\smartOrderService\lib\site-packages\flask\app.py", line 1952, in full_dispatch_request
    rv = self.handle_user_exception(e)
  File "C:\venvs\smartOrderService\lib\site-packages\flask_cors\extension.py", line 165, in wrapped_function
    return cors_after_request(app.make_response(f(*args, **kwargs)))
  File "C:\venvs\smartOrderService\lib\site-packages\flask\app.py", line 1821, in handle_user_exception
    reraise(exc_type, exc_value, tb)
  File "C:\venvs\smartOrderService\lib\site-packages\flask\_compat.py", line 39, in reraise
    raise value
  File "C:\venvs\smartOrderService\lib\site-packages\flask\app.py", line 1950, in full_dispatch_request
    rv = self.dispatch_request()
  File "C:\venvs\smartOrderService\lib\site-packages\flask\app.py", line 1936, in dispatch_request
    return self.view_functions[rule.endpoint](**req.view_args)
  File "C:/flaskProjects/smartOrderService_recommendingMenu/app.py", line 57, in recommend
    result = compute_recommending_menu.user_recommend(user_id, each_menu_recommend_data, each_user_pearson_data, conn)
  File "C:\flaskProjects\smartOrderService_recommendingMenu\compute_recommending_menu.py", line 93, in user_recommend
    result_list = []
IndexError: list index out of range
INFO:werkzeug:127.0.0.1 - - [05/May/2021 03:04:29] "[35m[1mGET /555 HTTP/1.1[0m" 500 -
INFO:werkzeug: * Running on http://0.0.0.0:5000/ (Press CTRL+C to quit)
INFO:werkzeug:127.0.0.1 - - [05/May/2021 03:04:40] "[37mGET / HTTP/1.1[0m" 200 -
ERROR:app:Exception on /555 [GET]
Traceback (most recent call last):
  File "C:\venvs\smartOrderService\lib\site-packages\flask\app.py", line 2447, in wsgi_app
    response = self.full_dispatch_request()
  File "C:\venvs\smartOrderService\lib\site-packages\flask\app.py", line 1952, in full_dispatch_request
    rv = self.handle_user_exception(e)
  File "C:\venvs\smartOrderService\lib\site-packages\flask_cors\extension.py", line 165, in wrapped_function
    return cors_after_request(app.make_response(f(*args, **kwargs)))
  File "C:\venvs\smartOrderService\lib\site-packages\flask\app.py", line 1821, in handle_user_exception
    reraise(exc_type, exc_value, tb)
  File "C:\venvs\smartOrderService\lib\site-packages\flask\_compat.py", line 39, in reraise
    raise value
  File "C:\venvs\smartOrderService\lib\site-packages\flask\app.py", line 1950, in full_dispatch_request
    rv = self.dispatch_request()
  File "C:\venvs\smartOrderService\lib\site-packages\flask\app.py", line 1936, in dispatch_request
    return self.view_functions[rule.endpoint](**req.view_args)
  File "C:/flaskProjects/smartOrderService_recommendingMenu/app.py", line 57, in recommend
    result = compute_recommending_menu.user_recommend(user_id, each_menu_recommend_data, each_user_pearson_data, conn)
  File "C:\flaskProjects\smartOrderService_recommendingMenu\compute_recommending_menu.py", line 93, in user_recommend
    result_list = []
IndexError: list index out of range
INFO:werkzeug:127.0.0.1 - - [05/May/2021 03:04:43] "[35m[1mGET /555 HTTP/1.1[0m" 500 -
ERROR:app:Exception on /555 [GET]
Traceback (most recent call last):
  File "C:\venvs\smartOrderService\lib\site-packages\flask\app.py", line 2447, in wsgi_app
    response = self.full_dispatch_request()
  File "C:\venvs\smartOrderService\lib\site-packages\flask\app.py", line 1952, in full_dispatch_request
    rv = self.handle_user_exception(e)
  File "C:\venvs\smartOrderService\lib\site-packages\flask_cors\extension.py", line 165, in wrapped_function
    return cors_after_request(app.make_response(f(*args, **kwargs)))
  File "C:\venvs\smartOrderService\lib\site-packages\flask\app.py", line 1821, in handle_user_exception
    reraise(exc_type, exc_value, tb)
  File "C:\venvs\smartOrderService\lib\site-packages\flask\_compat.py", line 39, in reraise
    raise value
  File "C:\venvs\smartOrderService\lib\site-packages\flask\app.py", line 1950, in full_dispatch_request
    rv = self.dispatch_request()
  File "C:\venvs\smartOrderService\lib\site-packages\flask\app.py", line 1936, in dispatch_request
    return self.view_functions[rule.endpoint](**req.view_args)
  File "C:/flaskProjects/smartOrderService_recommendingMenu/app.py", line 57, in recommend
    result = compute_recommending_menu.user_recommend(user_id, each_menu_recommend_data, each_user_pearson_data, conn)
  File "C:\flaskProjects\smartOrderService_recommendingMenu\compute_recommending_menu.py", line 93, in user_recommend
    result_list = []
IndexError: list index out of range
INFO:werkzeug:127.0.0.1 - - [05/May/2021 03:06:55] "[35m[1mGET /555 HTTP/1.1[0m" 500 -
ERROR:app:Exception on /555 [GET]
Traceback (most recent call last):
  File "C:\venvs\smartOrderService\lib\site-packages\flask\app.py", line 2447, in wsgi_app
    response = self.full_dispatch_request()
  File "C:\venvs\smartOrderService\lib\site-packages\flask\app.py", line 1952, in full_dispatch_request
    rv = self.handle_user_exception(e)
  File "C:\venvs\smartOrderService\lib\site-packages\flask_cors\extension.py", line 165, in wrapped_function
    return cors_after_request(app.make_response(f(*args, **kwargs)))
  File "C:\venvs\smartOrderService\lib\site-packages\flask\app.py", line 1821, in handle_user_exception
    reraise(exc_type, exc_value, tb)
  File "C:\venvs\smartOrderService\lib\site-packages\flask\_compat.py", line 39, in reraise
    raise value
  File "C:\venvs\smartOrderService\lib\site-packages\flask\app.py", line 1950, in full_dispatch_request
    rv = self.dispatch_request()
  File "C:\venvs\smartOrderService\lib\site-packages\flask\app.py", line 1936, in dispatch_request
    return self.view_functions[rule.endpoint](**req.view_args)
  File "C:/flaskProjects/smartOrderService_recommendingMenu/app.py", line 57, in recommend
    result = compute_recommending_menu.user_recommend(user_id, each_menu_recommend_data, each_user_pearson_data, conn)
  File "C:\flaskProjects\smartOrderService_recommendingMenu\compute_recommending_menu.py", line 93, in user_recommend
    result_list = []
IndexError: list index out of range
INFO:werkzeug:127.0.0.1 - - [05/May/2021 03:06:56] "[35m[1mGET /555 HTTP/1.1[0m" 500 -
INFO:werkzeug:127.0.0.1 - - [05/May/2021 03:06:59] "[37mGET / HTTP/1.1[0m" 200 -
INFO:werkzeug: * Running on http://0.0.0.0:5000/ (Press CTRL+C to quit)
INFO:werkzeug:127.0.0.1 - - [05/May/2021 03:10:30] "[37mGET / HTTP/1.1[0m" 200 -
ERROR:app:Exception on /555 [GET]
Traceback (most recent call last):
  File "C:\venvs\smartOrderService\lib\site-packages\flask\app.py", line 2447, in wsgi_app
    response = self.full_dispatch_request()
  File "C:\venvs\smartOrderService\lib\site-packages\flask\app.py", line 1952, in full_dispatch_request
    rv = self.handle_user_exception(e)
  File "C:\venvs\smartOrderService\lib\site-packages\flask_cors\extension.py", line 165, in wrapped_function
    return cors_after_request(app.make_response(f(*args, **kwargs)))
  File "C:\venvs\smartOrderService\lib\site-packages\flask\app.py", line 1821, in handle_user_exception
    reraise(exc_type, exc_value, tb)
  File "C:\venvs\smartOrderService\lib\site-packages\flask\_compat.py", line 39, in reraise
    raise value
  File "C:\venvs\smartOrderService\lib\site-packages\flask\app.py", line 1950, in full_dispatch_request
    rv = self.dispatch_request()
  File "C:\venvs\smartOrderService\lib\site-packages\flask\app.py", line 1936, in dispatch_request
    return self.view_functions[rule.endpoint](**req.view_args)
  File "C:/flaskProjects/smartOrderService_recommendingMenu/app.py", line 57, in recommend
    result = compute_recommending_menu.user_recommend(user_id, each_menu_recommend_data, each_user_pearson_data, conn)
  File "C:\flaskProjects\smartOrderService_recommendingMenu\compute_recommending_menu.py", line 93, in user_recommend
    result_list = []
IndexError: list index out of range
INFO:werkzeug:127.0.0.1 - - [05/May/2021 03:10:33] "[35m[1mGET /555 HTTP/1.1[0m" 500 -
INFO:werkzeug:127.0.0.1 - - [05/May/2021 03:11:05] "[37mGET / HTTP/1.1[0m" 200 -
ERROR:app:Exception on /555 [GET]
Traceback (most recent call last):
  File "C:\venvs\smartOrderService\lib\site-packages\flask\app.py", line 2447, in wsgi_app
    response = self.full_dispatch_request()
  File "C:\venvs\smartOrderService\lib\site-packages\flask\app.py", line 1952, in full_dispatch_request
    rv = self.handle_user_exception(e)
  File "C:\venvs\smartOrderService\lib\site-packages\flask_cors\extension.py", line 165, in wrapped_function
    return cors_after_request(app.make_response(f(*args, **kwargs)))
  File "C:\venvs\smartOrderService\lib\site-packages\flask\app.py", line 1821, in handle_user_exception
    reraise(exc_type, exc_value, tb)
  File "C:\venvs\smartOrderService\lib\site-packages\flask\_compat.py", line 39, in reraise
    raise value
  File "C:\venvs\smartOrderService\lib\site-packages\flask\app.py", line 1950, in full_dispatch_request
    rv = self.dispatch_request()
  File "C:\venvs\smartOrderService\lib\site-packages\flask\app.py", line 1936, in dispatch_request
    return self.view_functions[rule.endpoint](**req.view_args)
  File "C:/flaskProjects/smartOrderService_recommendingMenu/app.py", line 57, in recommend
    result = compute_recommending_menu.user_recommend(user_id, each_menu_recommend_data, each_user_pearson_data, conn)
  File "C:\flaskProjects\smartOrderService_recommendingMenu\compute_recommending_menu.py", line 93, in user_recommend
    result_list = []
IndexError: list index out of range
INFO:werkzeug:127.0.0.1 - - [05/May/2021 03:11:08] "[35m[1mGET /555 HTTP/1.1[0m" 500 -
INFO:werkzeug: * Running on http://0.0.0.0:5000/ (Press CTRL+C to quit)
ERROR:app:Exception on /555 [GET]
Traceback (most recent call last):
  File "C:\venvs\smartOrderService\lib\site-packages\flask\app.py", line 2447, in wsgi_app
    response = self.full_dispatch_request()
  File "C:\venvs\smartOrderService\lib\site-packages\flask\app.py", line 1952, in full_dispatch_request
    rv = self.handle_user_exception(e)
  File "C:\venvs\smartOrderService\lib\site-packages\flask_cors\extension.py", line 165, in wrapped_function
    return cors_after_request(app.make_response(f(*args, **kwargs)))
  File "C:\venvs\smartOrderService\lib\site-packages\flask\app.py", line 1821, in handle_user_exception
    reraise(exc_type, exc_value, tb)
  File "C:\venvs\smartOrderService\lib\site-packages\flask\_compat.py", line 39, in reraise
    raise value
  File "C:\venvs\smartOrderService\lib\site-packages\flask\app.py", line 1950, in full_dispatch_request
    rv = self.dispatch_request()
  File "C:\venvs\smartOrderService\lib\site-packages\flask\app.py", line 1936, in dispatch_request
    return self.view_functions[rule.endpoint](**req.view_args)
  File "C:/flaskProjects/smartOrderService_recommendingMenu/app.py", line 57, in recommend
    result = compute_recommending_menu.user_recommend(user_id, each_menu_recommend_data, each_user_pearson_data, conn)
  File "C:\flaskProjects\smartOrderService_recommendingMenu\compute_recommending_menu.py", line 93, in user_recommend
    result_list = []
IndexError: list index out of range
INFO:werkzeug:127.0.0.1 - - [05/May/2021 03:12:14] "[35m[1mGET /555 HTTP/1.1[0m" 500 -
ERROR:app:Exception on /555 [GET]
Traceback (most recent call last):
  File "C:\venvs\smartOrderService\lib\site-packages\flask\app.py", line 2447, in wsgi_app
    response = self.full_dispatch_request()
  File "C:\venvs\smartOrderService\lib\site-packages\flask\app.py", line 1952, in full_dispatch_request
    rv = self.handle_user_exception(e)
  File "C:\venvs\smartOrderService\lib\site-packages\flask_cors\extension.py", line 165, in wrapped_function
    return cors_after_request(app.make_response(f(*args, **kwargs)))
  File "C:\venvs\smartOrderService\lib\site-packages\flask\app.py", line 1821, in handle_user_exception
    reraise(exc_type, exc_value, tb)
  File "C:\venvs\smartOrderService\lib\site-packages\flask\_compat.py", line 39, in reraise
    raise value
  File "C:\venvs\smartOrderService\lib\site-packages\flask\app.py", line 1950, in full_dispatch_request
    rv = self.dispatch_request()
  File "C:\venvs\smartOrderService\lib\site-packages\flask\app.py", line 1936, in dispatch_request
    return self.view_functions[rule.endpoint](**req.view_args)
  File "C:/flaskProjects/smartOrderService_recommendingMenu/app.py", line 57, in recommend
    result = compute_recommending_menu.user_recommend(user_id, each_menu_recommend_data, each_user_pearson_data, conn)
  File "C:\flaskProjects\smartOrderService_recommendingMenu\compute_recommending_menu.py", line 93, in user_recommend
    result_list = []
IndexError: list index out of range
INFO:werkzeug:127.0.0.1 - - [05/May/2021 03:12:14] "[35m[1mGET /555 HTTP/1.1[0m" 500 -
ERROR:app:Exception on /555 [GET]
Traceback (most recent call last):
  File "C:\venvs\smartOrderService\lib\site-packages\flask\app.py", line 2447, in wsgi_app
    response = self.full_dispatch_request()
  File "C:\venvs\smartOrderService\lib\site-packages\flask\app.py", line 1952, in full_dispatch_request
    rv = self.handle_user_exception(e)
  File "C:\venvs\smartOrderService\lib\site-packages\flask_cors\extension.py", line 165, in wrapped_function
    return cors_after_request(app.make_response(f(*args, **kwargs)))
  File "C:\venvs\smartOrderService\lib\site-packages\flask\app.py", line 1821, in handle_user_exception
    reraise(exc_type, exc_value, tb)
  File "C:\venvs\smartOrderService\lib\site-packages\flask\_compat.py", line 39, in reraise
    raise value
  File "C:\venvs\smartOrderService\lib\site-packages\flask\app.py", line 1950, in full_dispatch_request
    rv = self.dispatch_request()
  File "C:\venvs\smartOrderService\lib\site-packages\flask\app.py", line 1936, in dispatch_request
    return self.view_functions[rule.endpoint](**req.view_args)
  File "C:/flaskProjects/smartOrderService_recommendingMenu/app.py", line 57, in recommend
    result = compute_recommending_menu.user_recommend(user_id, each_menu_recommend_data, each_user_pearson_data, conn)
  File "C:\flaskProjects\smartOrderService_recommendingMenu\compute_recommending_menu.py", line 93, in user_recommend
    result_list = []
IndexError: list index out of range
INFO:werkzeug:127.0.0.1 - - [05/May/2021 03:12:14] "[35m[1mGET /555 HTTP/1.1[0m" 500 -
ERROR:app:Exception on /555 [GET]
Traceback (most recent call last):
  File "C:\venvs\smartOrderService\lib\site-packages\flask\app.py", line 2447, in wsgi_app
    response = self.full_dispatch_request()
  File "C:\venvs\smartOrderService\lib\site-packages\flask\app.py", line 1952, in full_dispatch_request
    rv = self.handle_user_exception(e)
  File "C:\venvs\smartOrderService\lib\site-packages\flask_cors\extension.py", line 165, in wrapped_function
    return cors_after_request(app.make_response(f(*args, **kwargs)))
  File "C:\venvs\smartOrderService\lib\site-packages\flask\app.py", line 1821, in handle_user_exception
    reraise(exc_type, exc_value, tb)
  File "C:\venvs\smartOrderService\lib\site-packages\flask\_compat.py", line 39, in reraise
    raise value
  File "C:\venvs\smartOrderService\lib\site-packages\flask\app.py", line 1950, in full_dispatch_request
    rv = self.dispatch_request()
  File "C:\venvs\smartOrderService\lib\site-packages\flask\app.py", line 1936, in dispatch_request
    return self.view_functions[rule.endpoint](**req.view_args)
  File "C:/flaskProjects/smartOrderService_recommendingMenu/app.py", line 57, in recommend
    result = compute_recommending_menu.user_recommend(user_id, each_menu_recommend_data, each_user_pearson_data, conn)
  File "C:\flaskProjects\smartOrderService_recommendingMenu\compute_recommending_menu.py", line 93, in user_recommend
    result_list = []
IndexError: list index out of range
INFO:werkzeug:127.0.0.1 - - [05/May/2021 03:12:14] "[35m[1mGET /555 HTTP/1.1[0m" 500 -
ERROR:app:Exception on /555 [GET]
Traceback (most recent call last):
  File "C:\venvs\smartOrderService\lib\site-packages\flask\app.py", line 2447, in wsgi_app
    response = self.full_dispatch_request()
  File "C:\venvs\smartOrderService\lib\site-packages\flask\app.py", line 1952, in full_dispatch_request
    rv = self.handle_user_exception(e)
  File "C:\venvs\smartOrderService\lib\site-packages\flask_cors\extension.py", line 165, in wrapped_function
    return cors_after_request(app.make_response(f(*args, **kwargs)))
  File "C:\venvs\smartOrderService\lib\site-packages\flask\app.py", line 1821, in handle_user_exception
    reraise(exc_type, exc_value, tb)
  File "C:\venvs\smartOrderService\lib\site-packages\flask\_compat.py", line 39, in reraise
    raise value
  File "C:\venvs\smartOrderService\lib\site-packages\flask\app.py", line 1950, in full_dispatch_request
    rv = self.dispatch_request()
  File "C:\venvs\smartOrderService\lib\site-packages\flask\app.py", line 1936, in dispatch_request
    return self.view_functions[rule.endpoint](**req.view_args)
  File "C:/flaskProjects/smartOrderService_recommendingMenu/app.py", line 57, in recommend
    result = compute_recommending_menu.user_recommend(user_id, each_menu_recommend_data, each_user_pearson_data, conn)
  File "C:\flaskProjects\smartOrderService_recommendingMenu\compute_recommending_menu.py", line 93, in user_recommend
    result_list = []
IndexError: list index out of range
INFO:werkzeug:127.0.0.1 - - [05/May/2021 03:12:15] "[35m[1mGET /555 HTTP/1.1[0m" 500 -
ERROR:app:Exception on /555 [GET]
Traceback (most recent call last):
  File "C:\venvs\smartOrderService\lib\site-packages\flask\app.py", line 2447, in wsgi_app
    response = self.full_dispatch_request()
  File "C:\venvs\smartOrderService\lib\site-packages\flask\app.py", line 1952, in full_dispatch_request
    rv = self.handle_user_exception(e)
  File "C:\venvs\smartOrderService\lib\site-packages\flask_cors\extension.py", line 165, in wrapped_function
    return cors_after_request(app.make_response(f(*args, **kwargs)))
  File "C:\venvs\smartOrderService\lib\site-packages\flask\app.py", line 1821, in handle_user_exception
    reraise(exc_type, exc_value, tb)
  File "C:\venvs\smartOrderService\lib\site-packages\flask\_compat.py", line 39, in reraise
    raise value
  File "C:\venvs\smartOrderService\lib\site-packages\flask\app.py", line 1950, in full_dispatch_request
    rv = self.dispatch_request()
  File "C:\venvs\smartOrderService\lib\site-packages\flask\app.py", line 1936, in dispatch_request
    return self.view_functions[rule.endpoint](**req.view_args)
  File "C:/flaskProjects/smartOrderService_recommendingMenu/app.py", line 57, in recommend
    result = compute_recommending_menu.user_recommend(user_id, each_menu_recommend_data, each_user_pearson_data, conn)
  File "C:\flaskProjects\smartOrderService_recommendingMenu\compute_recommending_menu.py", line 93, in user_recommend
    result_list = []
IndexError: list index out of range
INFO:werkzeug:127.0.0.1 - - [05/May/2021 03:12:15] "[35m[1mGET /555 HTTP/1.1[0m" 500 -
ERROR:app:Exception on /555 [GET]
Traceback (most recent call last):
  File "C:\venvs\smartOrderService\lib\site-packages\flask\app.py", line 2447, in wsgi_app
    response = self.full_dispatch_request()
  File "C:\venvs\smartOrderService\lib\site-packages\flask\app.py", line 1952, in full_dispatch_request
    rv = self.handle_user_exception(e)
  File "C:\venvs\smartOrderService\lib\site-packages\flask_cors\extension.py", line 165, in wrapped_function
    return cors_after_request(app.make_response(f(*args, **kwargs)))
  File "C:\venvs\smartOrderService\lib\site-packages\flask\app.py", line 1821, in handle_user_exception
    reraise(exc_type, exc_value, tb)
  File "C:\venvs\smartOrderService\lib\site-packages\flask\_compat.py", line 39, in reraise
    raise value
  File "C:\venvs\smartOrderService\lib\site-packages\flask\app.py", line 1950, in full_dispatch_request
    rv = self.dispatch_request()
  File "C:\venvs\smartOrderService\lib\site-packages\flask\app.py", line 1936, in dispatch_request
    return self.view_functions[rule.endpoint](**req.view_args)
  File "C:/flaskProjects/smartOrderService_recommendingMenu/app.py", line 57, in recommend
    result = compute_recommending_menu.user_recommend(user_id, each_menu_recommend_data, each_user_pearson_data, conn)
  File "C:\flaskProjects\smartOrderService_recommendingMenu\compute_recommending_menu.py", line 93, in user_recommend
    result_list = []
IndexError: list index out of range
INFO:werkzeug:127.0.0.1 - - [05/May/2021 03:12:15] "[35m[1mGET /555 HTTP/1.1[0m" 500 -
ERROR:app:Exception on /555 [GET]
Traceback (most recent call last):
  File "C:\venvs\smartOrderService\lib\site-packages\flask\app.py", line 2447, in wsgi_app
    response = self.full_dispatch_request()
  File "C:\venvs\smartOrderService\lib\site-packages\flask\app.py", line 1952, in full_dispatch_request
    rv = self.handle_user_exception(e)
  File "C:\venvs\smartOrderService\lib\site-packages\flask_cors\extension.py", line 165, in wrapped_function
    return cors_after_request(app.make_response(f(*args, **kwargs)))
  File "C:\venvs\smartOrderService\lib\site-packages\flask\app.py", line 1821, in handle_user_exception
    reraise(exc_type, exc_value, tb)
  File "C:\venvs\smartOrderService\lib\site-packages\flask\_compat.py", line 39, in reraise
    raise value
  File "C:\venvs\smartOrderService\lib\site-packages\flask\app.py", line 1950, in full_dispatch_request
    rv = self.dispatch_request()
  File "C:\venvs\smartOrderService\lib\site-packages\flask\app.py", line 1936, in dispatch_request
    return self.view_functions[rule.endpoint](**req.view_args)
  File "C:/flaskProjects/smartOrderService_recommendingMenu/app.py", line 57, in recommend
    result = compute_recommending_menu.user_recommend(user_id, each_menu_recommend_data, each_user_pearson_data, conn)
  File "C:\flaskProjects\smartOrderService_recommendingMenu\compute_recommending_menu.py", line 93, in user_recommend
    result_list = []
IndexError: list index out of range
INFO:werkzeug:127.0.0.1 - - [05/May/2021 03:12:15] "[35m[1mGET /555 HTTP/1.1[0m" 500 -
ERROR:app:Exception on /55 [GET]
Traceback (most recent call last):
  File "C:\venvs\smartOrderService\lib\site-packages\flask\app.py", line 2447, in wsgi_app
    response = self.full_dispatch_request()
  File "C:\venvs\smartOrderService\lib\site-packages\flask\app.py", line 1952, in full_dispatch_request
    rv = self.handle_user_exception(e)
  File "C:\venvs\smartOrderService\lib\site-packages\flask_cors\extension.py", line 165, in wrapped_function
    return cors_after_request(app.make_response(f(*args, **kwargs)))
  File "C:\venvs\smartOrderService\lib\site-packages\flask\app.py", line 1821, in handle_user_exception
    reraise(exc_type, exc_value, tb)
  File "C:\venvs\smartOrderService\lib\site-packages\flask\_compat.py", line 39, in reraise
    raise value
  File "C:\venvs\smartOrderService\lib\site-packages\flask\app.py", line 1950, in full_dispatch_request
    rv = self.dispatch_request()
  File "C:\venvs\smartOrderService\lib\site-packages\flask\app.py", line 1936, in dispatch_request
    return self.view_functions[rule.endpoint](**req.view_args)
  File "C:/flaskProjects/smartOrderService_recommendingMenu/app.py", line 57, in recommend
    result = compute_recommending_menu.user_recommend(user_id, each_menu_recommend_data, each_user_pearson_data, conn)
  File "C:\flaskProjects\smartOrderService_recommendingMenu\compute_recommending_menu.py", line 93, in user_recommend
    result_list = []
IndexError: list index out of range
INFO:werkzeug:127.0.0.1 - - [05/May/2021 03:12:36] "[35m[1mGET /55 HTTP/1.1[0m" 500 -
ERROR:app:Exception on /111 [GET]
Traceback (most recent call last):
  File "C:\venvs\smartOrderService\lib\site-packages\flask\app.py", line 2447, in wsgi_app
    response = self.full_dispatch_request()
  File "C:\venvs\smartOrderService\lib\site-packages\flask\app.py", line 1952, in full_dispatch_request
    rv = self.handle_user_exception(e)
  File "C:\venvs\smartOrderService\lib\site-packages\flask_cors\extension.py", line 165, in wrapped_function
    return cors_after_request(app.make_response(f(*args, **kwargs)))
  File "C:\venvs\smartOrderService\lib\site-packages\flask\app.py", line 1821, in handle_user_exception
    reraise(exc_type, exc_value, tb)
  File "C:\venvs\smartOrderService\lib\site-packages\flask\_compat.py", line 39, in reraise
    raise value
  File "C:\venvs\smartOrderService\lib\site-packages\flask\app.py", line 1950, in full_dispatch_request
    rv = self.dispatch_request()
  File "C:\venvs\smartOrderService\lib\site-packages\flask\app.py", line 1936, in dispatch_request
    return self.view_functions[rule.endpoint](**req.view_args)
  File "C:/flaskProjects/smartOrderService_recommendingMenu/app.py", line 57, in recommend
    result = compute_recommending_menu.user_recommend(user_id, each_menu_recommend_data, each_user_pearson_data, conn)
  File "C:\flaskProjects\smartOrderService_recommendingMenu\compute_recommending_menu.py", line 93, in user_recommend
    result_list = []
IndexError: list index out of range
INFO:werkzeug:127.0.0.1 - - [05/May/2021 03:12:39] "[35m[1mGET /111 HTTP/1.1[0m" 500 -
ERROR:app:Exception on /111 [GET]
Traceback (most recent call last):
  File "C:\venvs\smartOrderService\lib\site-packages\flask\app.py", line 2447, in wsgi_app
    response = self.full_dispatch_request()
  File "C:\venvs\smartOrderService\lib\site-packages\flask\app.py", line 1952, in full_dispatch_request
    rv = self.handle_user_exception(e)
  File "C:\venvs\smartOrderService\lib\site-packages\flask_cors\extension.py", line 165, in wrapped_function
    return cors_after_request(app.make_response(f(*args, **kwargs)))
  File "C:\venvs\smartOrderService\lib\site-packages\flask\app.py", line 1821, in handle_user_exception
    reraise(exc_type, exc_value, tb)
  File "C:\venvs\smartOrderService\lib\site-packages\flask\_compat.py", line 39, in reraise
    raise value
  File "C:\venvs\smartOrderService\lib\site-packages\flask\app.py", line 1950, in full_dispatch_request
    rv = self.dispatch_request()
  File "C:\venvs\smartOrderService\lib\site-packages\flask\app.py", line 1936, in dispatch_request
    return self.view_functions[rule.endpoint](**req.view_args)
  File "C:/flaskProjects/smartOrderService_recommendingMenu/app.py", line 57, in recommend
    result = compute_recommending_menu.user_recommend(user_id, each_menu_recommend_data, each_user_pearson_data, conn)
  File "C:\flaskProjects\smartOrderService_recommendingMenu\compute_recommending_menu.py", line 93, in user_recommend
    result_list = []
IndexError: list index out of range
INFO:werkzeug:127.0.0.1 - - [05/May/2021 03:13:16] "[35m[1mGET /111 HTTP/1.1[0m" 500 -
ERROR:app:Exception on /666 [GET]
Traceback (most recent call last):
  File "C:\venvs\smartOrderService\lib\site-packages\flask\app.py", line 2447, in wsgi_app
    response = self.full_dispatch_request()
  File "C:\venvs\smartOrderService\lib\site-packages\flask\app.py", line 1952, in full_dispatch_request
    rv = self.handle_user_exception(e)
  File "C:\venvs\smartOrderService\lib\site-packages\flask_cors\extension.py", line 165, in wrapped_function
    return cors_after_request(app.make_response(f(*args, **kwargs)))
  File "C:\venvs\smartOrderService\lib\site-packages\flask\app.py", line 1821, in handle_user_exception
    reraise(exc_type, exc_value, tb)
  File "C:\venvs\smartOrderService\lib\site-packages\flask\_compat.py", line 39, in reraise
    raise value
  File "C:\venvs\smartOrderService\lib\site-packages\flask\app.py", line 1950, in full_dispatch_request
    rv = self.dispatch_request()
  File "C:\venvs\smartOrderService\lib\site-packages\flask\app.py", line 1936, in dispatch_request
    return self.view_functions[rule.endpoint](**req.view_args)
  File "C:/flaskProjects/smartOrderService_recommendingMenu/app.py", line 57, in recommend
    result = compute_recommending_menu.user_recommend(user_id, each_menu_recommend_data, each_user_pearson_data, conn)
  File "C:\flaskProjects\smartOrderService_recommendingMenu\compute_recommending_menu.py", line 93, in user_recommend
    result_list = []
IndexError: list index out of range
INFO:werkzeug:127.0.0.1 - - [05/May/2021 03:13:20] "[35m[1mGET /666 HTTP/1.1[0m" 500 -
INFO:werkzeug: * Restarting with stat
ERROR:app:Exception on /666 [GET]
Traceback (most recent call last):
  File "C:\venvs\smartOrderService\lib\site-packages\flask\app.py", line 2447, in wsgi_app
    response = self.full_dispatch_request()
  File "C:\venvs\smartOrderService\lib\site-packages\flask\app.py", line 1952, in full_dispatch_request
    rv = self.handle_user_exception(e)
  File "C:\venvs\smartOrderService\lib\site-packages\flask_cors\extension.py", line 165, in wrapped_function
    return cors_after_request(app.make_response(f(*args, **kwargs)))
  File "C:\venvs\smartOrderService\lib\site-packages\flask\app.py", line 1821, in handle_user_exception
    reraise(exc_type, exc_value, tb)
  File "C:\venvs\smartOrderService\lib\site-packages\flask\_compat.py", line 39, in reraise
    raise value
  File "C:\venvs\smartOrderService\lib\site-packages\flask\app.py", line 1950, in full_dispatch_request
    rv = self.dispatch_request()
  File "C:\venvs\smartOrderService\lib\site-packages\flask\app.py", line 1936, in dispatch_request
    return self.view_functions[rule.endpoint](**req.view_args)
  File "C:/flaskProjects/smartOrderService_recommendingMenu/app.py", line 57, in recommend
    result = compute_recommending_menu.user_recommend(user_id, each_menu_recommend_data, each_user_pearson_data, conn)
  File "C:\flaskProjects\smartOrderService_recommendingMenu\compute_recommending_menu.py", line 93, in user_recommend
    result_list = []
IndexError: list index out of range
INFO:werkzeug:127.0.0.1 - - [05/May/2021 03:13:53] "[35m[1mGET /666 HTTP/1.1[0m" 500 -
WARNING:werkzeug: * Debugger is active!
INFO:werkzeug: * Debugger PIN: 158-607-768
INFO:werkzeug: * Running on http://0.0.0.0:5000/ (Press CTRL+C to quit)
ERROR:app:Exception on /666 [GET]
Traceback (most recent call last):
  File "C:\venvs\smartOrderService\lib\site-packages\flask\app.py", line 2447, in wsgi_app
    response = self.full_dispatch_request()
  File "C:\venvs\smartOrderService\lib\site-packages\flask\app.py", line 1952, in full_dispatch_request
    rv = self.handle_user_exception(e)
  File "C:\venvs\smartOrderService\lib\site-packages\flask_cors\extension.py", line 165, in wrapped_function
    return cors_after_request(app.make_response(f(*args, **kwargs)))
  File "C:\venvs\smartOrderService\lib\site-packages\flask\app.py", line 1821, in handle_user_exception
    reraise(exc_type, exc_value, tb)
  File "C:\venvs\smartOrderService\lib\site-packages\flask\_compat.py", line 39, in reraise
    raise value
  File "C:\venvs\smartOrderService\lib\site-packages\flask\app.py", line 1950, in full_dispatch_request
    rv = self.dispatch_request()
  File "C:\venvs\smartOrderService\lib\site-packages\flask\app.py", line 1936, in dispatch_request
    return self.view_functions[rule.endpoint](**req.view_args)
  File "C:/flaskProjects/smartOrderService_recommendingMenu/app.py", line 57, in recommend
    result = compute_recommending_menu.user_recommend(user_id, each_menu_recommend_data, each_user_pearson_data, conn)
  File "C:\flaskProjects\smartOrderService_recommendingMenu\compute_recommending_menu.py", line 93, in user_recommend
    result_list = []
IndexError: list index out of range
INFO:werkzeug:127.0.0.1 - - [05/May/2021 03:13:55] "[35m[1mGET /666 HTTP/1.1[0m" 500 -
INFO:werkzeug:127.0.0.1 - - [05/May/2021 03:14:01] "[37mGET / HTTP/1.1[0m" 200 -
ERROR:app:Exception on /555 [GET]
Traceback (most recent call last):
  File "C:\venvs\smartOrderService\lib\site-packages\flask\app.py", line 2447, in wsgi_app
    response = self.full_dispatch_request()
  File "C:\venvs\smartOrderService\lib\site-packages\flask\app.py", line 1952, in full_dispatch_request
    rv = self.handle_user_exception(e)
  File "C:\venvs\smartOrderService\lib\site-packages\flask_cors\extension.py", line 165, in wrapped_function
    return cors_after_request(app.make_response(f(*args, **kwargs)))
  File "C:\venvs\smartOrderService\lib\site-packages\flask\app.py", line 1821, in handle_user_exception
    reraise(exc_type, exc_value, tb)
  File "C:\venvs\smartOrderService\lib\site-packages\flask\_compat.py", line 39, in reraise
    raise value
  File "C:\venvs\smartOrderService\lib\site-packages\flask\app.py", line 1950, in full_dispatch_request
    rv = self.dispatch_request()
  File "C:\venvs\smartOrderService\lib\site-packages\flask\app.py", line 1936, in dispatch_request
    return self.view_functions[rule.endpoint](**req.view_args)
  File "C:/flaskProjects/smartOrderService_recommendingMenu/app.py", line 57, in recommend
    result = compute_recommending_menu.user_recommend(user_id, each_menu_recommend_data, each_user_pearson_data, conn)
  File "C:\flaskProjects\smartOrderService_recommendingMenu\compute_recommending_menu.py", line 93, in user_recommend
    result_list = []
IndexError: list index out of range
INFO:werkzeug:127.0.0.1 - - [05/May/2021 03:14:08] "[35m[1mGET /555 HTTP/1.1[0m" 500 -
INFO:werkzeug: * Detected change in 'C:\\flaskProjects\\smartOrderService_recommendingMenu\\app.py', reloading
INFO:werkzeug: * Restarting with stat
INFO:werkzeug: * Running on http://0.0.0.0:5000/ (Press CTRL+C to quit)
INFO:werkzeug: * Running on http://0.0.0.0:5000/ (Press CTRL+C to quit)
INFO:werkzeug:127.0.0.1 - - [05/May/2021 03:15:26] "[37mGET / HTTP/1.1[0m" 200 -
INFO:werkzeug:127.0.0.1 - - [05/May/2021 03:15:36] "[37mGET /refresh_data HTTP/1.1[0m" 200 -
INFO:werkzeug:127.0.0.1 - - [05/May/2021 03:15:42] "[37mGET /555 HTTP/1.1[0m" 200 -
INFO:werkzeug:127.0.0.1 - - [05/May/2021 13:15:41] "[37mGET / HTTP/1.1[0m" 200 -
INFO:werkzeug:127.0.0.1 - - [05/May/2021 13:15:44] "[37mGET /566 HTTP/1.1[0m" 200 -
