INFO:werkzeug: * Running on http://0.0.0.0:5000/ (Press CTRL+C to quit)
INFO:werkzeug: * Running on http://0.0.0.0:5000/ (Press CTRL+C to quit)
INFO:werkzeug:127.0.0.1 - - [04/May/2021 13:33:18] "[37mGET / HTTP/1.1[0m" 200 -
INFO:werkzeug:127.0.0.1 - - [04/May/2021 13:33:18] "[33mGET /favicon.ico HTTP/1.1[0m" 404 -
INFO:werkzeug:127.0.0.1 - - [04/May/2021 13:33:23] "[37mGET /3 HTTP/1.1[0m" 200 -
ERROR:app:Exception on /$%refresh_data [GET]
Traceback (most recent call last):
  File "C:\venvs\smartOrderService\lib\site-packages\flask\app.py", line 2447, in wsgi_app
    response = self.full_dispatch_request()
  File "C:\venvs\smartOrderService\lib\site-packages\flask\app.py", line 1953, in full_dispatch_request
    return self.finalize_request(rv)
  File "C:\venvs\smartOrderService\lib\site-packages\flask\app.py", line 1968, in finalize_request
    response = self.make_response(rv)
  File "C:\venvs\smartOrderService\lib\site-packages\flask\app.py", line 2097, in make_response
    raise TypeError(
TypeError: The view function did not return a valid response. The function either returned None or ended without a return statement.
INFO:werkzeug:127.0.0.1 - - [04/May/2021 13:34:10] "[35m[1mGET /$%refresh_data HTTP/1.1[0m" 500 -
INFO:werkzeug: * Running on http://0.0.0.0:5000/ (Press CTRL+C to quit)
INFO:werkzeug:127.0.0.1 - - [04/May/2021 13:35:15] "[33mGET /refresh_data HTTP/1.1[0m" 404 -
INFO:werkzeug:127.0.0.1 - - [04/May/2021 13:35:45] "[33mGET /refresh_data HTTP/1.1[0m" 404 -
INFO:werkzeug:127.0.0.1 - - [04/May/2021 13:35:47] "[33mGET /refresh_data HTTP/1.1[0m" 404 -
INFO:werkzeug:127.0.0.1 - - [04/May/2021 13:35:47] "[33mGET /refresh_data HTTP/1.1[0m" 404 -
INFO:werkzeug:127.0.0.1 - - [04/May/2021 13:35:47] "[33mGET /refresh_data HTTP/1.1[0m" 404 -
INFO:werkzeug:127.0.0.1 - - [04/May/2021 13:35:47] "[33mGET /refresh_data HTTP/1.1[0m" 404 -
INFO:werkzeug:127.0.0.1 - - [04/May/2021 13:35:47] "[33mGET /refresh_data HTTP/1.1[0m" 404 -
INFO:werkzeug:127.0.0.1 - - [04/May/2021 13:35:47] "[33mGET /refresh_data HTTP/1.1[0m" 404 -
INFO:werkzeug:127.0.0.1 - - [04/May/2021 13:35:48] "[33mGET /refresh_data HTTP/1.1[0m" 404 -
INFO:werkzeug:127.0.0.1 - - [04/May/2021 13:35:48] "[33mGET /refresh_data HTTP/1.1[0m" 404 -
INFO:werkzeug:127.0.0.1 - - [04/May/2021 13:35:50] "[37mGET / HTTP/1.1[0m" 200 -
INFO:werkzeug: * Running on http://0.0.0.0:5000/ (Press CTRL+C to quit)
INFO:werkzeug:127.0.0.1 - - [04/May/2021 13:36:04] "[33mGET /refresh_dat HTTP/1.1[0m" 404 -
INFO:werkzeug:127.0.0.1 - - [04/May/2021 13:36:07] "[33mGET /refresh_data HTTP/1.1[0m" 404 -
INFO:werkzeug:127.0.0.1 - - [04/May/2021 13:36:08] "[33mGET /refresh_data HTTP/1.1[0m" 404 -
INFO:werkzeug:127.0.0.1 - - [04/May/2021 13:36:09] "[33mGET /refresh_data HTTP/1.1[0m" 404 -
INFO:werkzeug:127.0.0.1 - - [04/May/2021 13:36:09] "[33mGET /refresh_data HTTP/1.1[0m" 404 -
INFO:werkzeug:127.0.0.1 - - [04/May/2021 13:36:09] "[33mGET /refresh_data HTTP/1.1[0m" 404 -
INFO:werkzeug:127.0.0.1 - - [04/May/2021 13:36:10] "[33mGET /refresh_data HTTP/1.1[0m" 404 -
INFO:werkzeug:127.0.0.1 - - [04/May/2021 13:36:10] "[33mGET /refresh_data HTTP/1.1[0m" 404 -
INFO:werkzeug: * Running on http://0.0.0.0:5000/ (Press CTRL+C to quit)
INFO:werkzeug:127.0.0.1 - - [04/May/2021 13:38:17] "[33mGET /refresh_data HTTP/1.1[0m" 404 -
INFO:werkzeug:127.0.0.1 - - [04/May/2021 13:38:19] "[33mGET /refresh_data HTTP/1.1[0m" 404 -
INFO:werkzeug:127.0.0.1 - - [04/May/2021 13:38:19] "[33mGET /refresh_data HTTP/1.1[0m" 404 -
INFO:werkzeug:127.0.0.1 - - [04/May/2021 13:38:20] "[33mGET /refresh_data HTTP/1.1[0m" 404 -
INFO:werkzeug:127.0.0.1 - - [04/May/2021 13:38:20] "[33mGET /refresh_data HTTP/1.1[0m" 404 -
INFO:werkzeug:127.0.0.1 - - [04/May/2021 13:38:20] "[33mGET /refresh_data HTTP/1.1[0m" 404 -
INFO:werkzeug:127.0.0.1 - - [04/May/2021 13:38:20] "[33mGET /refresh_data HTTP/1.1[0m" 404 -
INFO:werkzeug:127.0.0.1 - - [04/May/2021 13:38:21] "[33mGET /refresh_data HTTP/1.1[0m" 404 -
INFO:werkzeug:127.0.0.1 - - [04/May/2021 13:38:21] "[33mGET /refresh_data HTTP/1.1[0m" 404 -
INFO:werkzeug:127.0.0.1 - - [04/May/2021 13:38:21] "[33mGET /refresh_data HTTP/1.1[0m" 404 -
INFO:werkzeug:127.0.0.1 - - [04/May/2021 13:38:21] "[33mGET /refresh_data HTTP/1.1[0m" 404 -
INFO:werkzeug:127.0.0.1 - - [04/May/2021 13:38:21] "[33mGET /refresh_data HTTP/1.1[0m" 404 -
INFO:werkzeug:127.0.0.1 - - [04/May/2021 13:40:19] "[37mGET /home HTTP/1.1[0m" 200 -
INFO:werkzeug: * Running on http://0.0.0.0:5000/ (Press CTRL+C to quit)
INFO:werkzeug:127.0.0.1 - - [04/May/2021 13:40:51] "[33mGET /refresh_data HTTP/1.1[0m" 404 -
INFO:werkzeug:127.0.0.1 - - [04/May/2021 13:41:12] "[33mGET /refresh_data HTTP/1.1[0m" 404 -
INFO:werkzeug:127.0.0.1 - - [04/May/2021 13:41:13] "[33mGET /refresh_data HTTP/1.1[0m" 404 -
INFO:werkzeug:127.0.0.1 - - [04/May/2021 13:41:14] "[33mGET /refresh_data HTTP/1.1[0m" 404 -
INFO:werkzeug: * Running on http://0.0.0.0:5000/ (Press CTRL+C to quit)
INFO:werkzeug:127.0.0.1 - - [04/May/2021 13:41:47] "[37mGET / HTTP/1.1[0m" 200 -
INFO:werkzeug:127.0.0.1 - - [04/May/2021 13:41:53] "[33mGET /refresh_data HTTP/1.1[0m" 404 -
INFO:werkzeug: * Running on http://0.0.0.0:5000/ (Press CTRL+C to quit)
INFO:werkzeug:127.0.0.1 - - [04/May/2021 13:42:14] "[33mGET /refresh_data HTTP/1.1[0m" 404 -
INFO:werkzeug:127.0.0.1 - - [04/May/2021 13:42:15] "[33mGET /refresh_data HTTP/1.1[0m" 404 -
INFO:werkzeug:127.0.0.1 - - [04/May/2021 13:42:15] "[33mGET /refresh_data HTTP/1.1[0m" 404 -
INFO:werkzeug:127.0.0.1 - - [04/May/2021 13:42:17] "[37mGET / HTTP/1.1[0m" 200 -
INFO:werkzeug:127.0.0.1 - - [04/May/2021 13:42:19] "[33mGET /refresh_data HTTP/1.1[0m" 404 -
INFO:werkzeug:127.0.0.1 - - [04/May/2021 13:42:19] "[33mGET /refresh_data HTTP/1.1[0m" 404 -
INFO:werkzeug:127.0.0.1 - - [04/May/2021 13:42:20] "[33mGET /refresh_data HTTP/1.1[0m" 404 -
INFO:werkzeug:127.0.0.1 - - [04/May/2021 13:42:20] "[33mGET /refresh_data HTTP/1.1[0m" 404 -
INFO:werkzeug:127.0.0.1 - - [04/May/2021 13:42:20] "[33mGET /refresh_data HTTP/1.1[0m" 404 -
INFO:werkzeug:127.0.0.1 - - [04/May/2021 13:42:20] "[33mGET /refresh_data HTTP/1.1[0m" 404 -
INFO:werkzeug:127.0.0.1 - - [04/May/2021 13:42:21] "[33mGET /refresh_data HTTP/1.1[0m" 404 -
INFO:werkzeug: * Running on http://0.0.0.0:5000/ (Press CTRL+C to quit)
INFO:werkzeug:127.0.0.1 - - [05/May/2021 02:30:59] "[37mGET / HTTP/1.1[0m" 200 -
INFO:werkzeug:127.0.0.1 - - [05/May/2021 02:30:59] "[33mGET /favicon.ico HTTP/1.1[0m" 404 -
ERROR:app:Exception on /555 [GET]
Traceback (most recent call last):
  File "C:\venvs\smartOrderService\lib\site-packages\flask\app.py", line 2447, in wsgi_app
    response = self.full_dispatch_request()
  File "C:\venvs\smartOrderService\lib\site-packages\flask\app.py", line 1952, in full_dispatch_request
    rv = self.handle_user_exception(e)
  File "C:\venvs\smartOrderService\lib\site-packages\flask_cors\extension.py", line 165, in wrapped_function
    return cors_after_request(app.make_response(f(*args, **kwargs)))
  File "C:\venvs\smartOrderService\lib\site-packages\flask\app.py", line 1821, in handle_user_exception
    reraise(exc_type, exc_value, tb)
  File "C:\venvs\smartOrderService\lib\site-packages\flask\_compat.py", line 39, in reraise
    raise value
  File "C:\venvs\smartOrderService\lib\site-packages\flask\app.py", line 1950, in full_dispatch_request
    rv = self.dispatch_request()
  File "C:\venvs\smartOrderService\lib\site-packages\flask\app.py", line 1936, in dispatch_request
    return self.view_functions[rule.endpoint](**req.view_args)
  File "C:/flaskProjects/smartOrderService_recommendingMenu/app.py", line 57, in recommend
    result = compute_recommending_menu.user_recommend(user_id, each_menu_recommend_data, each_user_pearson_data, conn)
  File "C:\flaskProjects\smartOrderService_recommendingMenu\compute_recommending_menu.py", line 93, in user_recommend
    cur_user_pearson_datas = each_user_pearson_data[user_id]['Pearson Data']
IndexError: list index out of range
INFO:werkzeug:127.0.0.1 - - [05/May/2021 02:31:02] "[35m[1mGET /555 HTTP/1.1[0m" 500 -
ERROR:app:Exception on /555 [GET]
Traceback (most recent call last):
  File "C:\venvs\smartOrderService\lib\site-packages\flask\app.py", line 2447, in wsgi_app
    response = self.full_dispatch_request()
  File "C:\venvs\smartOrderService\lib\site-packages\flask\app.py", line 1952, in full_dispatch_request
    rv = self.handle_user_exception(e)
  File "C:\venvs\smartOrderService\lib\site-packages\flask_cors\extension.py", line 165, in wrapped_function
    return cors_after_request(app.make_response(f(*args, **kwargs)))
  File "C:\venvs\smartOrderService\lib\site-packages\flask\app.py", line 1821, in handle_user_exception
    reraise(exc_type, exc_value, tb)
  File "C:\venvs\smartOrderService\lib\site-packages\flask\_compat.py", line 39, in reraise
    raise value
  File "C:\venvs\smartOrderService\lib\site-packages\flask\app.py", line 1950, in full_dispatch_request
    rv = self.dispatch_request()
  File "C:\venvs\smartOrderService\lib\site-packages\flask\app.py", line 1936, in dispatch_request
    return self.view_functions[rule.endpoint](**req.view_args)
  File "C:/flaskProjects/smartOrderService_recommendingMenu/app.py", line 57, in recommend
    result = compute_recommending_menu.user_recommend(user_id, each_menu_recommend_data, each_user_pearson_data, conn)
  File "C:\flaskProjects\smartOrderService_recommendingMenu\compute_recommending_menu.py", line 93, in user_recommend
    cur_user_pearson_datas = each_user_pearson_data[user_id]['Pearson Data']
IndexError: list index out of range
INFO:werkzeug:127.0.0.1 - - [05/May/2021 02:31:59] "[35m[1mGET /555 HTTP/1.1[0m" 500 -
INFO:werkzeug:127.0.0.1 - - [05/May/2021 02:32:02] "[37mGET / HTTP/1.1[0m" 200 -
INFO:werkzeug: * Running on http://0.0.0.0:5000/ (Press CTRL+C to quit)
INFO:werkzeug:127.0.0.1 - - [05/May/2021 02:32:42] "[37mGET / HTTP/1.1[0m" 200 -
ERROR:app:Exception on /555 [GET]
Traceback (most recent call last):
  File "C:\venvs\smartOrderService\lib\site-packages\flask\app.py", line 2447, in wsgi_app
    response = self.full_dispatch_request()
  File "C:\venvs\smartOrderService\lib\site-packages\flask\app.py", line 1952, in full_dispatch_request
    rv = self.handle_user_exception(e)
  File "C:\venvs\smartOrderService\lib\site-packages\flask_cors\extension.py", line 165, in wrapped_function
    return cors_after_request(app.make_response(f(*args, **kwargs)))
  File "C:\venvs\smartOrderService\lib\site-packages\flask\app.py", line 1821, in handle_user_exception
    reraise(exc_type, exc_value, tb)
  File "C:\venvs\smartOrderService\lib\site-packages\flask\_compat.py", line 39, in reraise
    raise value
  File "C:\venvs\smartOrderService\lib\site-packages\flask\app.py", line 1950, in full_dispatch_request
    rv = self.dispatch_request()
  File "C:\venvs\smartOrderService\lib\site-packages\flask\app.py", line 1936, in dispatch_request
    return self.view_functions[rule.endpoint](**req.view_args)
  File "C:/flaskProjects/smartOrderService_recommendingMenu/app.py", line 57, in recommend
    result = compute_recommending_menu.user_recommend(user_id, each_menu_recommend_data, each_user_pearson_data, conn)
  File "C:\flaskProjects\smartOrderService_recommendingMenu\compute_recommending_menu.py", line 93, in user_recommend
    cur_user_pearson_datas = each_user_pearson_data[user_id]['Pearson Data']
IndexError: list index out of range
INFO:werkzeug:127.0.0.1 - - [05/May/2021 02:32:44] "[35m[1mGET /555 HTTP/1.1[0m" 500 -
ERROR:app:Exception on /555 [GET]
Traceback (most recent call last):
  File "C:\venvs\smartOrderService\lib\site-packages\flask\app.py", line 2447, in wsgi_app
    response = self.full_dispatch_request()
  File "C:\venvs\smartOrderService\lib\site-packages\flask\app.py", line 1952, in full_dispatch_request
    rv = self.handle_user_exception(e)
  File "C:\venvs\smartOrderService\lib\site-packages\flask_cors\extension.py", line 165, in wrapped_function
    return cors_after_request(app.make_response(f(*args, **kwargs)))
  File "C:\venvs\smartOrderService\lib\site-packages\flask\app.py", line 1821, in handle_user_exception
    reraise(exc_type, exc_value, tb)
  File "C:\venvs\smartOrderService\lib\site-packages\flask\_compat.py", line 39, in reraise
    raise value
  File "C:\venvs\smartOrderService\lib\site-packages\flask\app.py", line 1950, in full_dispatch_request
    rv = self.dispatch_request()
  File "C:\venvs\smartOrderService\lib\site-packages\flask\app.py", line 1936, in dispatch_request
    return self.view_functions[rule.endpoint](**req.view_args)
  File "C:/flaskProjects/smartOrderService_recommendingMenu/app.py", line 57, in recommend
    result = compute_recommending_menu.user_recommend(user_id, each_menu_recommend_data, each_user_pearson_data, conn)
  File "C:\flaskProjects\smartOrderService_recommendingMenu\compute_recommending_menu.py", line 93, in user_recommend
    cur_user_pearson_datas = each_user_pearson_data[user_id]['Pearson Data']
IndexError: list index out of range
INFO:werkzeug:127.0.0.1 - - [05/May/2021 02:32:53] "[35m[1mGET /555 HTTP/1.1[0m" 500 -
INFO:werkzeug: * Running on http://0.0.0.0:5000/ (Press CTRL+C to quit)
ERROR:app:Exception on /555 [GET]
Traceback (most recent call last):
  File "C:\venvs\smartOrderService\lib\site-packages\flask\app.py", line 2447, in wsgi_app
    response = self.full_dispatch_request()
  File "C:\venvs\smartOrderService\lib\site-packages\flask\app.py", line 1952, in full_dispatch_request
    rv = self.handle_user_exception(e)
  File "C:\venvs\smartOrderService\lib\site-packages\flask_cors\extension.py", line 165, in wrapped_function
    return cors_after_request(app.make_response(f(*args, **kwargs)))
  File "C:\venvs\smartOrderService\lib\site-packages\flask\app.py", line 1821, in handle_user_exception
    reraise(exc_type, exc_value, tb)
  File "C:\venvs\smartOrderService\lib\site-packages\flask\_compat.py", line 39, in reraise
    raise value
  File "C:\venvs\smartOrderService\lib\site-packages\flask\app.py", line 1950, in full_dispatch_request
    rv = self.dispatch_request()
  File "C:\venvs\smartOrderService\lib\site-packages\flask\app.py", line 1936, in dispatch_request
    return self.view_functions[rule.endpoint](**req.view_args)
  File "C:/flaskProjects/smartOrderService_recommendingMenu/app.py", line 57, in recommend
    result = compute_recommending_menu.user_recommend(user_id, each_menu_recommend_data, each_user_pearson_data, conn)
  File "C:\flaskProjects\smartOrderService_recommendingMenu\compute_recommending_menu.py", line 93, in user_recommend
    cur_user_pearson_datas = each_user_pearson_data[user_id]['Pearson Data']
IndexError: list index out of range
INFO:werkzeug:127.0.0.1 - - [05/May/2021 02:33:45] "[35m[1mGET /555 HTTP/1.1[0m" 500 -
ERROR:app:Exception on /555 [GET]
Traceback (most recent call last):
  File "C:\venvs\smartOrderService\lib\site-packages\flask\app.py", line 2447, in wsgi_app
    response = self.full_dispatch_request()
  File "C:\venvs\smartOrderService\lib\site-packages\flask\app.py", line 1952, in full_dispatch_request
    rv = self.handle_user_exception(e)
  File "C:\venvs\smartOrderService\lib\site-packages\flask_cors\extension.py", line 165, in wrapped_function
    return cors_after_request(app.make_response(f(*args, **kwargs)))
  File "C:\venvs\smartOrderService\lib\site-packages\flask\app.py", line 1821, in handle_user_exception
    reraise(exc_type, exc_value, tb)
  File "C:\venvs\smartOrderService\lib\site-packages\flask\_compat.py", line 39, in reraise
    raise value
  File "C:\venvs\smartOrderService\lib\site-packages\flask\app.py", line 1950, in full_dispatch_request
    rv = self.dispatch_request()
  File "C:\venvs\smartOrderService\lib\site-packages\flask\app.py", line 1936, in dispatch_request
    return self.view_functions[rule.endpoint](**req.view_args)
  File "C:/flaskProjects/smartOrderService_recommendingMenu/app.py", line 57, in recommend
    result = compute_recommending_menu.user_recommend(user_id, each_menu_recommend_data, each_user_pearson_data, conn)
  File "C:\flaskProjects\smartOrderService_recommendingMenu\compute_recommending_menu.py", line 93, in user_recommend
    cur_user_pearson_datas = each_user_pearson_data[user_id]['Pearson Data']
IndexError: list index out of range
INFO:werkzeug:127.0.0.1 - - [05/May/2021 02:33:47] "[35m[1mGET /555 HTTP/1.1[0m" 500 -
ERROR:app:Exception on /555 [GET]
Traceback (most recent call last):
  File "C:\venvs\smartOrderService\lib\site-packages\flask\app.py", line 2447, in wsgi_app
    response = self.full_dispatch_request()
  File "C:\venvs\smartOrderService\lib\site-packages\flask\app.py", line 1952, in full_dispatch_request
    rv = self.handle_user_exception(e)
  File "C:\venvs\smartOrderService\lib\site-packages\flask_cors\extension.py", line 165, in wrapped_function
    return cors_after_request(app.make_response(f(*args, **kwargs)))
  File "C:\venvs\smartOrderService\lib\site-packages\flask\app.py", line 1821, in handle_user_exception
    reraise(exc_type, exc_value, tb)
  File "C:\venvs\smartOrderService\lib\site-packages\flask\_compat.py", line 39, in reraise
    raise value
  File "C:\venvs\smartOrderService\lib\site-packages\flask\app.py", line 1950, in full_dispatch_request
    rv = self.dispatch_request()
  File "C:\venvs\smartOrderService\lib\site-packages\flask\app.py", line 1936, in dispatch_request
    return self.view_functions[rule.endpoint](**req.view_args)
  File "C:/flaskProjects/smartOrderService_recommendingMenu/app.py", line 57, in recommend
    result = compute_recommending_menu.user_recommend(user_id, each_menu_recommend_data, each_user_pearson_data, conn)
  File "C:\flaskProjects\smartOrderService_recommendingMenu\compute_recommending_menu.py", line 93, in user_recommend
    cur_user_pearson_datas = each_user_pearson_data[user_id]['Pearson Data']
IndexError: list index out of range
INFO:werkzeug:127.0.0.1 - - [05/May/2021 02:33:47] "[35m[1mGET /555 HTTP/1.1[0m" 500 -
ERROR:app:Exception on /555 [GET]
Traceback (most recent call last):
  File "C:\venvs\smartOrderService\lib\site-packages\flask\app.py", line 2447, in wsgi_app
    response = self.full_dispatch_request()
  File "C:\venvs\smartOrderService\lib\site-packages\flask\app.py", line 1952, in full_dispatch_request
    rv = self.handle_user_exception(e)
  File "C:\venvs\smartOrderService\lib\site-packages\flask_cors\extension.py", line 165, in wrapped_function
    return cors_after_request(app.make_response(f(*args, **kwargs)))
  File "C:\venvs\smartOrderService\lib\site-packages\flask\app.py", line 1821, in handle_user_exception
    reraise(exc_type, exc_value, tb)
  File "C:\venvs\smartOrderService\lib\site-packages\flask\_compat.py", line 39, in reraise
    raise value
  File "C:\venvs\smartOrderService\lib\site-packages\flask\app.py", line 1950, in full_dispatch_request
    rv = self.dispatch_request()
  File "C:\venvs\smartOrderService\lib\site-packages\flask\app.py", line 1936, in dispatch_request
    return self.view_functions[rule.endpoint](**req.view_args)
  File "C:/flaskProjects/smartOrderService_recommendingMenu/app.py", line 57, in recommend
    result = compute_recommending_menu.user_recommend(user_id, each_menu_recommend_data, each_user_pearson_data, conn)
  File "C:\flaskProjects\smartOrderService_recommendingMenu\compute_recommending_menu.py", line 93, in user_recommend
    cur_user_pearson_datas = each_user_pearson_data[user_id]['Pearson Data']
IndexError: list index out of range
INFO:werkzeug:127.0.0.1 - - [05/May/2021 02:33:48] "[35m[1mGET /555 HTTP/1.1[0m" 500 -
ERROR:app:Exception on /555 [GET]
Traceback (most recent call last):
  File "C:\venvs\smartOrderService\lib\site-packages\flask\app.py", line 2447, in wsgi_app
    response = self.full_dispatch_request()
  File "C:\venvs\smartOrderService\lib\site-packages\flask\app.py", line 1952, in full_dispatch_request
    rv = self.handle_user_exception(e)
  File "C:\venvs\smartOrderService\lib\site-packages\flask_cors\extension.py", line 165, in wrapped_function
    return cors_after_request(app.make_response(f(*args, **kwargs)))
  File "C:\venvs\smartOrderService\lib\site-packages\flask\app.py", line 1821, in handle_user_exception
    reraise(exc_type, exc_value, tb)
  File "C:\venvs\smartOrderService\lib\site-packages\flask\_compat.py", line 39, in reraise
    raise value
  File "C:\venvs\smartOrderService\lib\site-packages\flask\app.py", line 1950, in full_dispatch_request
    rv = self.dispatch_request()
  File "C:\venvs\smartOrderService\lib\site-packages\flask\app.py", line 1936, in dispatch_request
    return self.view_functions[rule.endpoint](**req.view_args)
  File "C:/flaskProjects/smartOrderService_recommendingMenu/app.py", line 57, in recommend
    result = compute_recommending_menu.user_recommend(user_id, each_menu_recommend_data, each_user_pearson_data, conn)
  File "C:\flaskProjects\smartOrderService_recommendingMenu\compute_recommending_menu.py", line 93, in user_recommend
    cur_user_pearson_datas = each_user_pearson_data[user_id]['Pearson Data']
IndexError: list index out of range
INFO:werkzeug:127.0.0.1 - - [05/May/2021 02:33:48] "[35m[1mGET /555 HTTP/1.1[0m" 500 -
ERROR:app:Exception on /555 [GET]
Traceback (most recent call last):
  File "C:\venvs\smartOrderService\lib\site-packages\flask\app.py", line 2447, in wsgi_app
    response = self.full_dispatch_request()
  File "C:\venvs\smartOrderService\lib\site-packages\flask\app.py", line 1952, in full_dispatch_request
    rv = self.handle_user_exception(e)
  File "C:\venvs\smartOrderService\lib\site-packages\flask_cors\extension.py", line 165, in wrapped_function
    return cors_after_request(app.make_response(f(*args, **kwargs)))
  File "C:\venvs\smartOrderService\lib\site-packages\flask\app.py", line 1821, in handle_user_exception
    reraise(exc_type, exc_value, tb)
  File "C:\venvs\smartOrderService\lib\site-packages\flask\_compat.py", line 39, in reraise
    raise value
  File "C:\venvs\smartOrderService\lib\site-packages\flask\app.py", line 1950, in full_dispatch_request
    rv = self.dispatch_request()
  File "C:\venvs\smartOrderService\lib\site-packages\flask\app.py", line 1936, in dispatch_request
    return self.view_functions[rule.endpoint](**req.view_args)
  File "C:/flaskProjects/smartOrderService_recommendingMenu/app.py", line 57, in recommend
    result = compute_recommending_menu.user_recommend(user_id, each_menu_recommend_data, each_user_pearson_data, conn)
  File "C:\flaskProjects\smartOrderService_recommendingMenu\compute_recommending_menu.py", line 93, in user_recommend
    cur_user_pearson_datas = each_user_pearson_data[user_id]['Pearson Data']
IndexError: list index out of range
INFO:werkzeug:127.0.0.1 - - [05/May/2021 02:33:49] "[35m[1mGET /555 HTTP/1.1[0m" 500 -
INFO:werkzeug: * Running on http://0.0.0.0:5000/ (Press CTRL+C to quit)
ERROR:app:Exception on /55 [GET]
Traceback (most recent call last):
  File "C:\venvs\smartOrderService\lib\site-packages\flask\app.py", line 2447, in wsgi_app
    response = self.full_dispatch_request()
  File "C:\venvs\smartOrderService\lib\site-packages\flask\app.py", line 1952, in full_dispatch_request
    rv = self.handle_user_exception(e)
  File "C:\venvs\smartOrderService\lib\site-packages\flask_cors\extension.py", line 165, in wrapped_function
    return cors_after_request(app.make_response(f(*args, **kwargs)))
  File "C:\venvs\smartOrderService\lib\site-packages\flask\app.py", line 1821, in handle_user_exception
    reraise(exc_type, exc_value, tb)
  File "C:\venvs\smartOrderService\lib\site-packages\flask\_compat.py", line 39, in reraise
    raise value
  File "C:\venvs\smartOrderService\lib\site-packages\flask\app.py", line 1950, in full_dispatch_request
    rv = self.dispatch_request()
  File "C:\venvs\smartOrderService\lib\site-packages\flask\app.py", line 1936, in dispatch_request
    return self.view_functions[rule.endpoint](**req.view_args)
  File "C:/flaskProjects/smartOrderService_recommendingMenu/app.py", line 57, in recommend
    result = compute_recommending_menu.user_recommend(user_id, each_menu_recommend_data, each_user_pearson_data, conn)
  File "C:\flaskProjects\smartOrderService_recommendingMenu\compute_recommending_menu.py", line 93, in user_recommend
    cur_user_pearson_datas = each_user_pearson_data[user_id-1]['Pearson Data']
IndexError: list index out of range
INFO:werkzeug:127.0.0.1 - - [05/May/2021 02:35:09] "[35m[1mGET /55 HTTP/1.1[0m" 500 -
ERROR:app:Exception on /1 [GET]
Traceback (most recent call last):
  File "C:\venvs\smartOrderService\lib\site-packages\flask\app.py", line 2447, in wsgi_app
    response = self.full_dispatch_request()
  File "C:\venvs\smartOrderService\lib\site-packages\flask\app.py", line 1952, in full_dispatch_request
    rv = self.handle_user_exception(e)
  File "C:\venvs\smartOrderService\lib\site-packages\flask_cors\extension.py", line 165, in wrapped_function
    return cors_after_request(app.make_response(f(*args, **kwargs)))
  File "C:\venvs\smartOrderService\lib\site-packages\flask\app.py", line 1821, in handle_user_exception
    reraise(exc_type, exc_value, tb)
  File "C:\venvs\smartOrderService\lib\site-packages\flask\_compat.py", line 39, in reraise
    raise value
  File "C:\venvs\smartOrderService\lib\site-packages\flask\app.py", line 1950, in full_dispatch_request
    rv = self.dispatch_request()
  File "C:\venvs\smartOrderService\lib\site-packages\flask\app.py", line 1936, in dispatch_request
    return self.view_functions[rule.endpoint](**req.view_args)
  File "C:/flaskProjects/smartOrderService_recommendingMenu/app.py", line 57, in recommend
    result = compute_recommending_menu.user_recommend(user_id, each_menu_recommend_data, each_user_pearson_data, conn)
  File "C:\flaskProjects\smartOrderService_recommendingMenu\compute_recommending_menu.py", line 93, in user_recommend
    cur_user_pearson_datas = each_user_pearson_data[user_id-1]['Pearson Data']
IndexError: list index out of range
INFO:werkzeug:127.0.0.1 - - [05/May/2021 02:35:13] "[35m[1mGET /1 HTTP/1.1[0m" 500 -
ERROR:app:Exception on /1 [GET]
Traceback (most recent call last):
  File "C:\venvs\smartOrderService\lib\site-packages\flask\app.py", line 2447, in wsgi_app
    response = self.full_dispatch_request()
  File "C:\venvs\smartOrderService\lib\site-packages\flask\app.py", line 1952, in full_dispatch_request
    rv = self.handle_user_exception(e)
  File "C:\venvs\smartOrderService\lib\site-packages\flask_cors\extension.py", line 165, in wrapped_function
    return cors_after_request(app.make_response(f(*args, **kwargs)))
  File "C:\venvs\smartOrderService\lib\site-packages\flask\app.py", line 1821, in handle_user_exception
    reraise(exc_type, exc_value, tb)
  File "C:\venvs\smartOrderService\lib\site-packages\flask\_compat.py", line 39, in reraise
    raise value
  File "C:\venvs\smartOrderService\lib\site-packages\flask\app.py", line 1950, in full_dispatch_request
    rv = self.dispatch_request()
  File "C:\venvs\smartOrderService\lib\site-packages\flask\app.py", line 1936, in dispatch_request
    return self.view_functions[rule.endpoint](**req.view_args)
  File "C:/flaskProjects/smartOrderService_recommendingMenu/app.py", line 57, in recommend
    result = compute_recommending_menu.user_recommend(user_id, each_menu_recommend_data, each_user_pearson_data, conn)
  File "C:\flaskProjects\smartOrderService_recommendingMenu\compute_recommending_menu.py", line 93, in user_recommend
    cur_user_pearson_datas = each_user_pearson_data[user_id-1]['Pearson Data']
IndexError: list index out of range
INFO:werkzeug:127.0.0.1 - - [05/May/2021 02:35:15] "[35m[1mGET /1 HTTP/1.1[0m" 500 -
ERROR:app:Exception on /1 [GET]
Traceback (most recent call last):
  File "C:\venvs\smartOrderService\lib\site-packages\flask\app.py", line 2447, in wsgi_app
    response = self.full_dispatch_request()
  File "C:\venvs\smartOrderService\lib\site-packages\flask\app.py", line 1952, in full_dispatch_request
    rv = self.handle_user_exception(e)
  File "C:\venvs\smartOrderService\lib\site-packages\flask_cors\extension.py", line 165, in wrapped_function
    return cors_after_request(app.make_response(f(*args, **kwargs)))
  File "C:\venvs\smartOrderService\lib\site-packages\flask\app.py", line 1821, in handle_user_exception
    reraise(exc_type, exc_value, tb)
  File "C:\venvs\smartOrderService\lib\site-packages\flask\_compat.py", line 39, in reraise
    raise value
  File "C:\venvs\smartOrderService\lib\site-packages\flask\app.py", line 1950, in full_dispatch_request
    rv = self.dispatch_request()
  File "C:\venvs\smartOrderService\lib\site-packages\flask\app.py", line 1936, in dispatch_request
    return self.view_functions[rule.endpoint](**req.view_args)
  File "C:/flaskProjects/smartOrderService_recommendingMenu/app.py", line 57, in recommend
    result = compute_recommending_menu.user_recommend(user_id, each_menu_recommend_data, each_user_pearson_data, conn)
  File "C:\flaskProjects\smartOrderService_recommendingMenu\compute_recommending_menu.py", line 93, in user_recommend
    cur_user_pearson_datas = each_user_pearson_data[user_id-1]['Pearson Data']
IndexError: list index out of range
INFO:werkzeug:127.0.0.1 - - [05/May/2021 02:35:15] "[35m[1mGET /1 HTTP/1.1[0m" 500 -
ERROR:app:Exception on /1 [GET]
Traceback (most recent call last):
  File "C:\venvs\smartOrderService\lib\site-packages\flask\app.py", line 2447, in wsgi_app
    response = self.full_dispatch_request()
  File "C:\venvs\smartOrderService\lib\site-packages\flask\app.py", line 1952, in full_dispatch_request
    rv = self.handle_user_exception(e)
  File "C:\venvs\smartOrderService\lib\site-packages\flask_cors\extension.py", line 165, in wrapped_function
    return cors_after_request(app.make_response(f(*args, **kwargs)))
  File "C:\venvs\smartOrderService\lib\site-packages\flask\app.py", line 1821, in handle_user_exception
    reraise(exc_type, exc_value, tb)
  File "C:\venvs\smartOrderService\lib\site-packages\flask\_compat.py", line 39, in reraise
    raise value
  File "C:\venvs\smartOrderService\lib\site-packages\flask\app.py", line 1950, in full_dispatch_request
    rv = self.dispatch_request()
  File "C:\venvs\smartOrderService\lib\site-packages\flask\app.py", line 1936, in dispatch_request
    return self.view_functions[rule.endpoint](**req.view_args)
  File "C:/flaskProjects/smartOrderService_recommendingMenu/app.py", line 57, in recommend
    result = compute_recommending_menu.user_recommend(user_id, each_menu_recommend_data, each_user_pearson_data, conn)
  File "C:\flaskProjects\smartOrderService_recommendingMenu\compute_recommending_menu.py", line 93, in user_recommend
    cur_user_pearson_datas = each_user_pearson_data[user_id-1]['Pearson Data']
IndexError: list index out of range
INFO:werkzeug:127.0.0.1 - - [05/May/2021 02:35:15] "[35m[1mGET /1 HTTP/1.1[0m" 500 -
ERROR:app:Exception on /1 [GET]
Traceback (most recent call last):
  File "C:\venvs\smartOrderService\lib\site-packages\flask\app.py", line 2447, in wsgi_app
    response = self.full_dispatch_request()
  File "C:\venvs\smartOrderService\lib\site-packages\flask\app.py", line 1952, in full_dispatch_request
    rv = self.handle_user_exception(e)
  File "C:\venvs\smartOrderService\lib\site-packages\flask_cors\extension.py", line 165, in wrapped_function
    return cors_after_request(app.make_response(f(*args, **kwargs)))
  File "C:\venvs\smartOrderService\lib\site-packages\flask\app.py", line 1821, in handle_user_exception
    reraise(exc_type, exc_value, tb)
  File "C:\venvs\smartOrderService\lib\site-packages\flask\_compat.py", line 39, in reraise
    raise value
  File "C:\venvs\smartOrderService\lib\site-packages\flask\app.py", line 1950, in full_dispatch_request
    rv = self.dispatch_request()
  File "C:\venvs\smartOrderService\lib\site-packages\flask\app.py", line 1936, in dispatch_request
    return self.view_functions[rule.endpoint](**req.view_args)
  File "C:/flaskProjects/smartOrderService_recommendingMenu/app.py", line 57, in recommend
    result = compute_recommending_menu.user_recommend(user_id, each_menu_recommend_data, each_user_pearson_data, conn)
  File "C:\flaskProjects\smartOrderService_recommendingMenu\compute_recommending_menu.py", line 93, in user_recommend
    cur_user_pearson_datas = each_user_pearson_data[user_id-1]['Pearson Data']
IndexError: list index out of range
INFO:werkzeug:127.0.0.1 - - [05/May/2021 02:35:15] "[35m[1mGET /1 HTTP/1.1[0m" 500 -
ERROR:app:Exception on /556 [GET]
Traceback (most recent call last):
  File "C:\venvs\smartOrderService\lib\site-packages\flask\app.py", line 2447, in wsgi_app
    response = self.full_dispatch_request()
  File "C:\venvs\smartOrderService\lib\site-packages\flask\app.py", line 1952, in full_dispatch_request
    rv = self.handle_user_exception(e)
  File "C:\venvs\smartOrderService\lib\site-packages\flask_cors\extension.py", line 165, in wrapped_function
    return cors_after_request(app.make_response(f(*args, **kwargs)))
  File "C:\venvs\smartOrderService\lib\site-packages\flask\app.py", line 1821, in handle_user_exception
    reraise(exc_type, exc_value, tb)
  File "C:\venvs\smartOrderService\lib\site-packages\flask\_compat.py", line 39, in reraise
    raise value
  File "C:\venvs\smartOrderService\lib\site-packages\flask\app.py", line 1950, in full_dispatch_request
    rv = self.dispatch_request()
  File "C:\venvs\smartOrderService\lib\site-packages\flask\app.py", line 1936, in dispatch_request
    return self.view_functions[rule.endpoint](**req.view_args)
  File "C:/flaskProjects/smartOrderService_recommendingMenu/app.py", line 57, in recommend
    result = compute_recommending_menu.user_recommend(user_id, each_menu_recommend_data, each_user_pearson_data, conn)
  File "C:\flaskProjects\smartOrderService_recommendingMenu\compute_recommending_menu.py", line 93, in user_recommend
    cur_user_pearson_datas = each_user_pearson_data[user_id-1]['Pearson Data']
IndexError: list index out of range
INFO:werkzeug:127.0.0.1 - - [05/May/2021 02:35:20] "[35m[1mGET /556 HTTP/1.1[0m" 500 -
INFO:werkzeug: * Running on http://0.0.0.0:5000/ (Press CTRL+C to quit)
ERROR:app:Exception on /556 [GET]
Traceback (most recent call last):
  File "C:\venvs\smartOrderService\lib\site-packages\flask\app.py", line 2447, in wsgi_app
    response = self.full_dispatch_request()
  File "C:\venvs\smartOrderService\lib\site-packages\flask\app.py", line 1952, in full_dispatch_request
    rv = self.handle_user_exception(e)
  File "C:\venvs\smartOrderService\lib\site-packages\flask_cors\extension.py", line 165, in wrapped_function
    return cors_after_request(app.make_response(f(*args, **kwargs)))
  File "C:\venvs\smartOrderService\lib\site-packages\flask\app.py", line 1821, in handle_user_exception
    reraise(exc_type, exc_value, tb)
  File "C:\venvs\smartOrderService\lib\site-packages\flask\_compat.py", line 39, in reraise
    raise value
  File "C:\venvs\smartOrderService\lib\site-packages\flask\app.py", line 1950, in full_dispatch_request
    rv = self.dispatch_request()
  File "C:\venvs\smartOrderService\lib\site-packages\flask\app.py", line 1936, in dispatch_request
    return self.view_functions[rule.endpoint](**req.view_args)
  File "C:/flaskProjects/smartOrderService_recommendingMenu/app.py", line 57, in recommend
    result = compute_recommending_menu.user_recommend(user_id, each_menu_recommend_data, each_user_pearson_data, conn)
  File "C:\flaskProjects\smartOrderService_recommendingMenu\compute_recommending_menu.py", line 93, in user_recommend
    result_list = []
IndexError: list index out of range
INFO:werkzeug:127.0.0.1 - - [05/May/2021 03:03:55] "[35m[1mGET /556 HTTP/1.1[0m" 500 -
ERROR:app:Exception on /556 [GET]
Traceback (most recent call last):
  File "C:\venvs\smartOrderService\lib\site-packages\flask\app.py", line 2447, in wsgi_app
    response = self.full_dispatch_request()
  File "C:\venvs\smartOrderService\lib\site-packages\flask\app.py", line 1952, in full_dispatch_request
    rv = self.handle_user_exception(e)
  File "C:\venvs\smartOrderService\lib\site-packages\flask_cors\extension.py", line 165, in wrapped_function
    return cors_after_request(app.make_response(f(*args, **kwargs)))
  File "C:\venvs\smartOrderService\lib\site-packages\flask\app.py", line 1821, in handle_user_exception
    reraise(exc_type, exc_value, tb)
  File "C:\venvs\smartOrderService\lib\site-packages\flask\_compat.py", line 39, in reraise
    raise value
  File "C:\venvs\smartOrderService\lib\site-packages\flask\app.py", line 1950, in full_dispatch_request
    rv = self.dispatch_request()
  File "C:\venvs\smartOrderService\lib\site-packages\flask\app.py", line 1936, in dispatch_request
    return self.view_functions[rule.endpoint](**req.view_args)
  File "C:/flaskProjects/smartOrderService_recommendingMenu/app.py", line 57, in recommend
    result = compute_recommending_menu.user_recommend(user_id, each_menu_recommend_data, each_user_pearson_data, conn)
  File "C:\flaskProjects\smartOrderService_recommendingMenu\compute_recommending_menu.py", line 93, in user_recommend
    result_list = []
IndexError: list index out of range
INFO:werkzeug:127.0.0.1 - - [05/May/2021 03:03:57] "[35m[1mGET /556 HTTP/1.1[0m" 500 -
ERROR:app:Exception on /556 [GET]
Traceback (most recent call last):
  File "C:\venvs\smartOrderService\lib\site-packages\flask\app.py", line 2447, in wsgi_app
    response = self.full_dispatch_request()
  File "C:\venvs\smartOrderService\lib\site-packages\flask\app.py", line 1952, in full_dispatch_request
    rv = self.handle_user_exception(e)
  File "C:\venvs\smartOrderService\lib\site-packages\flask_cors\extension.py", line 165, in wrapped_function
    return cors_after_request(app.make_response(f(*args, **kwargs)))
  File "C:\venvs\smartOrderService\lib\site-packages\flask\app.py", line 1821, in handle_user_exception
    reraise(exc_type, exc_value, tb)
  File "C:\venvs\smartOrderService\lib\site-packages\flask\_compat.py", line 39, in reraise
    raise value
  File "C:\venvs\smartOrderService\lib\site-packages\flask\app.py", line 1950, in full_dispatch_request
    rv = self.dispatch_request()
  File "C:\venvs\smartOrderService\lib\site-packages\flask\app.py", line 1936, in dispatch_request
    return self.view_functions[rule.endpoint](**req.view_args)
  File "C:/flaskProjects/smartOrderService_recommendingMenu/app.py", line 57, in recommend
    result = compute_recommending_menu.user_recommend(user_id, each_menu_recommend_data, each_user_pearson_data, conn)
  File "C:\flaskProjects\smartOrderService_recommendingMenu\compute_recommending_menu.py", line 93, in user_recommend
    result_list = []
IndexError: list index out of range
INFO:werkzeug:127.0.0.1 - - [05/May/2021 03:04:00] "[35m[1mGET /556 HTTP/1.1[0m" 500 -
ERROR:app:Exception on /556 [GET]
Traceback (most recent call last):
  File "C:\venvs\smartOrderService\lib\site-packages\flask\app.py", line 2447, in wsgi_app
    response = self.full_dispatch_request()
  File "C:\venvs\smartOrderService\lib\site-packages\flask\app.py", line 1952, in full_dispatch_request
    rv = self.handle_user_exception(e)
  File "C:\venvs\smartOrderService\lib\site-packages\flask_cors\extension.py", line 165, in wrapped_function
    return cors_after_request(app.make_response(f(*args, **kwargs)))
  File "C:\venvs\smartOrderService\lib\site-packages\flask\app.py", line 1821, in handle_user_exception
    reraise(exc_type, exc_value, tb)
  File "C:\venvs\smartOrderService\lib\site-packages\flask\_compat.py", line 39, in reraise
    raise value
  File "C:\venvs\smartOrderService\lib\site-packages\flask\app.py", line 1950, in full_dispatch_request
    rv = self.dispatch_request()
  File "C:\venvs\smartOrderService\lib\site-packages\flask\app.py", line 1936, in dispatch_request
    return self.view_functions[rule.endpoint](**req.view_args)
  File "C:/flaskProjects/smartOrderService_recommendingMenu/app.py", line 57, in recommend
    result = compute_recommending_menu.user_recommend(user_id, each_menu_recommend_data, each_user_pearson_data, conn)
  File "C:\flaskProjects\smartOrderService_recommendingMenu\compute_recommending_menu.py", line 93, in user_recommend
    result_list = []
IndexError: list index out of range
INFO:werkzeug:127.0.0.1 - - [05/May/2021 03:04:00] "[35m[1mGET /556 HTTP/1.1[0m" 500 -
ERROR:app:Exception on /556 [GET]
Traceback (most recent call last):
  File "C:\venvs\smartOrderService\lib\site-packages\flask\app.py", line 2447, in wsgi_app
    response = self.full_dispatch_request()
  File "C:\venvs\smartOrderService\lib\site-packages\flask\app.py", line 1952, in full_dispatch_request
    rv = self.handle_user_exception(e)
  File "C:\venvs\smartOrderService\lib\site-packages\flask_cors\extension.py", line 165, in wrapped_function
    return cors_after_request(app.make_response(f(*args, **kwargs)))
  File "C:\venvs\smartOrderService\lib\site-packages\flask\app.py", line 1821, in handle_user_exception
    reraise(exc_type, exc_value, tb)
  File "C:\venvs\smartOrderService\lib\site-packages\flask\_compat.py", line 39, in reraise
    raise value
  File "C:\venvs\smartOrderService\lib\site-packages\flask\app.py", line 1950, in full_dispatch_request
    rv = self.dispatch_request()
  File "C:\venvs\smartOrderService\lib\site-packages\flask\app.py", line 1936, in dispatch_request
    return self.view_functions[rule.endpoint](**req.view_args)
  File "C:/flaskProjects/smartOrderService_recommendingMenu/app.py", line 57, in recommend
    result = compute_recommending_menu.user_recommend(user_id, each_menu_recommend_data, each_user_pearson_data, conn)
  File "C:\flaskProjects\smartOrderService_recommendingMenu\compute_recommending_menu.py", line 93, in user_recommend
    result_list = []
IndexError: list index out of range
INFO:werkzeug:127.0.0.1 - - [05/May/2021 03:04:01] "[35m[1mGET /556 HTTP/1.1[0m" 500 -
ERROR:app:Exception on /556 [GET]
Traceback (most recent call last):
  File "C:\venvs\smartOrderService\lib\site-packages\flask\app.py", line 2447, in wsgi_app
    response = self.full_dispatch_request()
  File "C:\venvs\smartOrderService\lib\site-packages\flask\app.py", line 1952, in full_dispatch_request
    rv = self.handle_user_exception(e)
  File "C:\venvs\smartOrderService\lib\site-packages\flask_cors\extension.py", line 165, in wrapped_function
    return cors_after_request(app.make_response(f(*args, **kwargs)))
  File "C:\venvs\smartOrderService\lib\site-packages\flask\app.py", line 1821, in handle_user_exception
    reraise(exc_type, exc_value, tb)
  File "C:\venvs\smartOrderService\lib\site-packages\flask\_compat.py", line 39, in reraise
    raise value
  File "C:\venvs\smartOrderService\lib\site-packages\flask\app.py", line 1950, in full_dispatch_request
    rv = self.dispatch_request()
  File "C:\venvs\smartOrderService\lib\site-packages\flask\app.py", line 1936, in dispatch_request
    return self.view_functions[rule.endpoint](**req.view_args)
  File "C:/flaskProjects/smartOrderService_recommendingMenu/app.py", line 57, in recommend
    result = compute_recommending_menu.user_recommend(user_id, each_menu_recommend_data, each_user_pearson_data, conn)
  File "C:\flaskProjects\smartOrderService_recommendingMenu\compute_recommending_menu.py", line 93, in user_recommend
    result_list = []
IndexError: list index out of range
INFO:werkzeug:127.0.0.1 - - [05/May/2021 03:04:01] "[35m[1mGET /556 HTTP/1.1[0m" 500 -
ERROR:app:Exception on /556 [GET]
Traceback (most recent call last):
  File "C:\venvs\smartOrderService\lib\site-packages\flask\app.py", line 2447, in wsgi_app
    response = self.full_dispatch_request()
  File "C:\venvs\smartOrderService\lib\site-packages\flask\app.py", line 1952, in full_dispatch_request
    rv = self.handle_user_exception(e)
  File "C:\venvs\smartOrderService\lib\site-packages\flask_cors\extension.py", line 165, in wrapped_function
    return cors_after_request(app.make_response(f(*args, **kwargs)))
  File "C:\venvs\smartOrderService\lib\site-packages\flask\app.py", line 1821, in handle_user_exception
    reraise(exc_type, exc_value, tb)
  File "C:\venvs\smartOrderService\lib\site-packages\flask\_compat.py", line 39, in reraise
    raise value
  File "C:\venvs\smartOrderService\lib\site-packages\flask\app.py", line 1950, in full_dispatch_request
    rv = self.dispatch_request()
  File "C:\venvs\smartOrderService\lib\site-packages\flask\app.py", line 1936, in dispatch_request
    return self.view_functions[rule.endpoint](**req.view_args)
  File "C:/flaskProjects/smartOrderService_recommendingMenu/app.py", line 57, in recommend
    result = compute_recommending_menu.user_recommend(user_id, each_menu_recommend_data, each_user_pearson_data, conn)
  File "C:\flaskProjects\smartOrderService_recommendingMenu\compute_recommending_menu.py", line 93, in user_recommend
    result_list = []
IndexError: list index out of range
INFO:werkzeug:127.0.0.1 - - [05/May/2021 03:04:01] "[35m[1mGET /556 HTTP/1.1[0m" 500 -
ERROR:app:Exception on /1 [GET]
Traceback (most recent call last):
  File "C:\venvs\smartOrderService\lib\site-packages\flask\app.py", line 2447, in wsgi_app
    response = self.full_dispatch_request()
  File "C:\venvs\smartOrderService\lib\site-packages\flask\app.py", line 1952, in full_dispatch_request
    rv = self.handle_user_exception(e)
  File "C:\venvs\smartOrderService\lib\site-packages\flask_cors\extension.py", line 165, in wrapped_function
    return cors_after_request(app.make_response(f(*args, **kwargs)))
  File "C:\venvs\smartOrderService\lib\site-packages\flask\app.py", line 1821, in handle_user_exception
    reraise(exc_type, exc_value, tb)
  File "C:\venvs\smartOrderService\lib\site-packages\flask\_compat.py", line 39, in reraise
    raise value
  File "C:\venvs\smartOrderService\lib\site-packages\flask\app.py", line 1950, in full_dispatch_request
    rv = self.dispatch_request()
  File "C:\venvs\smartOrderService\lib\site-packages\flask\app.py", line 1936, in dispatch_request
    return self.view_functions[rule.endpoint](**req.view_args)
  File "C:/flaskProjects/smartOrderService_recommendingMenu/app.py", line 57, in recommend
    result = compute_recommending_menu.user_recommend(user_id, each_menu_recommend_data, each_user_pearson_data, conn)
  File "C:\flaskProjects\smartOrderService_recommendingMenu\compute_recommending_menu.py", line 93, in user_recommend
    result_list = []
IndexError: list index out of range
INFO:werkzeug:127.0.0.1 - - [05/May/2021 03:04:25] "[35m[1mGET /1 HTTP/1.1[0m" 500 -
ERROR:app:Exception on /555 [GET]
Traceback (most recent call last):
  File "C:\venvs\smartOrderService\lib\site-packages\flask\app.py", line 2447, in wsgi_app
    response = self.full_dispatch_request()
  File "C:\venvs\smartOrderService\lib\site-packages\flask\app.py", line 1952, in full_dispatch_request
    rv = self.handle_user_exception(e)
  File "C:\venvs\smartOrderService\lib\site-packages\flask_cors\extension.py", line 165, in wrapped_function
    return cors_after_request(app.make_response(f(*args, **kwargs)))
  File "C:\venvs\smartOrderService\lib\site-packages\flask\app.py", line 1821, in handle_user_exception
    reraise(exc_type, exc_value, tb)
  File "C:\venvs\smartOrderService\lib\site-packages\flask\_compat.py", line 39, in reraise
    raise value
  File "C:\venvs\smartOrderService\lib\site-packages\flask\app.py", line 1950, in full_dispatch_request
    rv = self.dispatch_request()
  File "C:\venvs\smartOrderService\lib\site-packages\flask\app.py", line 1936, in dispatch_request
    return self.view_functions[rule.endpoint](**req.view_args)
  File "C:/flaskProjects/smartOrderService_recommendingMenu/app.py", line 57, in recommend
    result = compute_recommending_menu.user_recommend(user_id, each_menu_recommend_data, each_user_pearson_data, conn)
  File "C:\flaskProjects\smartOrderService_recommendingMenu\compute_recommending_menu.py", line 93, in user_recommend
    result_list = []
IndexError: list index out of range
INFO:werkzeug:127.0.0.1 - - [05/May/2021 03:04:29] "[35m[1mGET /555 HTTP/1.1[0m" 500 -
INFO:werkzeug: * Running on http://0.0.0.0:5000/ (Press CTRL+C to quit)
INFO:werkzeug:127.0.0.1 - - [05/May/2021 03:04:40] "[37mGET / HTTP/1.1[0m" 200 -
ERROR:app:Exception on /555 [GET]
Traceback (most recent call last):
  File "C:\venvs\smartOrderService\lib\site-packages\flask\app.py", line 2447, in wsgi_app
    response = self.full_dispatch_request()
  File "C:\venvs\smartOrderService\lib\site-packages\flask\app.py", line 1952, in full_dispatch_request
    rv = self.handle_user_exception(e)
  File "C:\venvs\smartOrderService\lib\site-packages\flask_cors\extension.py", line 165, in wrapped_function
    return cors_after_request(app.make_response(f(*args, **kwargs)))
  File "C:\venvs\smartOrderService\lib\site-packages\flask\app.py", line 1821, in handle_user_exception
    reraise(exc_type, exc_value, tb)
  File "C:\venvs\smartOrderService\lib\site-packages\flask\_compat.py", line 39, in reraise
    raise value
  File "C:\venvs\smartOrderService\lib\site-packages\flask\app.py", line 1950, in full_dispatch_request
    rv = self.dispatch_request()
  File "C:\venvs\smartOrderService\lib\site-packages\flask\app.py", line 1936, in dispatch_request
    return self.view_functions[rule.endpoint](**req.view_args)
  File "C:/flaskProjects/smartOrderService_recommendingMenu/app.py", line 57, in recommend
    result = compute_recommending_menu.user_recommend(user_id, each_menu_recommend_data, each_user_pearson_data, conn)
  File "C:\flaskProjects\smartOrderService_recommendingMenu\compute_recommending_menu.py", line 93, in user_recommend
    result_list = []
IndexError: list index out of range
INFO:werkzeug:127.0.0.1 - - [05/May/2021 03:04:43] "[35m[1mGET /555 HTTP/1.1[0m" 500 -
ERROR:app:Exception on /555 [GET]
Traceback (most recent call last):
  File "C:\venvs\smartOrderService\lib\site-packages\flask\app.py", line 2447, in wsgi_app
    response = self.full_dispatch_request()
  File "C:\venvs\smartOrderService\lib\site-packages\flask\app.py", line 1952, in full_dispatch_request
    rv = self.handle_user_exception(e)
  File "C:\venvs\smartOrderService\lib\site-packages\flask_cors\extension.py", line 165, in wrapped_function
    return cors_after_request(app.make_response(f(*args, **kwargs)))
  File "C:\venvs\smartOrderService\lib\site-packages\flask\app.py", line 1821, in handle_user_exception
    reraise(exc_type, exc_value, tb)
  File "C:\venvs\smartOrderService\lib\site-packages\flask\_compat.py", line 39, in reraise
    raise value
  File "C:\venvs\smartOrderService\lib\site-packages\flask\app.py", line 1950, in full_dispatch_request
    rv = self.dispatch_request()
  File "C:\venvs\smartOrderService\lib\site-packages\flask\app.py", line 1936, in dispatch_request
    return self.view_functions[rule.endpoint](**req.view_args)
  File "C:/flaskProjects/smartOrderService_recommendingMenu/app.py", line 57, in recommend
    result = compute_recommending_menu.user_recommend(user_id, each_menu_recommend_data, each_user_pearson_data, conn)
  File "C:\flaskProjects\smartOrderService_recommendingMenu\compute_recommending_menu.py", line 93, in user_recommend
    result_list = []
IndexError: list index out of range
INFO:werkzeug:127.0.0.1 - - [05/May/2021 03:06:55] "[35m[1mGET /555 HTTP/1.1[0m" 500 -
ERROR:app:Exception on /555 [GET]
Traceback (most recent call last):
  File "C:\venvs\smartOrderService\lib\site-packages\flask\app.py", line 2447, in wsgi_app
    response = self.full_dispatch_request()
  File "C:\venvs\smartOrderService\lib\site-packages\flask\app.py", line 1952, in full_dispatch_request
    rv = self.handle_user_exception(e)
  File "C:\venvs\smartOrderService\lib\site-packages\flask_cors\extension.py", line 165, in wrapped_function
    return cors_after_request(app.make_response(f(*args, **kwargs)))
  File "C:\venvs\smartOrderService\lib\site-packages\flask\app.py", line 1821, in handle_user_exception
    reraise(exc_type, exc_value, tb)
  File "C:\venvs\smartOrderService\lib\site-packages\flask\_compat.py", line 39, in reraise
    raise value
  File "C:\venvs\smartOrderService\lib\site-packages\flask\app.py", line 1950, in full_dispatch_request
    rv = self.dispatch_request()
  File "C:\venvs\smartOrderService\lib\site-packages\flask\app.py", line 1936, in dispatch_request
    return self.view_functions[rule.endpoint](**req.view_args)
  File "C:/flaskProjects/smartOrderService_recommendingMenu/app.py", line 57, in recommend
    result = compute_recommending_menu.user_recommend(user_id, each_menu_recommend_data, each_user_pearson_data, conn)
  File "C:\flaskProjects\smartOrderService_recommendingMenu\compute_recommending_menu.py", line 93, in user_recommend
    result_list = []
IndexError: list index out of range
INFO:werkzeug:127.0.0.1 - - [05/May/2021 03:06:56] "[35m[1mGET /555 HTTP/1.1[0m" 500 -
INFO:werkzeug:127.0.0.1 - - [05/May/2021 03:06:59] "[37mGET / HTTP/1.1[0m" 200 -
INFO:werkzeug: * Running on http://0.0.0.0:5000/ (Press CTRL+C to quit)
INFO:werkzeug:127.0.0.1 - - [05/May/2021 03:10:30] "[37mGET / HTTP/1.1[0m" 200 -
ERROR:app:Exception on /555 [GET]
Traceback (most recent call last):
  File "C:\venvs\smartOrderService\lib\site-packages\flask\app.py", line 2447, in wsgi_app
    response = self.full_dispatch_request()
  File "C:\venvs\smartOrderService\lib\site-packages\flask\app.py", line 1952, in full_dispatch_request
    rv = self.handle_user_exception(e)
  File "C:\venvs\smartOrderService\lib\site-packages\flask_cors\extension.py", line 165, in wrapped_function
    return cors_after_request(app.make_response(f(*args, **kwargs)))
  File "C:\venvs\smartOrderService\lib\site-packages\flask\app.py", line 1821, in handle_user_exception
    reraise(exc_type, exc_value, tb)
  File "C:\venvs\smartOrderService\lib\site-packages\flask\_compat.py", line 39, in reraise
    raise value
  File "C:\venvs\smartOrderService\lib\site-packages\flask\app.py", line 1950, in full_dispatch_request
    rv = self.dispatch_request()
  File "C:\venvs\smartOrderService\lib\site-packages\flask\app.py", line 1936, in dispatch_request
    return self.view_functions[rule.endpoint](**req.view_args)
  File "C:/flaskProjects/smartOrderService_recommendingMenu/app.py", line 57, in recommend
    result = compute_recommending_menu.user_recommend(user_id, each_menu_recommend_data, each_user_pearson_data, conn)
  File "C:\flaskProjects\smartOrderService_recommendingMenu\compute_recommending_menu.py", line 93, in user_recommend
    result_list = []
IndexError: list index out of range
INFO:werkzeug:127.0.0.1 - - [05/May/2021 03:10:33] "[35m[1mGET /555 HTTP/1.1[0m" 500 -
INFO:werkzeug:127.0.0.1 - - [05/May/2021 03:11:05] "[37mGET / HTTP/1.1[0m" 200 -
ERROR:app:Exception on /555 [GET]
Traceback (most recent call last):
  File "C:\venvs\smartOrderService\lib\site-packages\flask\app.py", line 2447, in wsgi_app
    response = self.full_dispatch_request()
  File "C:\venvs\smartOrderService\lib\site-packages\flask\app.py", line 1952, in full_dispatch_request
    rv = self.handle_user_exception(e)
  File "C:\venvs\smartOrderService\lib\site-packages\flask_cors\extension.py", line 165, in wrapped_function
    return cors_after_request(app.make_response(f(*args, **kwargs)))
  File "C:\venvs\smartOrderService\lib\site-packages\flask\app.py", line 1821, in handle_user_exception
    reraise(exc_type, exc_value, tb)
  File "C:\venvs\smartOrderService\lib\site-packages\flask\_compat.py", line 39, in reraise
    raise value
  File "C:\venvs\smartOrderService\lib\site-packages\flask\app.py", line 1950, in full_dispatch_request
    rv = self.dispatch_request()
  File "C:\venvs\smartOrderService\lib\site-packages\flask\app.py", line 1936, in dispatch_request
    return self.view_functions[rule.endpoint](**req.view_args)
  File "C:/flaskProjects/smartOrderService_recommendingMenu/app.py", line 57, in recommend
    result = compute_recommending_menu.user_recommend(user_id, each_menu_recommend_data, each_user_pearson_data, conn)
  File "C:\flaskProjects\smartOrderService_recommendingMenu\compute_recommending_menu.py", line 93, in user_recommend
    result_list = []
IndexError: list index out of range
INFO:werkzeug:127.0.0.1 - - [05/May/2021 03:11:08] "[35m[1mGET /555 HTTP/1.1[0m" 500 -
INFO:werkzeug: * Running on http://0.0.0.0:5000/ (Press CTRL+C to quit)
ERROR:app:Exception on /555 [GET]
Traceback (most recent call last):
  File "C:\venvs\smartOrderService\lib\site-packages\flask\app.py", line 2447, in wsgi_app
    response = self.full_dispatch_request()
  File "C:\venvs\smartOrderService\lib\site-packages\flask\app.py", line 1952, in full_dispatch_request
    rv = self.handle_user_exception(e)
  File "C:\venvs\smartOrderService\lib\site-packages\flask_cors\extension.py", line 165, in wrapped_function
    return cors_after_request(app.make_response(f(*args, **kwargs)))
  File "C:\venvs\smartOrderService\lib\site-packages\flask\app.py", line 1821, in handle_user_exception
    reraise(exc_type, exc_value, tb)
  File "C:\venvs\smartOrderService\lib\site-packages\flask\_compat.py", line 39, in reraise
    raise value
  File "C:\venvs\smartOrderService\lib\site-packages\flask\app.py", line 1950, in full_dispatch_request
    rv = self.dispatch_request()
  File "C:\venvs\smartOrderService\lib\site-packages\flask\app.py", line 1936, in dispatch_request
    return self.view_functions[rule.endpoint](**req.view_args)
  File "C:/flaskProjects/smartOrderService_recommendingMenu/app.py", line 57, in recommend
    result = compute_recommending_menu.user_recommend(user_id, each_menu_recommend_data, each_user_pearson_data, conn)
  File "C:\flaskProjects\smartOrderService_recommendingMenu\compute_recommending_menu.py", line 93, in user_recommend
    result_list = []
IndexError: list index out of range
INFO:werkzeug:127.0.0.1 - - [05/May/2021 03:12:14] "[35m[1mGET /555 HTTP/1.1[0m" 500 -
ERROR:app:Exception on /555 [GET]
Traceback (most recent call last):
  File "C:\venvs\smartOrderService\lib\site-packages\flask\app.py", line 2447, in wsgi_app
    response = self.full_dispatch_request()
  File "C:\venvs\smartOrderService\lib\site-packages\flask\app.py", line 1952, in full_dispatch_request
    rv = self.handle_user_exception(e)
  File "C:\venvs\smartOrderService\lib\site-packages\flask_cors\extension.py", line 165, in wrapped_function
    return cors_after_request(app.make_response(f(*args, **kwargs)))
  File "C:\venvs\smartOrderService\lib\site-packages\flask\app.py", line 1821, in handle_user_exception
    reraise(exc_type, exc_value, tb)
  File "C:\venvs\smartOrderService\lib\site-packages\flask\_compat.py", line 39, in reraise
    raise value
  File "C:\venvs\smartOrderService\lib\site-packages\flask\app.py", line 1950, in full_dispatch_request
    rv = self.dispatch_request()
  File "C:\venvs\smartOrderService\lib\site-packages\flask\app.py", line 1936, in dispatch_request
    return self.view_functions[rule.endpoint](**req.view_args)
  File "C:/flaskProjects/smartOrderService_recommendingMenu/app.py", line 57, in recommend
    result = compute_recommending_menu.user_recommend(user_id, each_menu_recommend_data, each_user_pearson_data, conn)
  File "C:\flaskProjects\smartOrderService_recommendingMenu\compute_recommending_menu.py", line 93, in user_recommend
    result_list = []
IndexError: list index out of range
INFO:werkzeug:127.0.0.1 - - [05/May/2021 03:12:14] "[35m[1mGET /555 HTTP/1.1[0m" 500 -
ERROR:app:Exception on /555 [GET]
Traceback (most recent call last):
  File "C:\venvs\smartOrderService\lib\site-packages\flask\app.py", line 2447, in wsgi_app
    response = self.full_dispatch_request()
  File "C:\venvs\smartOrderService\lib\site-packages\flask\app.py", line 1952, in full_dispatch_request
    rv = self.handle_user_exception(e)
  File "C:\venvs\smartOrderService\lib\site-packages\flask_cors\extension.py", line 165, in wrapped_function
    return cors_after_request(app.make_response(f(*args, **kwargs)))
  File "C:\venvs\smartOrderService\lib\site-packages\flask\app.py", line 1821, in handle_user_exception
    reraise(exc_type, exc_value, tb)
  File "C:\venvs\smartOrderService\lib\site-packages\flask\_compat.py", line 39, in reraise
    raise value
  File "C:\venvs\smartOrderService\lib\site-packages\flask\app.py", line 1950, in full_dispatch_request
    rv = self.dispatch_request()
  File "C:\venvs\smartOrderService\lib\site-packages\flask\app.py", line 1936, in dispatch_request
    return self.view_functions[rule.endpoint](**req.view_args)
  File "C:/flaskProjects/smartOrderService_recommendingMenu/app.py", line 57, in recommend
    result = compute_recommending_menu.user_recommend(user_id, each_menu_recommend_data, each_user_pearson_data, conn)
  File "C:\flaskProjects\smartOrderService_recommendingMenu\compute_recommending_menu.py", line 93, in user_recommend
    result_list = []
IndexError: list index out of range
INFO:werkzeug:127.0.0.1 - - [05/May/2021 03:12:14] "[35m[1mGET /555 HTTP/1.1[0m" 500 -
ERROR:app:Exception on /555 [GET]
Traceback (most recent call last):
  File "C:\venvs\smartOrderService\lib\site-packages\flask\app.py", line 2447, in wsgi_app
    response = self.full_dispatch_request()
  File "C:\venvs\smartOrderService\lib\site-packages\flask\app.py", line 1952, in full_dispatch_request
    rv = self.handle_user_exception(e)
  File "C:\venvs\smartOrderService\lib\site-packages\flask_cors\extension.py", line 165, in wrapped_function
    return cors_after_request(app.make_response(f(*args, **kwargs)))
  File "C:\venvs\smartOrderService\lib\site-packages\flask\app.py", line 1821, in handle_user_exception
    reraise(exc_type, exc_value, tb)
  File "C:\venvs\smartOrderService\lib\site-packages\flask\_compat.py", line 39, in reraise
    raise value
  File "C:\venvs\smartOrderService\lib\site-packages\flask\app.py", line 1950, in full_dispatch_request
    rv = self.dispatch_request()
  File "C:\venvs\smartOrderService\lib\site-packages\flask\app.py", line 1936, in dispatch_request
    return self.view_functions[rule.endpoint](**req.view_args)
  File "C:/flaskProjects/smartOrderService_recommendingMenu/app.py", line 57, in recommend
    result = compute_recommending_menu.user_recommend(user_id, each_menu_recommend_data, each_user_pearson_data, conn)
  File "C:\flaskProjects\smartOrderService_recommendingMenu\compute_recommending_menu.py", line 93, in user_recommend
    result_list = []
IndexError: list index out of range
INFO:werkzeug:127.0.0.1 - - [05/May/2021 03:12:14] "[35m[1mGET /555 HTTP/1.1[0m" 500 -
ERROR:app:Exception on /555 [GET]
Traceback (most recent call last):
  File "C:\venvs\smartOrderService\lib\site-packages\flask\app.py", line 2447, in wsgi_app
    response = self.full_dispatch_request()
  File "C:\venvs\smartOrderService\lib\site-packages\flask\app.py", line 1952, in full_dispatch_request
    rv = self.handle_user_exception(e)
  File "C:\venvs\smartOrderService\lib\site-packages\flask_cors\extension.py", line 165, in wrapped_function
    return cors_after_request(app.make_response(f(*args, **kwargs)))
  File "C:\venvs\smartOrderService\lib\site-packages\flask\app.py", line 1821, in handle_user_exception
    reraise(exc_type, exc_value, tb)
  File "C:\venvs\smartOrderService\lib\site-packages\flask\_compat.py", line 39, in reraise
    raise value
  File "C:\venvs\smartOrderService\lib\site-packages\flask\app.py", line 1950, in full_dispatch_request
    rv = self.dispatch_request()
  File "C:\venvs\smartOrderService\lib\site-packages\flask\app.py", line 1936, in dispatch_request
    return self.view_functions[rule.endpoint](**req.view_args)
  File "C:/flaskProjects/smartOrderService_recommendingMenu/app.py", line 57, in recommend
    result = compute_recommending_menu.user_recommend(user_id, each_menu_recommend_data, each_user_pearson_data, conn)
  File "C:\flaskProjects\smartOrderService_recommendingMenu\compute_recommending_menu.py", line 93, in user_recommend
    result_list = []
IndexError: list index out of range
INFO:werkzeug:127.0.0.1 - - [05/May/2021 03:12:15] "[35m[1mGET /555 HTTP/1.1[0m" 500 -
ERROR:app:Exception on /555 [GET]
Traceback (most recent call last):
  File "C:\venvs\smartOrderService\lib\site-packages\flask\app.py", line 2447, in wsgi_app
    response = self.full_dispatch_request()
  File "C:\venvs\smartOrderService\lib\site-packages\flask\app.py", line 1952, in full_dispatch_request
    rv = self.handle_user_exception(e)
  File "C:\venvs\smartOrderService\lib\site-packages\flask_cors\extension.py", line 165, in wrapped_function
    return cors_after_request(app.make_response(f(*args, **kwargs)))
  File "C:\venvs\smartOrderService\lib\site-packages\flask\app.py", line 1821, in handle_user_exception
    reraise(exc_type, exc_value, tb)
  File "C:\venvs\smartOrderService\lib\site-packages\flask\_compat.py", line 39, in reraise
    raise value
  File "C:\venvs\smartOrderService\lib\site-packages\flask\app.py", line 1950, in full_dispatch_request
    rv = self.dispatch_request()
  File "C:\venvs\smartOrderService\lib\site-packages\flask\app.py", line 1936, in dispatch_request
    return self.view_functions[rule.endpoint](**req.view_args)
  File "C:/flaskProjects/smartOrderService_recommendingMenu/app.py", line 57, in recommend
    result = compute_recommending_menu.user_recommend(user_id, each_menu_recommend_data, each_user_pearson_data, conn)
  File "C:\flaskProjects\smartOrderService_recommendingMenu\compute_recommending_menu.py", line 93, in user_recommend
    result_list = []
IndexError: list index out of range
INFO:werkzeug:127.0.0.1 - - [05/May/2021 03:12:15] "[35m[1mGET /555 HTTP/1.1[0m" 500 -
ERROR:app:Exception on /555 [GET]
Traceback (most recent call last):
  File "C:\venvs\smartOrderService\lib\site-packages\flask\app.py", line 2447, in wsgi_app
    response = self.full_dispatch_request()
  File "C:\venvs\smartOrderService\lib\site-packages\flask\app.py", line 1952, in full_dispatch_request
    rv = self.handle_user_exception(e)
  File "C:\venvs\smartOrderService\lib\site-packages\flask_cors\extension.py", line 165, in wrapped_function
    return cors_after_request(app.make_response(f(*args, **kwargs)))
  File "C:\venvs\smartOrderService\lib\site-packages\flask\app.py", line 1821, in handle_user_exception
    reraise(exc_type, exc_value, tb)
  File "C:\venvs\smartOrderService\lib\site-packages\flask\_compat.py", line 39, in reraise
    raise value
  File "C:\venvs\smartOrderService\lib\site-packages\flask\app.py", line 1950, in full_dispatch_request
    rv = self.dispatch_request()
  File "C:\venvs\smartOrderService\lib\site-packages\flask\app.py", line 1936, in dispatch_request
    return self.view_functions[rule.endpoint](**req.view_args)
  File "C:/flaskProjects/smartOrderService_recommendingMenu/app.py", line 57, in recommend
    result = compute_recommending_menu.user_recommend(user_id, each_menu_recommend_data, each_user_pearson_data, conn)
  File "C:\flaskProjects\smartOrderService_recommendingMenu\compute_recommending_menu.py", line 93, in user_recommend
    result_list = []
IndexError: list index out of range
INFO:werkzeug:127.0.0.1 - - [05/May/2021 03:12:15] "[35m[1mGET /555 HTTP/1.1[0m" 500 -
ERROR:app:Exception on /555 [GET]
Traceback (most recent call last):
  File "C:\venvs\smartOrderService\lib\site-packages\flask\app.py", line 2447, in wsgi_app
    response = self.full_dispatch_request()
  File "C:\venvs\smartOrderService\lib\site-packages\flask\app.py", line 1952, in full_dispatch_request
    rv = self.handle_user_exception(e)
  File "C:\venvs\smartOrderService\lib\site-packages\flask_cors\extension.py", line 165, in wrapped_function
    return cors_after_request(app.make_response(f(*args, **kwargs)))
  File "C:\venvs\smartOrderService\lib\site-packages\flask\app.py", line 1821, in handle_user_exception
    reraise(exc_type, exc_value, tb)
  File "C:\venvs\smartOrderService\lib\site-packages\flask\_compat.py", line 39, in reraise
    raise value
  File "C:\venvs\smartOrderService\lib\site-packages\flask\app.py", line 1950, in full_dispatch_request
    rv = self.dispatch_request()
  File "C:\venvs\smartOrderService\lib\site-packages\flask\app.py", line 1936, in dispatch_request
    return self.view_functions[rule.endpoint](**req.view_args)
  File "C:/flaskProjects/smartOrderService_recommendingMenu/app.py", line 57, in recommend
    result = compute_recommending_menu.user_recommend(user_id, each_menu_recommend_data, each_user_pearson_data, conn)
  File "C:\flaskProjects\smartOrderService_recommendingMenu\compute_recommending_menu.py", line 93, in user_recommend
    result_list = []
IndexError: list index out of range
INFO:werkzeug:127.0.0.1 - - [05/May/2021 03:12:15] "[35m[1mGET /555 HTTP/1.1[0m" 500 -
ERROR:app:Exception on /55 [GET]
Traceback (most recent call last):
  File "C:\venvs\smartOrderService\lib\site-packages\flask\app.py", line 2447, in wsgi_app
    response = self.full_dispatch_request()
  File "C:\venvs\smartOrderService\lib\site-packages\flask\app.py", line 1952, in full_dispatch_request
    rv = self.handle_user_exception(e)
  File "C:\venvs\smartOrderService\lib\site-packages\flask_cors\extension.py", line 165, in wrapped_function
    return cors_after_request(app.make_response(f(*args, **kwargs)))
  File "C:\venvs\smartOrderService\lib\site-packages\flask\app.py", line 1821, in handle_user_exception
    reraise(exc_type, exc_value, tb)
  File "C:\venvs\smartOrderService\lib\site-packages\flask\_compat.py", line 39, in reraise
    raise value
  File "C:\venvs\smartOrderService\lib\site-packages\flask\app.py", line 1950, in full_dispatch_request
    rv = self.dispatch_request()
  File "C:\venvs\smartOrderService\lib\site-packages\flask\app.py", line 1936, in dispatch_request
    return self.view_functions[rule.endpoint](**req.view_args)
  File "C:/flaskProjects/smartOrderService_recommendingMenu/app.py", line 57, in recommend
    result = compute_recommending_menu.user_recommend(user_id, each_menu_recommend_data, each_user_pearson_data, conn)
  File "C:\flaskProjects\smartOrderService_recommendingMenu\compute_recommending_menu.py", line 93, in user_recommend
    result_list = []
IndexError: list index out of range
INFO:werkzeug:127.0.0.1 - - [05/May/2021 03:12:36] "[35m[1mGET /55 HTTP/1.1[0m" 500 -
ERROR:app:Exception on /111 [GET]
Traceback (most recent call last):
  File "C:\venvs\smartOrderService\lib\site-packages\flask\app.py", line 2447, in wsgi_app
    response = self.full_dispatch_request()
  File "C:\venvs\smartOrderService\lib\site-packages\flask\app.py", line 1952, in full_dispatch_request
    rv = self.handle_user_exception(e)
  File "C:\venvs\smartOrderService\lib\site-packages\flask_cors\extension.py", line 165, in wrapped_function
    return cors_after_request(app.make_response(f(*args, **kwargs)))
  File "C:\venvs\smartOrderService\lib\site-packages\flask\app.py", line 1821, in handle_user_exception
    reraise(exc_type, exc_value, tb)
  File "C:\venvs\smartOrderService\lib\site-packages\flask\_compat.py", line 39, in reraise
    raise value
  File "C:\venvs\smartOrderService\lib\site-packages\flask\app.py", line 1950, in full_dispatch_request
    rv = self.dispatch_request()
  File "C:\venvs\smartOrderService\lib\site-packages\flask\app.py", line 1936, in dispatch_request
    return self.view_functions[rule.endpoint](**req.view_args)
  File "C:/flaskProjects/smartOrderService_recommendingMenu/app.py", line 57, in recommend
    result = compute_recommending_menu.user_recommend(user_id, each_menu_recommend_data, each_user_pearson_data, conn)
  File "C:\flaskProjects\smartOrderService_recommendingMenu\compute_recommending_menu.py", line 93, in user_recommend
    result_list = []
IndexError: list index out of range
INFO:werkzeug:127.0.0.1 - - [05/May/2021 03:12:39] "[35m[1mGET /111 HTTP/1.1[0m" 500 -
ERROR:app:Exception on /111 [GET]
Traceback (most recent call last):
  File "C:\venvs\smartOrderService\lib\site-packages\flask\app.py", line 2447, in wsgi_app
    response = self.full_dispatch_request()
  File "C:\venvs\smartOrderService\lib\site-packages\flask\app.py", line 1952, in full_dispatch_request
    rv = self.handle_user_exception(e)
  File "C:\venvs\smartOrderService\lib\site-packages\flask_cors\extension.py", line 165, in wrapped_function
    return cors_after_request(app.make_response(f(*args, **kwargs)))
  File "C:\venvs\smartOrderService\lib\site-packages\flask\app.py", line 1821, in handle_user_exception
    reraise(exc_type, exc_value, tb)
  File "C:\venvs\smartOrderService\lib\site-packages\flask\_compat.py", line 39, in reraise
    raise value
  File "C:\venvs\smartOrderService\lib\site-packages\flask\app.py", line 1950, in full_dispatch_request
    rv = self.dispatch_request()
  File "C:\venvs\smartOrderService\lib\site-packages\flask\app.py", line 1936, in dispatch_request
    return self.view_functions[rule.endpoint](**req.view_args)
  File "C:/flaskProjects/smartOrderService_recommendingMenu/app.py", line 57, in recommend
    result = compute_recommending_menu.user_recommend(user_id, each_menu_recommend_data, each_user_pearson_data, conn)
  File "C:\flaskProjects\smartOrderService_recommendingMenu\compute_recommending_menu.py", line 93, in user_recommend
    result_list = []
IndexError: list index out of range
INFO:werkzeug:127.0.0.1 - - [05/May/2021 03:13:16] "[35m[1mGET /111 HTTP/1.1[0m" 500 -
ERROR:app:Exception on /666 [GET]
Traceback (most recent call last):
  File "C:\venvs\smartOrderService\lib\site-packages\flask\app.py", line 2447, in wsgi_app
    response = self.full_dispatch_request()
  File "C:\venvs\smartOrderService\lib\site-packages\flask\app.py", line 1952, in full_dispatch_request
    rv = self.handle_user_exception(e)
  File "C:\venvs\smartOrderService\lib\site-packages\flask_cors\extension.py", line 165, in wrapped_function
    return cors_after_request(app.make_response(f(*args, **kwargs)))
  File "C:\venvs\smartOrderService\lib\site-packages\flask\app.py", line 1821, in handle_user_exception
    reraise(exc_type, exc_value, tb)
  File "C:\venvs\smartOrderService\lib\site-packages\flask\_compat.py", line 39, in reraise
    raise value
  File "C:\venvs\smartOrderService\lib\site-packages\flask\app.py", line 1950, in full_dispatch_request
    rv = self.dispatch_request()
  File "C:\venvs\smartOrderService\lib\site-packages\flask\app.py", line 1936, in dispatch_request
    return self.view_functions[rule.endpoint](**req.view_args)
  File "C:/flaskProjects/smartOrderService_recommendingMenu/app.py", line 57, in recommend
    result = compute_recommending_menu.user_recommend(user_id, each_menu_recommend_data, each_user_pearson_data, conn)
  File "C:\flaskProjects\smartOrderService_recommendingMenu\compute_recommending_menu.py", line 93, in user_recommend
    result_list = []
IndexError: list index out of range
INFO:werkzeug:127.0.0.1 - - [05/May/2021 03:13:20] "[35m[1mGET /666 HTTP/1.1[0m" 500 -
INFO:werkzeug: * Restarting with stat
ERROR:app:Exception on /666 [GET]
Traceback (most recent call last):
  File "C:\venvs\smartOrderService\lib\site-packages\flask\app.py", line 2447, in wsgi_app
    response = self.full_dispatch_request()
  File "C:\venvs\smartOrderService\lib\site-packages\flask\app.py", line 1952, in full_dispatch_request
    rv = self.handle_user_exception(e)
  File "C:\venvs\smartOrderService\lib\site-packages\flask_cors\extension.py", line 165, in wrapped_function
    return cors_after_request(app.make_response(f(*args, **kwargs)))
  File "C:\venvs\smartOrderService\lib\site-packages\flask\app.py", line 1821, in handle_user_exception
    reraise(exc_type, exc_value, tb)
  File "C:\venvs\smartOrderService\lib\site-packages\flask\_compat.py", line 39, in reraise
    raise value
  File "C:\venvs\smartOrderService\lib\site-packages\flask\app.py", line 1950, in full_dispatch_request
    rv = self.dispatch_request()
  File "C:\venvs\smartOrderService\lib\site-packages\flask\app.py", line 1936, in dispatch_request
    return self.view_functions[rule.endpoint](**req.view_args)
  File "C:/flaskProjects/smartOrderService_recommendingMenu/app.py", line 57, in recommend
    result = compute_recommending_menu.user_recommend(user_id, each_menu_recommend_data, each_user_pearson_data, conn)
  File "C:\flaskProjects\smartOrderService_recommendingMenu\compute_recommending_menu.py", line 93, in user_recommend
    result_list = []
IndexError: list index out of range
INFO:werkzeug:127.0.0.1 - - [05/May/2021 03:13:53] "[35m[1mGET /666 HTTP/1.1[0m" 500 -
WARNING:werkzeug: * Debugger is active!
INFO:werkzeug: * Debugger PIN: 158-607-768
INFO:werkzeug: * Running on http://0.0.0.0:5000/ (Press CTRL+C to quit)
ERROR:app:Exception on /666 [GET]
Traceback (most recent call last):
  File "C:\venvs\smartOrderService\lib\site-packages\flask\app.py", line 2447, in wsgi_app
    response = self.full_dispatch_request()
  File "C:\venvs\smartOrderService\lib\site-packages\flask\app.py", line 1952, in full_dispatch_request
    rv = self.handle_user_exception(e)
  File "C:\venvs\smartOrderService\lib\site-packages\flask_cors\extension.py", line 165, in wrapped_function
    return cors_after_request(app.make_response(f(*args, **kwargs)))
  File "C:\venvs\smartOrderService\lib\site-packages\flask\app.py", line 1821, in handle_user_exception
    reraise(exc_type, exc_value, tb)
  File "C:\venvs\smartOrderService\lib\site-packages\flask\_compat.py", line 39, in reraise
    raise value
  File "C:\venvs\smartOrderService\lib\site-packages\flask\app.py", line 1950, in full_dispatch_request
    rv = self.dispatch_request()
  File "C:\venvs\smartOrderService\lib\site-packages\flask\app.py", line 1936, in dispatch_request
    return self.view_functions[rule.endpoint](**req.view_args)
  File "C:/flaskProjects/smartOrderService_recommendingMenu/app.py", line 57, in recommend
    result = compute_recommending_menu.user_recommend(user_id, each_menu_recommend_data, each_user_pearson_data, conn)
  File "C:\flaskProjects\smartOrderService_recommendingMenu\compute_recommending_menu.py", line 93, in user_recommend
    result_list = []
IndexError: list index out of range
INFO:werkzeug:127.0.0.1 - - [05/May/2021 03:13:55] "[35m[1mGET /666 HTTP/1.1[0m" 500 -
INFO:werkzeug:127.0.0.1 - - [05/May/2021 03:14:01] "[37mGET / HTTP/1.1[0m" 200 -
ERROR:app:Exception on /555 [GET]
Traceback (most recent call last):
  File "C:\venvs\smartOrderService\lib\site-packages\flask\app.py", line 2447, in wsgi_app
    response = self.full_dispatch_request()
  File "C:\venvs\smartOrderService\lib\site-packages\flask\app.py", line 1952, in full_dispatch_request
    rv = self.handle_user_exception(e)
  File "C:\venvs\smartOrderService\lib\site-packages\flask_cors\extension.py", line 165, in wrapped_function
    return cors_after_request(app.make_response(f(*args, **kwargs)))
  File "C:\venvs\smartOrderService\lib\site-packages\flask\app.py", line 1821, in handle_user_exception
    reraise(exc_type, exc_value, tb)
  File "C:\venvs\smartOrderService\lib\site-packages\flask\_compat.py", line 39, in reraise
    raise value
  File "C:\venvs\smartOrderService\lib\site-packages\flask\app.py", line 1950, in full_dispatch_request
    rv = self.dispatch_request()
  File "C:\venvs\smartOrderService\lib\site-packages\flask\app.py", line 1936, in dispatch_request
    return self.view_functions[rule.endpoint](**req.view_args)
  File "C:/flaskProjects/smartOrderService_recommendingMenu/app.py", line 57, in recommend
    result = compute_recommending_menu.user_recommend(user_id, each_menu_recommend_data, each_user_pearson_data, conn)
  File "C:\flaskProjects\smartOrderService_recommendingMenu\compute_recommending_menu.py", line 93, in user_recommend
    result_list = []
IndexError: list index out of range
INFO:werkzeug:127.0.0.1 - - [05/May/2021 03:14:08] "[35m[1mGET /555 HTTP/1.1[0m" 500 -
INFO:werkzeug: * Detected change in 'C:\\flaskProjects\\smartOrderService_recommendingMenu\\app.py', reloading
INFO:werkzeug: * Restarting with stat
INFO:werkzeug: * Running on http://0.0.0.0:5000/ (Press CTRL+C to quit)
INFO:werkzeug: * Running on http://0.0.0.0:5000/ (Press CTRL+C to quit)
INFO:werkzeug:127.0.0.1 - - [05/May/2021 03:15:26] "[37mGET / HTTP/1.1[0m" 200 -
INFO:werkzeug:127.0.0.1 - - [05/May/2021 03:15:36] "[37mGET /refresh_data HTTP/1.1[0m" 200 -
INFO:werkzeug:127.0.0.1 - - [05/May/2021 03:15:42] "[37mGET /555 HTTP/1.1[0m" 200 -
INFO:werkzeug:127.0.0.1 - - [05/May/2021 13:15:41] "[37mGET / HTTP/1.1[0m" 200 -
INFO:werkzeug:127.0.0.1 - - [05/May/2021 13:15:44] "[37mGET /566 HTTP/1.1[0m" 200 -
INFO:werkzeug: * Running on http://0.0.0.0:5000/ (Press CTRL+C to quit)
INFO:werkzeug:125.138.216.31 - - [05/May/2021 15:30:25] "[37mGET /611 HTTP/1.1[0m" 200 -
INFO:werkzeug:125.138.216.31 - - [05/May/2021 15:30:28] "[37mGET /1 HTTP/1.1[0m" 200 -
ERROR:app:Exception on /2 [GET]
Traceback (most recent call last):
  File "/usr/local/lib/python3.6/dist-packages/flask/app.py", line 2447, in wsgi_app
    response = self.full_dispatch_request()
  File "/usr/local/lib/python3.6/dist-packages/flask/app.py", line 1952, in full_dispatch_request
    rv = self.handle_user_exception(e)
  File "/usr/local/lib/python3.6/dist-packages/flask_cors/extension.py", line 165, in wrapped_function
    return cors_after_request(app.make_response(f(*args, **kwargs)))
  File "/usr/local/lib/python3.6/dist-packages/flask/app.py", line 1821, in handle_user_exception
    reraise(exc_type, exc_value, tb)
  File "/usr/local/lib/python3.6/dist-packages/flask/_compat.py", line 39, in reraise
    raise value
  File "/usr/local/lib/python3.6/dist-packages/flask/app.py", line 1950, in full_dispatch_request
    rv = self.dispatch_request()
  File "/usr/local/lib/python3.6/dist-packages/flask/app.py", line 1936, in dispatch_request
    return self.view_functions[rule.endpoint](**req.view_args)
  File "./app.py", line 57, in recommend
    result = compute_recommending_menu.user_recommend(user_id, each_menu_recommend_data, each_user_pearson_data, conn)
  File "/home/ubuntu/smartOrderService/compute_recommending_menu.py", line 95, in user_recommend
    result_list = non_user_recommend_func(user_id, each_menu_recommend_data, conn)
  File "/home/ubuntu/smartOrderService/compute_recommending_menu.py", line 129, in non_user_recommend_func
    process_recommend(ratings_matrix, each_menu_recommend_data, func_result)
  File "/home/ubuntu/smartOrderService/compute_recommending_menu.py", line 19, in process_recommend
    cur_pearson_datas = each_menu_recommend_data[csv_menu_idx]['Pearson Data']
IndexError: list index out of range
INFO:werkzeug:125.138.216.31 - - [05/May/2021 15:30:30] "[35m[1mGET /2 HTTP/1.1[0m" 500 -
ERROR:app:Exception on /2 [GET]
Traceback (most recent call last):
  File "/usr/local/lib/python3.6/dist-packages/flask/app.py", line 2447, in wsgi_app
    response = self.full_dispatch_request()
  File "/usr/local/lib/python3.6/dist-packages/flask/app.py", line 1952, in full_dispatch_request
    rv = self.handle_user_exception(e)
  File "/usr/local/lib/python3.6/dist-packages/flask_cors/extension.py", line 165, in wrapped_function
    return cors_after_request(app.make_response(f(*args, **kwargs)))
  File "/usr/local/lib/python3.6/dist-packages/flask/app.py", line 1821, in handle_user_exception
    reraise(exc_type, exc_value, tb)
  File "/usr/local/lib/python3.6/dist-packages/flask/_compat.py", line 39, in reraise
    raise value
  File "/usr/local/lib/python3.6/dist-packages/flask/app.py", line 1950, in full_dispatch_request
    rv = self.dispatch_request()
  File "/usr/local/lib/python3.6/dist-packages/flask/app.py", line 1936, in dispatch_request
    return self.view_functions[rule.endpoint](**req.view_args)
  File "./app.py", line 57, in recommend
    result = compute_recommending_menu.user_recommend(user_id, each_menu_recommend_data, each_user_pearson_data, conn)
  File "/home/ubuntu/smartOrderService/compute_recommending_menu.py", line 95, in user_recommend
    result_list = non_user_recommend_func(user_id, each_menu_recommend_data, conn)
  File "/home/ubuntu/smartOrderService/compute_recommending_menu.py", line 129, in non_user_recommend_func
    process_recommend(ratings_matrix, each_menu_recommend_data, func_result)
  File "/home/ubuntu/smartOrderService/compute_recommending_menu.py", line 19, in process_recommend
    cur_pearson_datas = each_menu_recommend_data[csv_menu_idx]['Pearson Data']
IndexError: list index out of range
INFO:werkzeug:125.138.216.31 - - [05/May/2021 15:30:34] "[35m[1mGET /2 HTTP/1.1[0m" 500 -
ERROR:app:Exception on /3 [GET]
Traceback (most recent call last):
  File "/usr/local/lib/python3.6/dist-packages/flask/app.py", line 2447, in wsgi_app
    response = self.full_dispatch_request()
  File "/usr/local/lib/python3.6/dist-packages/flask/app.py", line 1952, in full_dispatch_request
    rv = self.handle_user_exception(e)
  File "/usr/local/lib/python3.6/dist-packages/flask_cors/extension.py", line 165, in wrapped_function
    return cors_after_request(app.make_response(f(*args, **kwargs)))
  File "/usr/local/lib/python3.6/dist-packages/flask/app.py", line 1821, in handle_user_exception
    reraise(exc_type, exc_value, tb)
  File "/usr/local/lib/python3.6/dist-packages/flask/_compat.py", line 39, in reraise
    raise value
  File "/usr/local/lib/python3.6/dist-packages/flask/app.py", line 1950, in full_dispatch_request
    rv = self.dispatch_request()
  File "/usr/local/lib/python3.6/dist-packages/flask/app.py", line 1936, in dispatch_request
    return self.view_functions[rule.endpoint](**req.view_args)
  File "./app.py", line 57, in recommend
    result = compute_recommending_menu.user_recommend(user_id, each_menu_recommend_data, each_user_pearson_data, conn)
  File "/home/ubuntu/smartOrderService/compute_recommending_menu.py", line 95, in user_recommend
    result_list = non_user_recommend_func(user_id, each_menu_recommend_data, conn)
  File "/home/ubuntu/smartOrderService/compute_recommending_menu.py", line 129, in non_user_recommend_func
    process_recommend(ratings_matrix, each_menu_recommend_data, func_result)
  File "/home/ubuntu/smartOrderService/compute_recommending_menu.py", line 19, in process_recommend
    cur_pearson_datas = each_menu_recommend_data[csv_menu_idx]['Pearson Data']
IndexError: list index out of range
INFO:werkzeug:125.138.216.31 - - [05/May/2021 15:30:36] "[35m[1mGET /3 HTTP/1.1[0m" 500 -
INFO:werkzeug:125.138.216.31 - - [05/May/2021 15:30:38] "[37mGET /1 HTTP/1.1[0m" 200 -
ERROR:app:Exception on /4 [GET]
Traceback (most recent call last):
  File "/usr/local/lib/python3.6/dist-packages/flask/app.py", line 2447, in wsgi_app
    response = self.full_dispatch_request()
  File "/usr/local/lib/python3.6/dist-packages/flask/app.py", line 1952, in full_dispatch_request
    rv = self.handle_user_exception(e)
  File "/usr/local/lib/python3.6/dist-packages/flask_cors/extension.py", line 165, in wrapped_function
    return cors_after_request(app.make_response(f(*args, **kwargs)))
  File "/usr/local/lib/python3.6/dist-packages/flask/app.py", line 1821, in handle_user_exception
    reraise(exc_type, exc_value, tb)
  File "/usr/local/lib/python3.6/dist-packages/flask/_compat.py", line 39, in reraise
    raise value
  File "/usr/local/lib/python3.6/dist-packages/flask/app.py", line 1950, in full_dispatch_request
    rv = self.dispatch_request()
  File "/usr/local/lib/python3.6/dist-packages/flask/app.py", line 1936, in dispatch_request
    return self.view_functions[rule.endpoint](**req.view_args)
  File "./app.py", line 57, in recommend
    result = compute_recommending_menu.user_recommend(user_id, each_menu_recommend_data, each_user_pearson_data, conn)
  File "/home/ubuntu/smartOrderService/compute_recommending_menu.py", line 95, in user_recommend
    result_list = non_user_recommend_func(user_id, each_menu_recommend_data, conn)
  File "/home/ubuntu/smartOrderService/compute_recommending_menu.py", line 129, in non_user_recommend_func
    process_recommend(ratings_matrix, each_menu_recommend_data, func_result)
  File "/home/ubuntu/smartOrderService/compute_recommending_menu.py", line 19, in process_recommend
    cur_pearson_datas = each_menu_recommend_data[csv_menu_idx]['Pearson Data']
IndexError: list index out of range
INFO:werkzeug:125.138.216.31 - - [05/May/2021 15:30:40] "[35m[1mGET /4 HTTP/1.1[0m" 500 -
ERROR:app:Exception on /503 [GET]
Traceback (most recent call last):
  File "/usr/local/lib/python3.6/dist-packages/flask/app.py", line 2447, in wsgi_app
    response = self.full_dispatch_request()
  File "/usr/local/lib/python3.6/dist-packages/flask/app.py", line 1952, in full_dispatch_request
    rv = self.handle_user_exception(e)
  File "/usr/local/lib/python3.6/dist-packages/flask_cors/extension.py", line 165, in wrapped_function
    return cors_after_request(app.make_response(f(*args, **kwargs)))
  File "/usr/local/lib/python3.6/dist-packages/flask/app.py", line 1821, in handle_user_exception
    reraise(exc_type, exc_value, tb)
  File "/usr/local/lib/python3.6/dist-packages/flask/_compat.py", line 39, in reraise
    raise value
  File "/usr/local/lib/python3.6/dist-packages/flask/app.py", line 1950, in full_dispatch_request
    rv = self.dispatch_request()
  File "/usr/local/lib/python3.6/dist-packages/flask/app.py", line 1936, in dispatch_request
    return self.view_functions[rule.endpoint](**req.view_args)
  File "./app.py", line 57, in recommend
    result = compute_recommending_menu.user_recommend(user_id, each_menu_recommend_data, each_user_pearson_data, conn)
  File "/home/ubuntu/smartOrderService/compute_recommending_menu.py", line 97, in user_recommend
    result_list = user_recommend_func(user_id, each_menu_recommend_data, each_user_pearson_data, conn)
  File "/home/ubuntu/smartOrderService/compute_recommending_menu.py", line 107, in user_recommend_func
    gather_menu(user_pearson[0], user_pearson[1], each_menu_recommend_data, result_list, conn, True)
  File "/home/ubuntu/smartOrderService/compute_recommending_menu.py", line 37, in gather_menu
    pearson_datas = each_menu_recommend_data[user_favor['menu_id'][0] - 1]['Pearson Data']
IndexError: list index out of range
INFO:werkzeug:125.138.216.31 - - [05/May/2021 15:30:43] "[35m[1mGET /503 HTTP/1.1[0m" 500 -
INFO:werkzeug:125.138.216.31 - - [05/May/2021 15:30:47] "[37mGET /555 HTTP/1.1[0m" 200 -
INFO:werkzeug: * Running on http://0.0.0.0:5000/ (Press CTRL+C to quit)
INFO:werkzeug:125.138.216.31 - - [05/May/2021 15:32:07] "[37mGET /1 HTTP/1.1[0m" 200 -
INFO:werkzeug:125.138.216.31 - - [05/May/2021 15:32:10] "[37mGET /2 HTTP/1.1[0m" 200 -
INFO:werkzeug:125.138.216.31 - - [05/May/2021 15:32:12] "[37mGET /3 HTTP/1.1[0m" 200 -
INFO:werkzeug:125.138.216.31 - - [05/May/2021 15:32:15] "[37mGET /666 HTTP/1.1[0m" 200 -
INFO:werkzeug:125.138.216.31 - - [05/May/2021 15:34:50] "[37mGET /669 HTTP/1.1[0m" 200 -
INFO:werkzeug:125.138.216.31 - - [05/May/2021 15:34:59] "[37mGET /800 HTTP/1.1[0m" 200 -
INFO:werkzeug:39.119.57.117 - - [05/May/2021 15:36:27] "[37mGET /666 HTTP/1.1[0m" 200 -
INFO:werkzeug:39.119.57.117 - - [05/May/2021 15:36:27] "[33mGET /favicon.ico HTTP/1.1[0m" 404 -
INFO:werkzeug:39.119.57.117 - - [05/May/2021 15:37:19] "[37mOPTIONS /804 HTTP/1.1[0m" 200 -
INFO:werkzeug:39.119.57.117 - - [05/May/2021 15:37:19] "[37mGET /804 HTTP/1.1[0m" 200 -
INFO:werkzeug:39.119.57.117 - - [05/May/2021 15:41:05] "[37mOPTIONS /805 HTTP/1.1[0m" 200 -
INFO:werkzeug:39.119.57.117 - - [05/May/2021 15:41:05] "[37mGET /805 HTTP/1.1[0m" 200 -
INFO:werkzeug:39.119.57.117 - - [05/May/2021 15:41:30] "[37mOPTIONS /806 HTTP/1.1[0m" 200 -
INFO:werkzeug:39.119.57.117 - - [05/May/2021 15:41:30] "[37mGET /806 HTTP/1.1[0m" 200 -
INFO:werkzeug:39.119.57.117 - - [05/May/2021 15:44:42] "[37mOPTIONS /807 HTTP/1.1[0m" 200 -
INFO:werkzeug:39.119.57.117 - - [05/May/2021 15:44:42] "[37mGET /807 HTTP/1.1[0m" 200 -
INFO:werkzeug:39.119.57.117 - - [05/May/2021 15:45:00] "[37mOPTIONS / HTTP/1.1[0m" 200 -
INFO:werkzeug:39.119.57.117 - - [05/May/2021 15:45:01] "[37mGET / HTTP/1.1[0m" 200 -
INFO:werkzeug:39.119.57.117 - - [05/May/2021 15:45:30] "[37mOPTIONS / HTTP/1.1[0m" 200 -
INFO:werkzeug:39.119.57.117 - - [05/May/2021 15:45:30] "[37mGET / HTTP/1.1[0m" 200 -
INFO:werkzeug:39.119.57.117 - - [05/May/2021 15:47:06] "[37mOPTIONS /810 HTTP/1.1[0m" 200 -
INFO:werkzeug:39.119.57.117 - - [05/May/2021 15:47:06] "[37mGET /810 HTTP/1.1[0m" 200 -
INFO:werkzeug:39.119.57.117 - - [05/May/2021 15:47:23] "[37mOPTIONS /811 HTTP/1.1[0m" 200 -
INFO:werkzeug:39.119.57.117 - - [05/May/2021 15:47:23] "[37mGET /811 HTTP/1.1[0m" 200 -
INFO:werkzeug:39.119.57.117 - - [05/May/2021 15:47:48] "[37mOPTIONS /801 HTTP/1.1[0m" 200 -
INFO:werkzeug:39.119.57.117 - - [05/May/2021 15:47:48] "[37mGET /801 HTTP/1.1[0m" 200 -
INFO:werkzeug:39.119.57.117 - - [05/May/2021 15:48:08] "[37mOPTIONS /801 HTTP/1.1[0m" 200 -
INFO:werkzeug:39.119.57.117 - - [05/May/2021 15:48:08] "[37mGET /801 HTTP/1.1[0m" 200 -
INFO:werkzeug:39.119.57.117 - - [05/May/2021 15:48:34] "[37mOPTIONS /801 HTTP/1.1[0m" 200 -
INFO:werkzeug:39.119.57.117 - - [05/May/2021 15:48:34] "[37mGET /801 HTTP/1.1[0m" 200 -
INFO:werkzeug:39.119.57.117 - - [05/May/2021 15:49:00] "[37mOPTIONS /801 HTTP/1.1[0m" 200 -
INFO:werkzeug:39.119.57.117 - - [05/May/2021 15:49:00] "[37mGET /801 HTTP/1.1[0m" 200 -
INFO:werkzeug:39.119.57.117 - - [05/May/2021 15:51:04] "[37mOPTIONS /801 HTTP/1.1[0m" 200 -
INFO:werkzeug:39.119.57.117 - - [05/May/2021 15:51:04] "[37mGET /801 HTTP/1.1[0m" 200 -
INFO:werkzeug:39.119.57.117 - - [05/May/2021 15:51:28] "[37mOPTIONS /801 HTTP/1.1[0m" 200 -
INFO:werkzeug:39.119.57.117 - - [05/May/2021 15:51:28] "[37mGET /801 HTTP/1.1[0m" 200 -
INFO:werkzeug:39.119.57.117 - - [05/May/2021 15:52:05] "[37mOPTIONS /801 HTTP/1.1[0m" 200 -
INFO:werkzeug:39.119.57.117 - - [05/May/2021 15:52:05] "[37mGET /801 HTTP/1.1[0m" 200 -
INFO:werkzeug:39.119.57.117 - - [05/May/2021 15:52:35] "[37mOPTIONS /801 HTTP/1.1[0m" 200 -
INFO:werkzeug:39.119.57.117 - - [05/May/2021 15:52:35] "[37mGET /801 HTTP/1.1[0m" 200 -
INFO:werkzeug:39.119.57.117 - - [05/May/2021 15:55:53] "[37mOPTIONS /801 HTTP/1.1[0m" 200 -
INFO:werkzeug:39.119.57.117 - - [05/May/2021 15:55:53] "[37mGET /801 HTTP/1.1[0m" 200 -
INFO:werkzeug:39.119.57.117 - - [05/May/2021 16:00:53] "[37mOPTIONS /801 HTTP/1.1[0m" 200 -
INFO:werkzeug:39.119.57.117 - - [05/May/2021 16:00:53] "[37mGET /801 HTTP/1.1[0m" 200 -
INFO:werkzeug:39.119.57.117 - - [05/May/2021 16:08:29] "[37mOPTIONS /801 HTTP/1.1[0m" 200 -
INFO:werkzeug:39.119.57.117 - - [05/May/2021 16:08:29] "[37mGET /801 HTTP/1.1[0m" 200 -
INFO:werkzeug:39.119.57.117 - - [05/May/2021 16:14:55] "[37mOPTIONS /812 HTTP/1.1[0m" 200 -
INFO:werkzeug:39.119.57.117 - - [05/May/2021 16:14:55] "[37mGET /812 HTTP/1.1[0m" 200 -
INFO:werkzeug:39.119.57.117 - - [05/May/2021 16:15:28] "[37mOPTIONS /813 HTTP/1.1[0m" 200 -
INFO:werkzeug:39.119.57.117 - - [05/May/2021 16:15:28] "[37mGET /813 HTTP/1.1[0m" 200 -
INFO:werkzeug: * Running on http://0.0.0.0:5000/ (Press CTRL+C to quit)
INFO:werkzeug:39.119.57.117 - - [05/May/2021 16:44:56] "[37mOPTIONS /815 HTTP/1.1[0m" 200 -
INFO:werkzeug:39.119.57.117 - - [05/May/2021 16:44:56] "[37mGET /815 HTTP/1.1[0m" 200 -
INFO:werkzeug:39.119.57.117 - - [05/May/2021 16:45:12] "[37mOPTIONS /801 HTTP/1.1[0m" 200 -
INFO:werkzeug:39.119.57.117 - - [05/May/2021 16:45:12] "[37mGET /801 HTTP/1.1[0m" 200 -
INFO:werkzeug:39.119.57.117 - - [05/May/2021 16:45:34] "[37mOPTIONS /801 HTTP/1.1[0m" 200 -
INFO:werkzeug:39.119.57.117 - - [05/May/2021 16:45:34] "[37mGET /801 HTTP/1.1[0m" 200 -
INFO:werkzeug:39.119.57.117 - - [05/May/2021 16:51:12] "[37mOPTIONS /801 HTTP/1.1[0m" 200 -
INFO:werkzeug:39.119.57.117 - - [05/May/2021 16:51:12] "[37mGET /801 HTTP/1.1[0m" 200 -
INFO:werkzeug:39.119.57.117 - - [05/May/2021 16:51:31] "[37mOPTIONS /801 HTTP/1.1[0m" 200 -
INFO:werkzeug:39.119.57.117 - - [05/May/2021 16:51:31] "[37mGET /801 HTTP/1.1[0m" 200 -
INFO:werkzeug:39.119.57.117 - - [05/May/2021 16:53:26] "[37mOPTIONS /801 HTTP/1.1[0m" 200 -
INFO:werkzeug:39.119.57.117 - - [05/May/2021 16:53:26] "[37mGET /801 HTTP/1.1[0m" 200 -
INFO:werkzeug:39.119.57.117 - - [05/May/2021 16:55:53] "[37mOPTIONS /801 HTTP/1.1[0m" 200 -
INFO:werkzeug:39.119.57.117 - - [05/May/2021 16:55:54] "[37mGET /801 HTTP/1.1[0m" 200 -
INFO:werkzeug:125.138.216.31 - - [05/May/2021 17:01:05] "[37mGET /800 HTTP/1.1[0m" 200 -
INFO:werkzeug:39.119.57.117 - - [05/May/2021 17:01:13] "[37mOPTIONS /801 HTTP/1.1[0m" 200 -
INFO:werkzeug:39.119.57.117 - - [05/May/2021 17:01:13] "[37mGET /801 HTTP/1.1[0m" 200 -
INFO:werkzeug:39.119.57.117 - - [05/May/2021 17:03:27] "[37mOPTIONS /801 HTTP/1.1[0m" 200 -
INFO:werkzeug:39.119.57.117 - - [05/May/2021 17:03:27] "[37mGET /801 HTTP/1.1[0m" 200 -
INFO:werkzeug:39.119.57.117 - - [05/May/2021 17:04:42] "[37mOPTIONS /801 HTTP/1.1[0m" 200 -
INFO:werkzeug:39.119.57.117 - - [05/May/2021 17:04:42] "[37mGET /801 HTTP/1.1[0m" 200 -
INFO:werkzeug:39.119.57.117 - - [05/May/2021 17:11:36] "[37mOPTIONS /816 HTTP/1.1[0m" 200 -
INFO:werkzeug:39.119.57.117 - - [05/May/2021 17:11:36] "[37mGET /816 HTTP/1.1[0m" 200 -
INFO:werkzeug:39.119.57.117 - - [05/May/2021 17:11:53] "[37mOPTIONS /801 HTTP/1.1[0m" 200 -
INFO:werkzeug:39.119.57.117 - - [05/May/2021 17:11:53] "[37mGET /801 HTTP/1.1[0m" 200 -
INFO:werkzeug:39.119.57.117 - - [05/May/2021 17:23:51] "[37mOPTIONS /817 HTTP/1.1[0m" 200 -
INFO:werkzeug:39.119.57.117 - - [05/May/2021 17:23:51] "[37mGET /817 HTTP/1.1[0m" 200 -
INFO:werkzeug:39.119.57.117 - - [05/May/2021 17:24:14] "[37mOPTIONS /801 HTTP/1.1[0m" 200 -
INFO:werkzeug:39.119.57.117 - - [05/May/2021 17:24:14] "[37mGET /801 HTTP/1.1[0m" 200 -
INFO:werkzeug: * Running on http://0.0.0.0:5000/ (Press CTRL+C to quit)
INFO:werkzeug:125.138.216.31 - - [05/May/2021 18:07:55] "[37mGET /800 HTTP/1.1[0m" 200 -
INFO:werkzeug:39.119.57.117 - - [05/May/2021 18:36:51] "[37mOPTIONS /818 HTTP/1.1[0m" 200 -
INFO:werkzeug:39.119.57.117 - - [05/May/2021 18:36:51] "[37mGET /818 HTTP/1.1[0m" 200 -
INFO:werkzeug:39.119.57.117 - - [05/May/2021 18:38:19] "[37mOPTIONS /820 HTTP/1.1[0m" 200 -
INFO:werkzeug:39.119.57.117 - - [05/May/2021 18:38:19] "[37mGET /820 HTTP/1.1[0m" 200 -
INFO:werkzeug:39.119.57.117 - - [05/May/2021 18:38:44] "[37mOPTIONS /801 HTTP/1.1[0m" 200 -
INFO:werkzeug:39.119.57.117 - - [05/May/2021 18:38:44] "[37mGET /801 HTTP/1.1[0m" 200 -
INFO:werkzeug: * Running on http://0.0.0.0:5000/ (Press CTRL+C to quit)
INFO:werkzeug:125.138.216.31 - - [05/May/2021 23:11:33] "[37mGET / HTTP/1.1[0m" 200 -
INFO:werkzeug:125.138.216.31 - - [05/May/2021 23:11:33] "[33mGET /favicon.ico HTTP/1.1[0m" 404 -
ERROR:app:Exception on /820 [GET]
Traceback (most recent call last):
  File "/usr/local/lib/python3.6/dist-packages/flask/app.py", line 2447, in wsgi_app
    response = self.full_dispatch_request()
  File "/usr/local/lib/python3.6/dist-packages/flask/app.py", line 1952, in full_dispatch_request
    rv = self.handle_user_exception(e)
  File "/usr/local/lib/python3.6/dist-packages/flask_cors/extension.py", line 165, in wrapped_function
    return cors_after_request(app.make_response(f(*args, **kwargs)))
  File "/usr/local/lib/python3.6/dist-packages/flask/app.py", line 1821, in handle_user_exception
    reraise(exc_type, exc_value, tb)
  File "/usr/local/lib/python3.6/dist-packages/flask/_compat.py", line 39, in reraise
    raise value
  File "/usr/local/lib/python3.6/dist-packages/flask/app.py", line 1950, in full_dispatch_request
    rv = self.dispatch_request()
  File "/usr/local/lib/python3.6/dist-packages/flask/app.py", line 1936, in dispatch_request
    return self.view_functions[rule.endpoint](**req.view_args)
  File "./app.py", line 57, in recommend
    result = compute_recommending_menu.user_recommend(user_id, each_menu_recommend_data, each_user_pearson_data, conn)
  File "/home/ubuntu/smartOrderService/compute_recommending_menu.py", line 94, in user_recommend
    user_create_date = user['created_at'][0].to_pydatetime()
  File "/usr/local/lib/python3.6/dist-packages/pandas/core/series.py", line 879, in __getitem__
    return self._values[key]
IndexError: index 0 is out of bounds for axis 0 with size 0
INFO:werkzeug:125.138.216.31 - - [05/May/2021 23:11:39] "[35m[1mGET /820 HTTP/1.1[0m" 500 -
ERROR:app:Exception on /820 [GET]
Traceback (most recent call last):
  File "/usr/local/lib/python3.6/dist-packages/flask/app.py", line 2447, in wsgi_app
    response = self.full_dispatch_request()
  File "/usr/local/lib/python3.6/dist-packages/flask/app.py", line 1952, in full_dispatch_request
    rv = self.handle_user_exception(e)
  File "/usr/local/lib/python3.6/dist-packages/flask_cors/extension.py", line 165, in wrapped_function
    return cors_after_request(app.make_response(f(*args, **kwargs)))
  File "/usr/local/lib/python3.6/dist-packages/flask/app.py", line 1821, in handle_user_exception
    reraise(exc_type, exc_value, tb)
  File "/usr/local/lib/python3.6/dist-packages/flask/_compat.py", line 39, in reraise
    raise value
  File "/usr/local/lib/python3.6/dist-packages/flask/app.py", line 1950, in full_dispatch_request
    rv = self.dispatch_request()
  File "/usr/local/lib/python3.6/dist-packages/flask/app.py", line 1936, in dispatch_request
    return self.view_functions[rule.endpoint](**req.view_args)
  File "./app.py", line 57, in recommend
    result = compute_recommending_menu.user_recommend(user_id, each_menu_recommend_data, each_user_pearson_data, conn)
  File "/home/ubuntu/smartOrderService/compute_recommending_menu.py", line 94, in user_recommend
    user_create_date = user['created_at'][0].to_pydatetime()
  File "/usr/local/lib/python3.6/dist-packages/pandas/core/series.py", line 879, in __getitem__
    return self._values[key]
IndexError: index 0 is out of bounds for axis 0 with size 0
INFO:werkzeug:125.138.216.31 - - [05/May/2021 23:11:42] "[35m[1mGET /820 HTTP/1.1[0m" 500 -
ERROR:app:Exception on /800 [GET]
Traceback (most recent call last):
  File "/usr/local/lib/python3.6/dist-packages/flask/app.py", line 2447, in wsgi_app
    response = self.full_dispatch_request()
  File "/usr/local/lib/python3.6/dist-packages/flask/app.py", line 1952, in full_dispatch_request
    rv = self.handle_user_exception(e)
  File "/usr/local/lib/python3.6/dist-packages/flask_cors/extension.py", line 165, in wrapped_function
    return cors_after_request(app.make_response(f(*args, **kwargs)))
  File "/usr/local/lib/python3.6/dist-packages/flask/app.py", line 1821, in handle_user_exception
    reraise(exc_type, exc_value, tb)
  File "/usr/local/lib/python3.6/dist-packages/flask/_compat.py", line 39, in reraise
    raise value
  File "/usr/local/lib/python3.6/dist-packages/flask/app.py", line 1950, in full_dispatch_request
    rv = self.dispatch_request()
  File "/usr/local/lib/python3.6/dist-packages/flask/app.py", line 1936, in dispatch_request
    return self.view_functions[rule.endpoint](**req.view_args)
  File "./app.py", line 57, in recommend
    result = compute_recommending_menu.user_recommend(user_id, each_menu_recommend_data, each_user_pearson_data, conn)
  File "/home/ubuntu/smartOrderService/compute_recommending_menu.py", line 95, in user_recommend
    now_date = dt.now()
NameError: name 'dt' is not defined
INFO:werkzeug:125.138.216.31 - - [05/May/2021 23:12:48] "[35m[1mGET /800 HTTP/1.1[0m" 500 -
ERROR:app:Exception on /555 [GET]
Traceback (most recent call last):
  File "/usr/local/lib/python3.6/dist-packages/flask/app.py", line 2447, in wsgi_app
    response = self.full_dispatch_request()
  File "/usr/local/lib/python3.6/dist-packages/flask/app.py", line 1952, in full_dispatch_request
    rv = self.handle_user_exception(e)
  File "/usr/local/lib/python3.6/dist-packages/flask_cors/extension.py", line 165, in wrapped_function
    return cors_after_request(app.make_response(f(*args, **kwargs)))
  File "/usr/local/lib/python3.6/dist-packages/flask/app.py", line 1821, in handle_user_exception
    reraise(exc_type, exc_value, tb)
  File "/usr/local/lib/python3.6/dist-packages/flask/_compat.py", line 39, in reraise
    raise value
  File "/usr/local/lib/python3.6/dist-packages/flask/app.py", line 1950, in full_dispatch_request
    rv = self.dispatch_request()
  File "/usr/local/lib/python3.6/dist-packages/flask/app.py", line 1936, in dispatch_request
    return self.view_functions[rule.endpoint](**req.view_args)
  File "./app.py", line 57, in recommend
    result = compute_recommending_menu.user_recommend(user_id, each_menu_recommend_data, each_user_pearson_data, conn)
  File "/home/ubuntu/smartOrderService/compute_recommending_menu.py", line 95, in user_recommend
    now_date = dt.now()
NameError: name 'dt' is not defined
INFO:werkzeug:125.138.216.31 - - [05/May/2021 23:12:52] "[35m[1mGET /555 HTTP/1.1[0m" 500 -
ERROR:app:Exception on /511 [GET]
Traceback (most recent call last):
  File "/usr/local/lib/python3.6/dist-packages/flask/app.py", line 2447, in wsgi_app
    response = self.full_dispatch_request()
  File "/usr/local/lib/python3.6/dist-packages/flask/app.py", line 1952, in full_dispatch_request
    rv = self.handle_user_exception(e)
  File "/usr/local/lib/python3.6/dist-packages/flask_cors/extension.py", line 165, in wrapped_function
    return cors_after_request(app.make_response(f(*args, **kwargs)))
  File "/usr/local/lib/python3.6/dist-packages/flask/app.py", line 1821, in handle_user_exception
    reraise(exc_type, exc_value, tb)
  File "/usr/local/lib/python3.6/dist-packages/flask/_compat.py", line 39, in reraise
    raise value
  File "/usr/local/lib/python3.6/dist-packages/flask/app.py", line 1950, in full_dispatch_request
    rv = self.dispatch_request()
  File "/usr/local/lib/python3.6/dist-packages/flask/app.py", line 1936, in dispatch_request
    return self.view_functions[rule.endpoint](**req.view_args)
  File "./app.py", line 57, in recommend
    result = compute_recommending_menu.user_recommend(user_id, each_menu_recommend_data, each_user_pearson_data, conn)
  File "/home/ubuntu/smartOrderService/compute_recommending_menu.py", line 95, in user_recommend
    now_date = dt.now()
NameError: name 'dt' is not defined
INFO:werkzeug:125.138.216.31 - - [05/May/2021 23:12:57] "[35m[1mGET /511 HTTP/1.1[0m" 500 -
ERROR:app:Exception on /1 [GET]
Traceback (most recent call last):
  File "/usr/local/lib/python3.6/dist-packages/flask/app.py", line 2447, in wsgi_app
    response = self.full_dispatch_request()
  File "/usr/local/lib/python3.6/dist-packages/flask/app.py", line 1952, in full_dispatch_request
    rv = self.handle_user_exception(e)
  File "/usr/local/lib/python3.6/dist-packages/flask_cors/extension.py", line 165, in wrapped_function
    return cors_after_request(app.make_response(f(*args, **kwargs)))
  File "/usr/local/lib/python3.6/dist-packages/flask/app.py", line 1821, in handle_user_exception
    reraise(exc_type, exc_value, tb)
  File "/usr/local/lib/python3.6/dist-packages/flask/_compat.py", line 39, in reraise
    raise value
  File "/usr/local/lib/python3.6/dist-packages/flask/app.py", line 1950, in full_dispatch_request
    rv = self.dispatch_request()
  File "/usr/local/lib/python3.6/dist-packages/flask/app.py", line 1936, in dispatch_request
    return self.view_functions[rule.endpoint](**req.view_args)
  File "./app.py", line 57, in recommend
    result = compute_recommending_menu.user_recommend(user_id, each_menu_recommend_data, each_user_pearson_data, conn)
  File "/home/ubuntu/smartOrderService/compute_recommending_menu.py", line 94, in user_recommend
    user_create_date = user['created_at'][0].to_pydatetime()
  File "/usr/local/lib/python3.6/dist-packages/pandas/core/series.py", line 879, in __getitem__
    return self._values[key]
IndexError: index 0 is out of bounds for axis 0 with size 0
INFO:werkzeug:125.138.216.31 - - [05/May/2021 23:13:00] "[35m[1mGET /1 HTTP/1.1[0m" 500 -
INFO:werkzeug: * Running on http://0.0.0.0:5000/ (Press CTRL+C to quit)
INFO:werkzeug:125.138.216.31 - - [06/May/2021 02:37:01] "[37mGET / HTTP/1.1[0m" 200 -
INFO:werkzeug:125.138.216.31 - - [06/May/2021 02:37:04] "[37mGET /22 HTTP/1.1[0m" 200 -
ERROR:app:Exception on /501 [GET]
Traceback (most recent call last):
  File "/usr/local/lib/python3.6/dist-packages/flask/app.py", line 2447, in wsgi_app
    response = self.full_dispatch_request()
  File "/usr/local/lib/python3.6/dist-packages/flask/app.py", line 1952, in full_dispatch_request
    rv = self.handle_user_exception(e)
  File "/usr/local/lib/python3.6/dist-packages/flask_cors/extension.py", line 165, in wrapped_function
    return cors_after_request(app.make_response(f(*args, **kwargs)))
  File "/usr/local/lib/python3.6/dist-packages/flask/app.py", line 1821, in handle_user_exception
    reraise(exc_type, exc_value, tb)
  File "/usr/local/lib/python3.6/dist-packages/flask/_compat.py", line 39, in reraise
    raise value
  File "/usr/local/lib/python3.6/dist-packages/flask/app.py", line 1950, in full_dispatch_request
    rv = self.dispatch_request()
  File "/usr/local/lib/python3.6/dist-packages/flask/app.py", line 1936, in dispatch_request
    return self.view_functions[rule.endpoint](**req.view_args)
  File "./app.py", line 57, in recommend
    result = compute_recommending_menu.user_recommend(user_id, each_menu_recommend_data, each_user_pearson_data, conn)
  File "/home/ubuntu/smartOrderService/compute_recommending_menu.py", line 99, in user_recommend
    now_date = dt.now()
NameError: name 'dt' is not defined
INFO:werkzeug:125.138.216.31 - - [06/May/2021 02:37:07] "[35m[1mGET /501 HTTP/1.1[0m" 500 -
ERROR:app:Exception on /600 [GET]
Traceback (most recent call last):
  File "/usr/local/lib/python3.6/dist-packages/flask/app.py", line 2447, in wsgi_app
    response = self.full_dispatch_request()
  File "/usr/local/lib/python3.6/dist-packages/flask/app.py", line 1952, in full_dispatch_request
    rv = self.handle_user_exception(e)
  File "/usr/local/lib/python3.6/dist-packages/flask_cors/extension.py", line 165, in wrapped_function
    return cors_after_request(app.make_response(f(*args, **kwargs)))
  File "/usr/local/lib/python3.6/dist-packages/flask/app.py", line 1821, in handle_user_exception
    reraise(exc_type, exc_value, tb)
  File "/usr/local/lib/python3.6/dist-packages/flask/_compat.py", line 39, in reraise
    raise value
  File "/usr/local/lib/python3.6/dist-packages/flask/app.py", line 1950, in full_dispatch_request
    rv = self.dispatch_request()
  File "/usr/local/lib/python3.6/dist-packages/flask/app.py", line 1936, in dispatch_request
    return self.view_functions[rule.endpoint](**req.view_args)
  File "./app.py", line 57, in recommend
    result = compute_recommending_menu.user_recommend(user_id, each_menu_recommend_data, each_user_pearson_data, conn)
  File "/home/ubuntu/smartOrderService/compute_recommending_menu.py", line 99, in user_recommend
    now_date = dt.now()
NameError: name 'dt' is not defined
INFO:werkzeug:125.138.216.31 - - [06/May/2021 02:37:13] "[35m[1mGET /600 HTTP/1.1[0m" 500 -
INFO:werkzeug:125.138.216.31 - - [06/May/2021 02:37:17] "[37mGET /820 HTTP/1.1[0m" 200 -
INFO:werkzeug:125.138.216.31 - - [06/May/2021 02:37:25] "[37mGET /824 HTTP/1.1[0m" 200 -
INFO:werkzeug: * Running on http://0.0.0.0:5000/ (Press CTRL+C to quit)
ERROR:app:Exception on /823 [GET]
Traceback (most recent call last):
  File "/usr/local/lib/python3.6/dist-packages/flask/app.py", line 2447, in wsgi_app
    response = self.full_dispatch_request()
  File "/usr/local/lib/python3.6/dist-packages/flask/app.py", line 1952, in full_dispatch_request
    rv = self.handle_user_exception(e)
  File "/usr/local/lib/python3.6/dist-packages/flask_cors/extension.py", line 165, in wrapped_function
    return cors_after_request(app.make_response(f(*args, **kwargs)))
  File "/usr/local/lib/python3.6/dist-packages/flask/app.py", line 1821, in handle_user_exception
    reraise(exc_type, exc_value, tb)
  File "/usr/local/lib/python3.6/dist-packages/flask/_compat.py", line 39, in reraise
    raise value
  File "/usr/local/lib/python3.6/dist-packages/flask/app.py", line 1950, in full_dispatch_request
    rv = self.dispatch_request()
  File "/usr/local/lib/python3.6/dist-packages/flask/app.py", line 1936, in dispatch_request
    return self.view_functions[rule.endpoint](**req.view_args)
  File "./app.py", line 57, in recommend
    result = compute_recommending_menu.user_recommend(user_id, each_menu_recommend_data, each_user_pearson_data, conn)
  File "/home/ubuntu/smartOrderService/compute_recommending_menu.py", line 102, in user_recommend
    result_list = user_recommend_func(user_id, each_menu_recommend_data, each_user_pearson_data, conn)
  File "/home/ubuntu/smartOrderService/compute_recommending_menu.py", line 109, in user_recommend_func
    cur_user_pearson_datas = each_user_pearson_data[user_id - 501]['Pearson Data']
IndexError: list index out of range
INFO:werkzeug:125.138.216.31 - - [06/May/2021 02:38:49] "[35m[1mGET /823 HTTP/1.1[0m" 500 -
ERROR:app:Exception on /822 [GET]
Traceback (most recent call last):
  File "/usr/local/lib/python3.6/dist-packages/flask/app.py", line 2447, in wsgi_app
    response = self.full_dispatch_request()
  File "/usr/local/lib/python3.6/dist-packages/flask/app.py", line 1952, in full_dispatch_request
    rv = self.handle_user_exception(e)
  File "/usr/local/lib/python3.6/dist-packages/flask_cors/extension.py", line 165, in wrapped_function
    return cors_after_request(app.make_response(f(*args, **kwargs)))
  File "/usr/local/lib/python3.6/dist-packages/flask/app.py", line 1821, in handle_user_exception
    reraise(exc_type, exc_value, tb)
  File "/usr/local/lib/python3.6/dist-packages/flask/_compat.py", line 39, in reraise
    raise value
  File "/usr/local/lib/python3.6/dist-packages/flask/app.py", line 1950, in full_dispatch_request
    rv = self.dispatch_request()
  File "/usr/local/lib/python3.6/dist-packages/flask/app.py", line 1936, in dispatch_request
    return self.view_functions[rule.endpoint](**req.view_args)
  File "./app.py", line 57, in recommend
    result = compute_recommending_menu.user_recommend(user_id, each_menu_recommend_data, each_user_pearson_data, conn)
  File "/home/ubuntu/smartOrderService/compute_recommending_menu.py", line 102, in user_recommend
    result_list = user_recommend_func(user_id, each_menu_recommend_data, each_user_pearson_data, conn)
  File "/home/ubuntu/smartOrderService/compute_recommending_menu.py", line 109, in user_recommend_func
    cur_user_pearson_datas = each_user_pearson_data[user_id - 501]['Pearson Data']
IndexError: list index out of range
INFO:werkzeug:125.138.216.31 - - [06/May/2021 02:38:53] "[35m[1mGET /822 HTTP/1.1[0m" 500 -
INFO:werkzeug:125.138.216.31 - - [06/May/2021 02:38:57] "[37mGET /555 HTTP/1.1[0m" 200 -
INFO:werkzeug:125.138.216.31 - - [06/May/2021 02:39:01] "[37mGET /800 HTTP/1.1[0m" 200 -
INFO:werkzeug:125.138.216.31 - - [06/May/2021 02:39:34] "[37mGET /803 HTTP/1.1[0m" 200 -
INFO:werkzeug:125.138.216.31 - - [06/May/2021 02:39:46] "[37mGET /804 HTTP/1.1[0m" 200 -
ERROR:app:Exception on /822 [GET]
Traceback (most recent call last):
  File "/usr/local/lib/python3.6/dist-packages/flask/app.py", line 2447, in wsgi_app
    response = self.full_dispatch_request()
  File "/usr/local/lib/python3.6/dist-packages/flask/app.py", line 1952, in full_dispatch_request
    rv = self.handle_user_exception(e)
  File "/usr/local/lib/python3.6/dist-packages/flask_cors/extension.py", line 165, in wrapped_function
    return cors_after_request(app.make_response(f(*args, **kwargs)))
  File "/usr/local/lib/python3.6/dist-packages/flask/app.py", line 1821, in handle_user_exception
    reraise(exc_type, exc_value, tb)
  File "/usr/local/lib/python3.6/dist-packages/flask/_compat.py", line 39, in reraise
    raise value
  File "/usr/local/lib/python3.6/dist-packages/flask/app.py", line 1950, in full_dispatch_request
    rv = self.dispatch_request()
  File "/usr/local/lib/python3.6/dist-packages/flask/app.py", line 1936, in dispatch_request
    return self.view_functions[rule.endpoint](**req.view_args)
  File "./app.py", line 57, in recommend
    result = compute_recommending_menu.user_recommend(user_id, each_menu_recommend_data, each_user_pearson_data, conn)
  File "/home/ubuntu/smartOrderService/compute_recommending_menu.py", line 102, in user_recommend
    result_list = user_recommend_func(user_id, each_menu_recommend_data, each_user_pearson_data, conn)
  File "/home/ubuntu/smartOrderService/compute_recommending_menu.py", line 109, in user_recommend_func
    cur_user_pearson_datas = each_user_pearson_data[user_id - 501]['Pearson Data']
IndexError: list index out of range
INFO:werkzeug:125.138.216.31 - - [06/May/2021 02:40:00] "[35m[1mGET /822 HTTP/1.1[0m" 500 -
INFO:werkzeug: * Running on http://0.0.0.0:5000/ (Press CTRL+C to quit)
ERROR:app:Exception on /822 [GET]
Traceback (most recent call last):
  File "/usr/local/lib/python3.6/dist-packages/flask/app.py", line 2447, in wsgi_app
    response = self.full_dispatch_request()
  File "/usr/local/lib/python3.6/dist-packages/flask/app.py", line 1952, in full_dispatch_request
    rv = self.handle_user_exception(e)
  File "/usr/local/lib/python3.6/dist-packages/flask_cors/extension.py", line 165, in wrapped_function
    return cors_after_request(app.make_response(f(*args, **kwargs)))
  File "/usr/local/lib/python3.6/dist-packages/flask/app.py", line 1821, in handle_user_exception
    reraise(exc_type, exc_value, tb)
  File "/usr/local/lib/python3.6/dist-packages/flask/_compat.py", line 39, in reraise
    raise value
  File "/usr/local/lib/python3.6/dist-packages/flask/app.py", line 1950, in full_dispatch_request
    rv = self.dispatch_request()
  File "/usr/local/lib/python3.6/dist-packages/flask/app.py", line 1936, in dispatch_request
    return self.view_functions[rule.endpoint](**req.view_args)
  File "./app.py", line 57, in recommend
    result = compute_recommending_menu.user_recommend(user_id, each_menu_recommend_data, each_user_pearson_data, conn)
  File "/home/ubuntu/smartOrderService/compute_recommending_menu.py", line 105, in user_recommend
    result_list = user_recommend_func(user_id, each_menu_recommend_data, each_user_pearson_data, conn)
  File "/home/ubuntu/smartOrderService/compute_recommending_menu.py", line 112, in user_recommend_func
    cur_user_pearson_datas = each_user_pearson_data[user_id - 501]['Pearson Data']
IndexError: list index out of range
INFO:werkzeug:125.138.216.31 - - [06/May/2021 02:46:13] "[35m[1mGET /822 HTTP/1.1[0m" 500 -
INFO:werkzeug: * Running on http://0.0.0.0:5000/ (Press CTRL+C to quit)
INFO:werkzeug: * Running on http://0.0.0.0:5000/ (Press CTRL+C to quit)
ERROR:app:Exception on /822 [GET]
Traceback (most recent call last):
  File "/usr/local/lib/python3.6/dist-packages/flask/app.py", line 2447, in wsgi_app
    response = self.full_dispatch_request()
  File "/usr/local/lib/python3.6/dist-packages/flask/app.py", line 1952, in full_dispatch_request
    rv = self.handle_user_exception(e)
  File "/usr/local/lib/python3.6/dist-packages/flask_cors/extension.py", line 165, in wrapped_function
    return cors_after_request(app.make_response(f(*args, **kwargs)))
  File "/usr/local/lib/python3.6/dist-packages/flask/app.py", line 1821, in handle_user_exception
    reraise(exc_type, exc_value, tb)
  File "/usr/local/lib/python3.6/dist-packages/flask/_compat.py", line 39, in reraise
    raise value
  File "/usr/local/lib/python3.6/dist-packages/flask/app.py", line 1950, in full_dispatch_request
    rv = self.dispatch_request()
  File "/usr/local/lib/python3.6/dist-packages/flask/app.py", line 1936, in dispatch_request
    return self.view_functions[rule.endpoint](**req.view_args)
  File "./app.py", line 57, in recommend
    result = compute_recommending_menu.user_recommend(user_id, each_menu_recommend_data, each_user_pearson_data, conn)
  File "/home/ubuntu/smartOrderService/compute_recommending_menu.py", line 105, in user_recommend
    result_list = user_recommend_func(user_id, each_menu_recommend_data, each_user_pearson_data, conn)
  File "/home/ubuntu/smartOrderService/compute_recommending_menu.py", line 112, in user_recommend_func
    cur_user_pearson_datas = each_user_pearson_data[user_id - 501]['Pearson Data']
IndexError: list index out of range
INFO:werkzeug:125.138.216.31 - - [06/May/2021 02:48:51] "[35m[1mGET /822 HTTP/1.1[0m" 500 -
INFO:werkzeug: * Running on http://0.0.0.0:5000/ (Press CTRL+C to quit)
ERROR:app:Exception on /822 [GET]
Traceback (most recent call last):
  File "/usr/local/lib/python3.6/dist-packages/flask/app.py", line 2447, in wsgi_app
    response = self.full_dispatch_request()
  File "/usr/local/lib/python3.6/dist-packages/flask/app.py", line 1952, in full_dispatch_request
    rv = self.handle_user_exception(e)
  File "/usr/local/lib/python3.6/dist-packages/flask_cors/extension.py", line 165, in wrapped_function
    return cors_after_request(app.make_response(f(*args, **kwargs)))
  File "/usr/local/lib/python3.6/dist-packages/flask/app.py", line 1821, in handle_user_exception
    reraise(exc_type, exc_value, tb)
  File "/usr/local/lib/python3.6/dist-packages/flask/_compat.py", line 39, in reraise
    raise value
  File "/usr/local/lib/python3.6/dist-packages/flask/app.py", line 1950, in full_dispatch_request
    rv = self.dispatch_request()
  File "/usr/local/lib/python3.6/dist-packages/flask/app.py", line 1936, in dispatch_request
    return self.view_functions[rule.endpoint](**req.view_args)
  File "./app.py", line 57, in recommend
    result = compute_recommending_menu.user_recommend(user_id, each_menu_recommend_data, each_user_pearson_data, conn)
  File "/home/ubuntu/smartOrderService/compute_recommending_menu.py", line 105, in user_recommend
    result_list = user_recommend_func(user_id, each_menu_recommend_data, each_user_pearson_data, conn)
  File "/home/ubuntu/smartOrderService/compute_recommending_menu.py", line 112, in user_recommend_func
    cur_user_pearson_datas = each_user_pearson_data[user_id - 501]['Pearson Data']
IndexError: list index out of range
INFO:werkzeug:125.138.216.31 - - [06/May/2021 02:50:37] "[35m[1mGET /822 HTTP/1.1[0m" 500 -
INFO:werkzeug:125.138.216.31 - - [06/May/2021 02:51:41] "[37mGET /821 HTTP/1.1[0m" 200 -
INFO:werkzeug:125.138.216.31 - - [06/May/2021 02:51:54] "[37mGET /820 HTTP/1.1[0m" 200 -
INFO:werkzeug:125.138.216.31 - - [06/May/2021 02:52:03] "[37mGET /819 HTTP/1.1[0m" 200 -
INFO:werkzeug:125.138.216.31 - - [06/May/2021 02:52:25] "[37mGET /800 HTTP/1.1[0m" 200 -
INFO:werkzeug:125.138.216.31 - - [06/May/2021 02:52:38] "[33mGET /80q HTTP/1.1[0m" 404 -
INFO:werkzeug:125.138.216.31 - - [06/May/2021 02:52:41] "[37mGET /801 HTTP/1.1[0m" 200 -
INFO:werkzeug:125.138.216.31 - - [06/May/2021 02:52:46] "[37mGET /802 HTTP/1.1[0m" 200 -
INFO:werkzeug:125.138.216.31 - - [06/May/2021 02:52:48] "[37mGET /803 HTTP/1.1[0m" 200 -
INFO:werkzeug:125.138.216.31 - - [06/May/2021 02:52:51] "[37mGET /804 HTTP/1.1[0m" 200 -
INFO:werkzeug:125.138.216.31 - - [06/May/2021 02:52:55] "[37mGET /805 HTTP/1.1[0m" 200 -
INFO:werkzeug:125.138.216.31 - - [06/May/2021 02:53:17] "[37mGET /817 HTTP/1.1[0m" 200 -
INFO:werkzeug:125.138.216.31 - - [06/May/2021 02:53:26] "[37mGET /820 HTTP/1.1[0m" 200 -
INFO:werkzeug:125.138.216.31 - - [06/May/2021 02:53:50] "[37mGET /821 HTTP/1.1[0m" 200 -
ERROR:app:Exception on /822 [GET]
Traceback (most recent call last):
  File "/usr/local/lib/python3.6/dist-packages/flask/app.py", line 2447, in wsgi_app
    response = self.full_dispatch_request()
  File "/usr/local/lib/python3.6/dist-packages/flask/app.py", line 1952, in full_dispatch_request
    rv = self.handle_user_exception(e)
  File "/usr/local/lib/python3.6/dist-packages/flask_cors/extension.py", line 165, in wrapped_function
    return cors_after_request(app.make_response(f(*args, **kwargs)))
  File "/usr/local/lib/python3.6/dist-packages/flask/app.py", line 1821, in handle_user_exception
    reraise(exc_type, exc_value, tb)
  File "/usr/local/lib/python3.6/dist-packages/flask/_compat.py", line 39, in reraise
    raise value
  File "/usr/local/lib/python3.6/dist-packages/flask/app.py", line 1950, in full_dispatch_request
    rv = self.dispatch_request()
  File "/usr/local/lib/python3.6/dist-packages/flask/app.py", line 1936, in dispatch_request
    return self.view_functions[rule.endpoint](**req.view_args)
  File "./app.py", line 57, in recommend
    result = compute_recommending_menu.user_recommend(user_id, each_menu_recommend_data, each_user_pearson_data, conn)
  File "/home/ubuntu/smartOrderService/compute_recommending_menu.py", line 105, in user_recommend
    result_list = user_recommend_func(user_id, each_menu_recommend_data, each_user_pearson_data, conn)
  File "/home/ubuntu/smartOrderService/compute_recommending_menu.py", line 112, in user_recommend_func
    cur_user_pearson_datas = each_user_pearson_data[user_id - 501]['Pearson Data']
IndexError: list index out of range
INFO:werkzeug:125.138.216.31 - - [06/May/2021 02:53:53] "[35m[1mGET /822 HTTP/1.1[0m" 500 -
ERROR:app:Exception on /822 [GET]
Traceback (most recent call last):
  File "/usr/local/lib/python3.6/dist-packages/flask/app.py", line 2447, in wsgi_app
    response = self.full_dispatch_request()
  File "/usr/local/lib/python3.6/dist-packages/flask/app.py", line 1952, in full_dispatch_request
    rv = self.handle_user_exception(e)
  File "/usr/local/lib/python3.6/dist-packages/flask_cors/extension.py", line 165, in wrapped_function
    return cors_after_request(app.make_response(f(*args, **kwargs)))
  File "/usr/local/lib/python3.6/dist-packages/flask/app.py", line 1821, in handle_user_exception
    reraise(exc_type, exc_value, tb)
  File "/usr/local/lib/python3.6/dist-packages/flask/_compat.py", line 39, in reraise
    raise value
  File "/usr/local/lib/python3.6/dist-packages/flask/app.py", line 1950, in full_dispatch_request
    rv = self.dispatch_request()
  File "/usr/local/lib/python3.6/dist-packages/flask/app.py", line 1936, in dispatch_request
    return self.view_functions[rule.endpoint](**req.view_args)
  File "./app.py", line 57, in recommend
    result = compute_recommending_menu.user_recommend(user_id, each_menu_recommend_data, each_user_pearson_data, conn)
  File "/home/ubuntu/smartOrderService/compute_recommending_menu.py", line 105, in user_recommend
    result_list = user_recommend_func(user_id, each_menu_recommend_data, each_user_pearson_data, conn)
  File "/home/ubuntu/smartOrderService/compute_recommending_menu.py", line 112, in user_recommend_func
    cur_user_pearson_datas = each_user_pearson_data[user_id - 501]['Pearson Data']
IndexError: list index out of range
INFO:werkzeug:125.138.216.31 - - [06/May/2021 02:54:15] "[35m[1mGET /822 HTTP/1.1[0m" 500 -
INFO:werkzeug: * Running on http://0.0.0.0:5000/ (Press CTRL+C to quit)
INFO:werkzeug:125.138.216.31 - - [06/May/2021 02:55:42] "[37mGET /822 HTTP/1.1[0m" 200 -
INFO:werkzeug:125.138.216.31 - - [06/May/2021 02:55:45] "[37mGET /823 HTTP/1.1[0m" 200 -
INFO:werkzeug:125.138.216.31 - - [06/May/2021 02:55:47] "[37mGET /824 HTTP/1.1[0m" 200 -
INFO:werkzeug:125.138.216.31 - - [06/May/2021 02:56:07] "[37mGET /823 HTTP/1.1[0m" 200 -
INFO:werkzeug:125.138.216.31 - - [06/May/2021 02:56:11] "[33mGET /801] HTTP/1.1[0m" 404 -
INFO:werkzeug:125.138.216.31 - - [06/May/2021 02:56:14] "[37mGET /801 HTTP/1.1[0m" 200 -
INFO:werkzeug:125.138.216.31 - - [06/May/2021 02:56:17] "[37mGET /802 HTTP/1.1[0m" 200 -
INFO:werkzeug:125.138.216.31 - - [06/May/2021 02:56:19] "[37mGET /804 HTTP/1.1[0m" 200 -
INFO:werkzeug:125.138.216.31 - - [06/May/2021 02:56:21] "[37mGET /806 HTTP/1.1[0m" 200 -
INFO:werkzeug:125.138.216.31 - - [06/May/2021 02:56:24] "[37mGET /807 HTTP/1.1[0m" 200 -
INFO:werkzeug:125.138.216.31 - - [06/May/2021 02:56:29] "[37mGET /8013 HTTP/1.1[0m" 200 -
INFO:werkzeug:125.138.216.31 - - [06/May/2021 02:56:33] "[37mGET /813 HTTP/1.1[0m" 200 -
INFO:werkzeug:125.138.216.31 - - [06/May/2021 02:56:38] "[37mGET /820 HTTP/1.1[0m" 200 -
INFO:werkzeug:125.138.216.31 - - [06/May/2021 02:56:40] "[37mGET /821 HTTP/1.1[0m" 200 -
INFO:werkzeug:125.138.216.31 - - [06/May/2021 02:56:43] "[37mGET /822 HTTP/1.1[0m" 200 -
INFO:werkzeug: * Running on http://0.0.0.0:5000/ (Press CTRL+C to quit)
INFO:werkzeug:125.138.216.31 - - [06/May/2021 02:59:11] "[37mGET /1 HTTP/1.1[0m" 200 -
INFO:werkzeug:125.138.216.31 - - [06/May/2021 02:59:14] "[37mGET /133 HTTP/1.1[0m" 200 -
INFO:werkzeug:125.138.216.31 - - [06/May/2021 02:59:16] "[37mGET /666 HTTP/1.1[0m" 200 -
INFO:werkzeug:125.138.216.31 - - [06/May/2021 02:59:21] "[37mGET /591 HTTP/1.1[0m" 200 -
INFO:werkzeug:125.138.216.31 - - [06/May/2021 02:59:26] "[37mGET /501 HTTP/1.1[0m" 200 -
INFO:werkzeug:125.138.216.31 - - [06/May/2021 02:59:32] "[37mGET /802 HTTP/1.1[0m" 200 -
INFO:werkzeug:125.138.216.31 - - [06/May/2021 02:59:34] "[37mGET /801 HTTP/1.1[0m" 200 -
INFO:werkzeug:125.138.216.31 - - [06/May/2021 02:59:36] "[37mGET /820 HTTP/1.1[0m" 200 -
INFO:werkzeug:125.138.216.31 - - [06/May/2021 02:59:38] "[37mGET /823 HTTP/1.1[0m" 200 -
INFO:werkzeug:125.138.216.31 - - [06/May/2021 02:59:41] "[37mGET /822 HTTP/1.1[0m" 200 -
